Workbook

Sheet Итог-Модел CGE
A1: Модел CGE - SAM 2024-Баҳодиҳии пешакии нишондиҳандаҳои асосии макроиќтисодии Љумҳурии Тољикистон барои соли 2026 ва дурнамои он барои солҳои 2027-2029
A2: Нишондињандањо | B2: Воњиди ченак | C2: Соли 2022 | E2: Соли 2023 | G2: Соли 2024 | I2: Соли 2025 | K2: Соли 2026 | M2: Соли 2027 | O2: Соли 2028 | Q2: Соли 2029 | S2: Соли 2030 | U2: Соли 2031 | W2: Соли 2032 | Y2: 2024
C3: Воќеї | D3: нисбат ба соли 2021 (бо фоиз) | E3: Воќеї | F3: нисбат ба соли 2022 (бо фоиз) | G3: Воќеї | H3: нисбат ба соли 2023 (бо фоиз) | I3: Воќеї | J3: нисбат ба соли 2024 (бо фоиз) | K3: Бањодињї | L3: нисбат ба соли 2025 (бо фоиз) | M3: Дурнамо | N3: нисбат ба соли 2026 (бо фоиз) | O3: Дурнамо | P3: нисбат ба соли 2027 (бо фоиз) | Q3: Дурнамо | R3: нисбат ба соли 2027 (бо фоиз) | S3: Дурнамо | T3: нисбат ба соли 2027 (бо фоиз) | U3: Дурнамо | V3: нисбат ба соли 2027 (бо фоиз) | W3: Дурнамо | X3: нисбат ба соли 2027 (бо фоиз) | Z3: Соли 2023 | AB3: Соли 2024 | AD3: Соли 2025 | AF3: Соли 2026 | AH3: Соли 2027 | AJ3: Соли 2028 | AL3: Соли 2029 | AN3: Соли 2030 | AP3: Соли 2031 | AR3: Соли 2032
A4: Шумораи ањолї (ба њисоби миёнаи солона) | B4: Њазор нафар | C4: 9982.6 | D4: 101.8 | E4: 10183.3 | F4: =+E4/C4*100 -> 102.0105 | G4: 10398.4 | H4: =+G4/E4*100 -> 102.11228 | I4: 10614.691 | J4: =+I4/G4*100 -> 102.08004 | K4: =+I4*L4/100 -> 10837.6 | L4: 102.1 | M4: =+K4*N4/100 -> 11076.027 | N4: 102.2 | O4: =+M4*P4/100 -> 11319.699 | P4: 102.2 | Q4: =+O4*P4/100 -> 11568.733 | R4: 102.2 | S4: =+Q4*R4/100 -> 11823.245 | T4: 102.2 | U4: =+S4*T4/100 -> 12083.356 | V4: 102.2 | W4: =+U4*V4/100 -> 12349.19 | X4: 102.3 | Y4: 10382.1 | Z4: =C4*F4/100 -> 10183.3 | AA4: =E4/C4*100 -> 102.0105 | AB4: =E4*H4/100 -> 10398.4 | AC4: =G4/E4*100 -> 102.11228 | AD4: =G4*J4/100 -> 10614.691 | AE4: =I4/G4*100 -> 102.08004 | AF4: =I4*L4/100 -> 10837.6 | AG4: =K4/I4*100 -> 102.1 | AH4: =K4*N4/100 -> 11076.027 | AI4: =M4/K4*100 -> 102.2 | AJ4: =M4*P4/100 -> 11319.699 | AK4: =O4/M4*100 -> 102.2 | AL4: =O4*R4/100 -> 11568.733 | AM4: =Q4/O4*100 -> 102.2 | AN4: =Q4*T4/100 -> 11823.245 | AO4: =S4/Q4*100 -> 102.2 | AP4: =S4*V4/100 -> 12083.356 | AQ4: =U4/S4*100 -> 102.2 | AR4: =U4*X4/100 -> 12361.273 | AS4: =W4/U4*100 -> 102.2
A5: Маљмўи мањсулоти дохилї | B5: млн. сомонї | C5: 118181.7 | D5: 108.03592 | E5: 132781.9 | F5: 108.31977 | G5: 155783.9 | H5: 108.4 | I5: 176919 | J5: 108.4 | K5: =GDP!P19 -> 199898.14 | L5: =GDP!P36 -> 108.516 | M5: =GDP!Q19 -> 225457.17 | N5: =GDP!Q36 -> 108.37389 | O5: =GDP!R19 -> 254612 | P5: =GDP!R36 -> 108.6252 | Q5: =GDP!S19 -> 290957.14 | R5: =GDP!S36 -> 108.76495 | S5: =GDP!T19 -> 325987.62 | T5: =GDP!T36 -> 107.88215 | U5: =GDP!U19 -> 368330.85 | V5: =GDP!U36 -> 108.53792 | W5: =GDP!V19 -> 413970.34 | X5: =GDP!V36 -> 108.10939 | Y5: 153402.2 | Z5: =S5/I5*100 -> 184.25812
A6: Индекс-дефлятори ММД | B6: бо фоиз | D6: 108.22628 | F6: 103.7244 | H6: 108.2 | J6: 106.4 | L6: =GDP!P35 -> 104.12161 | N6: =GDP!Q35 -> 104.07122 | P6: =GDP!R35 -> 103.9643 | R6: =GDP!S35 -> 105.06575 | T6: =GDP!T35 -> 103.85382 | V6: =GDP!U35 -> 104.10115 | X6: =GDP!V35 -> 103.96034 | Z6: =S6/I6*100 -> #DIV/0!
A7: Таваррум | B7: бо фоиз | D7: 104.2 | F7: 103.8 | H7: 103.6 | J7: 103.5 | L7: ='6_Closures'!E20 -> 103.92894 | N7: ='6_Closures'!F20 -> 104.00219 | P7: ='6_Closures'!G20 -> 103.83918 | R7: ='6_Closures'!H20 -> 103.94069 | T7: ='6_Closures'!I20 -> 104.0531 | V7: ='6_Closures'!J20 -> 104.40046 | X7: ='6_Closures'!K20 -> 104.36099 | Z7: =S7/I7*100 -> #DIV/0!
A8: ММД ба њар нафар ањолї | B8: сомонї | C8: =+C5/C4*1000 -> 11838.769 | D8: =+C8/10312*100 -> 114.80576 | E8: =+E5/E4*1000 -> 13039.182 | F8: =+E8/C8*100 -> 110.13967 | G8: =+G5/G4*1000 -> 14981.526 | H8: =+G8/E8*100 -> 114.89621 | I8: =+I5/I4*1000 -> 16667.372 | J8: =+I8/G8*100 -> 111.25283 | K8: =+K5/K4*1000 -> 18444.873 | L8: =+K8/I8*100 -> 110.66455 | M8: =+M5/M4*1000 -> 20355.419 | N8: =+M8/K8*100 -> 110.35814 | O8: =+O5/O4*1000 -> 22492.824 | P8: =+O8/M8*100 -> 110.50042 | Q8: =+Q5/Q4*1000 -> 25150.304 | R8: =+Q8/O8*100 -> 111.81479 | S8: =+S5/S4*1000 -> 27571.756 | T8: =+S8/Q8*100 -> 109.62792 | U8: =+U5/U4*1000 -> 30482.496 | V8: =+U8/S8*100 -> 110.55696 | W8: =+W5/W4*1000 -> 33522.064 | X8: =+W8/U8*100 -> 109.97152 | Y8: =+Y5/Y4*1000 -> 14775.643 | Z8: =S8/I8*100 -> 165.42354
A9: Њаљми мањсулоти саноатї | B9: млн. сомонї | C9: 42221.4 | D9: 115.4 | E9: 46816 | F9: 112 | G9: 53819 | H9: 120 | I9: 66726.1 | J9: 122.1 | K9: ='GDP-total'!D30 -> 83491.033 | L9: ='2_Production_2'!X35 -> 125 | M9: ='GDP-total'!E30 -> 104885.61 | N9: ='2_Production_2'!Y35 -> 125 | O9: ='GDP-total'!F30 -> 131605.53 | P9: ='2_Production_2'!Z35 -> 125.1 | Q9: ='GDP-total'!G30 -> 164803.16 | R9: ='2_Production_2'!AA35 -> 125.1 | S9: ='GDP-total'!H30 -> 167868.34 | T9: ='2_Production_2'!AB35 -> 119.97633 | U9: ='GDP-total'!I30 -> 171881.64 | V9: ='2_Production_2'!AC35 -> 120.03604 | W9: ='GDP-total'!J30 -> 172763.33 | X9: ='2_Production_2'!AD35 -> 120.08717 | Z9: =S9/I9*100 -> 251.57824
A10: Њаљми мањсулоти кишоварзї | B10: млн. сомонї | C10: 61337.9 | D10: 108 | E10: 66907.2 | F10: 109 | G10: 73976.6 | H10: 110.6 | I10: 84653.8 | J10: 109.5 | K10: ='2_Production_2'!E21 -> 95155.45 | L10: ='2_Production_2'!X21 -> 108.92031 | M10: ='2_Production_2'!F21 -> 104590.97 | N10: ='2_Production_2'!Y21 -> 108.61255 | O10: ='2_Production_2'!G21 -> 114715.95 | P10: ='2_Production_2'!Z21 -> 108.27301 | Q10: ='2_Production_2'!H21 -> 125434.68 | R10: ='2_Production_2'!AA21 -> 108.15402 | S10: ='2_Production_2'!I21 -> 136949.67 | T10: ='2_Production_2'!AB21 -> 108.31356 | U10: ='2_Production_2'!J21 -> 148095.67 | V10: ='2_Production_2'!AC21 -> 107.60075 | W10: ='2_Production_2'!K21 -> 159589.19 | X10: ='2_Production_2'!AD21 -> 107.54578 | Z10: =S10/I10*100 -> 161.77616
A11: Маблаѓгузорї ба сармояи асосї аз њисоби њамаи манбаъњои маблаѓгузорї | B11: млн. сомонї | C11: 16279.5 | D11: 111.4 | E11: 19859 | F11: 121.98778 | G11: 22543 | H11: 108.4 | I11: 28736 | J11: 123 | K11: ='GDP-total'!D35 -> 32767.972 | L11: =+K11/I11*100 -> 114.03108 | M11: ='GDP-total'!E35 -> 38923.922 | N11: =+M11/K11*100 -> 118.78648 | O11: ='GDP-total'!F35 -> 44524.431 | P11: =+O11/M11*100 -> 114.38835 | Q11: ='GDP-total'!G35 -> 51375.484 | R11: =+Q11/O11*100 -> 115.38718 | S11: ='GDP-total'!H35 -> 55564.062 | T11: =+S11/Q11*100 -> 108.15287 | U11: ='GDP-total'!I35 -> 63254.949 | V11: =+U11/S11*100 -> 113.84148 | W11: ='GDP-total'!J35 -> 73256.893 | X11: =+W11/U11*100 -> 115.81211 | Z11: =S11/I11*100 -> 193.36046
A12: аз чумла аз њисоби буљети давлатї | B12: млн. сомонї | C12: 6736.9 | D12: 110.3 | E12: 7922.5 | F12: 117.5986 | G12: 9830.5 | H12: 118.5 | I12: 13280.5 | J12: 130.4 | K12: ='GDP-total'!D44 -> 14210.135 | L12: =+K12/I12*100 -> 107 | M12: ='GDP-total'!E44 -> 15631.149 | N12: =+M12/K12*100 -> 110 | O12: ='GDP-total'!F44 -> 16881.64 | P12: =+O12/M12*100 -> 108 | Q12: ='GDP-total'!G44 -> 18063.355 | R12: =+Q12/O12*100 -> 107 | S12: ='GDP-total'!H44 -> 18785.889 | T12: =+S12/Q12*100 -> 104 | U12: ='GDP-total'!I44 -> 19725.184 | V12: =+U12/S12*100 -> 105 | W12: ='GDP-total'!J44 -> 21697.702 | X12: =+W12/U12*100 -> 110 | Z12: =S12/I12*100 -> 141.45468
A13: Сармоягузории хориљї (қарз, грант, мустақим) | B13: млн. доллар | C13: 2577 | E13: 2690 | F13: 104.38494 | G13: 5126.6 | H13: =+G13/E13*100 -> 190.57993 | I13: =[1]OEA!$AF$34 -> 6925.3 | J13: =+I13/G13*100 -> 135.08563 | K13: =[1]OEA!$AG$34 -> 7624.7553 | L13: =+K13/I13*100 -> 110.1 | M13: =[1]OEA!$AH$34 -> 8562.6002 | N13: =+M13/K13*100 -> 112.3 | O13: =[1]OEA!$AI$34 -> 9598.6748 | P13: =+O13/M13*100 -> 112.1 | Q13: =[1]OEA!$AJ$34 -> 10769.713 | R13: =+Q13/O13*100 -> 112.2 | S13: =[1]OEA!$AK$34 -> 12094.388 | T13: =+S13/Q13*100 -> 112.3 | U13: =[1]OEA!$AL$34 -> 13545.714 | V13: =+U13/S13*100 -> 112 | W13: =[1]OEA!$AM$34 -> 15184.746 | X13: =+W13/U13*100 -> 112.1 | Z13: =S13/I13*100 -> 174.64063
A14: Њаљми умумии гардиши савдо дар њама соњањо | B14: млн. сомонї | C14: 47563.4 | D14: 111.2 | E14: 56124.4 | F14: 113.4 | G14: 65783.8 | H14: 113.6 | I14: 77307.1 | J14: 113.9 | K14: =[1]Household!$AG$81 -> 89946.541 | L14: =[1]Household!$AG$82 -> 114.15336 | M14: =[1]Household!$AH$81 -> 105319.77 | N14: =[1]Household!$AH$82 -> 114.4858 | O14: =[1]Household!$AI$81 -> 120054.47 | P14: =[1]Household!$AI$82 -> 113.559 | Q14: =[1]Household!$AJ$81 -> 138358.42 | R14: =[1]Household!$AJ$82 -> 113.89538 | S14: =[1]Household!$AK$81 -> 149157.72 | T14: =[1]Household!$AK$82 -> 108.35112 | U14: =[1]Household!$AL$81 -> 160879.07 | V14: =[1]Household!$AL$82 -> 109.75396 | W14: =[1]Household!$AM$81 -> 174656.34 | X14: =[1]Household!$AM$82 -> 109.31575 | Z14: =S14/I14*100 -> 192.94181 | AH14: =K13*L13/100 -> 8394.8556 | AI14: =M13/K13*100 -> 112.3
A15: аз он: гардиши савдои чакана | B15: млн. сомонї | C15: 39586.2 | D15: 110.2 | E15: 47540.5 | F15: 115.4 | G15: 55663 | H15: 113.5 | I15: 65705.6 | J15: 114.4 | K15: =[1]Household!$AG$84 -> 78696.141 | L15: =[1]Household!$AG$85 -> 114.0414 | M15: =[1]Household!$AH$84 -> 91582.412 | N15: =[1]Household!$AH$85 -> 114.2317 | O15: =[1]Household!$AI$84 -> 104395.19 | P15: =[1]Household!$AI$85 -> 113.33319 | Q15: =[1]Household!$AJ$84 -> 119274.5 | R15: =[1]Household!$AJ$85 -> 113.47425 | S15: =[1]Household!$AK$84 -> 129702.36 | T15: =[1]Household!$AK$85 -> 108.20577 | U15: =[1]Household!$AL$84 -> 139894.85 | V15: =[1]Household!$AL$85 -> 107.45769 | W15: =[1]Household!$AM$84 -> 151875.08 | X15: =[1]Household!$AM$85 -> 107.26362 | Z15: =S15/I15*100 -> 197.39925
A16: Њаљми хизматрасонињои пулакї дар њамаи соњањо | B16: млн. сомонї | C16: 18696.8 | D16: 116 | E16: 21760.3 | F16: 114.1 | G16: 25722.9 | H16: 113 | I16: 30470.2 | J16: 113.2 | K16: =[1]Household!$AG$88 -> 35439.755 | L16: =[1]Household!$AG$89 -> 114.93039 | M16: =[1]Household!$AH$88 -> 41254.485 | N16: =[1]Household!$AH$89 -> 113.90153 | O16: =[1]Household!$AI$88 -> 47612.182 | P16: =[1]Household!$AI$89 -> 113.70534 | Q16: =[1]Household!$AJ$88 -> 51548.635 | R16: =[1]Household!$AJ$89 -> 108.15958 | S16: =[1]Household!$AK$88 -> 56661.404 | T16: =[1]Household!$AK$89 -> 109.69894 | U16: =[1]Household!$AL$88 -> 62425.439 | V16: =[1]Household!$AL$89 -> 109.62465 | W16: =[1]Household!$AM$88 -> 64323.564 | X16: =[1]Household!$AM$89 -> 102.52799 | Z16: =S16/I16*100 -> 185.95678
A17: аз он: хизматрасонињои пулакї ба ањолї | B17: млн. сомонї | C17: 13866.9 | D17: 110.9 | E17: 16740.8 | F17: 118.4 | G17: 19094.9 | H17: 109 | I17: 22148.5 | J17: 110.9 | K17: =[1]Household!$AG$91 -> 25868.434 | L17: =[1]Household!$AG$92 -> 111.23374 | M17: =[1]Household!$AH$91 -> 29679.485 | N17: =[1]Household!$AH$92 -> 111.39072 | O17: =[1]Household!$AI$91 -> 33529.706 | P17: =[1]Household!$AI$92 -> 111.85412 | Q17: =[1]Household!$AJ$91 -> 37085.349 | R17: =[1]Household!$AJ$92 -> 110.49396 | S17: =[1]Household!$AK$91 -> 40763.6 | T17: =[1]Household!$AK$92 -> 108.83004 | U17: =[1]Household!$AL$91 -> 43351 | V17: =[1]Household!$AL$92 -> 105.81824 | W17: =[1]Household!$AM$91 -> 45945.403 | X17: =[1]Household!$AM$92 -> 103.90651 | Z17: =S17/I17*100 -> 184.04677
A18: Гардиши савдои хориљї | B18: млн. доллар | C18: 7309.5 | D18: 114.9 | E18: =+E19+E20 -> 8733.359 | F18: =+E18/C18*100 -> 119.47957 | G18: =+G19+G20 -> 8955.1 | H18: =+G18/E18*100 -> 102.53901 | I18: =+I19+I20 -> 10793.1 | J18: =+I18/G18*100 -> 120.52462 | K18: =+K19+K20 -> 11021.795 | L18: =+K18/I18*100 -> 102.1189 | M18: =+M19+M20 -> 11200.6 | N18: =+M18/K18*100 -> 101.62229 | O18: =+O19+O20 -> 11336.584 | P18: =+O18/M18*100 -> 101.21408 | Q18: =+Q19+Q20 -> 11664.552 | R18: =+Q18/O18*100 -> 102.89301 | S18: =+S19+S20 -> 11979.381 | T18: =+S18/Q18*100 -> 102.69902 | U18: =+U19+U20 -> 11976.135 | V18: =+U18/S18*100 -> 99.972908 | W18: =+W19+W20 -> 12300.515 | X18: =+W18/U18*100 -> 102.70855 | Z18: =S18/I18*100 -> 110.99111
A19: аз он: - содирот | C19: 2142 | D19: 99.6 | E19: =1861.478+243.5 -> 2104.978 | F19: =+E19/C19*100 -> 98.271615 | G19: 1947.5 | H19: =+G19/E19*100 -> 92.518782 | I19: 2487.9 | J19: =+I19/G19*100 -> 127.7484 | K19: ='5_IntTrade'!E74 -> 2672.7851 | L19: =+K19/I19*100 -> 107.43137 | M19: ='5_IntTrade'!F74 -> 2840.4586 | N19: =+M19/K19*100 -> 106.27336 | O19: ='5_IntTrade'!G74 -> 2973.4668 | P19: =+O19/M19*100 -> 104.68263 | Q19: ='5_IntTrade'!H74 -> 3140.6396 | R19: =+Q19/O19*100 -> 105.62215 | S19: ='5_IntTrade'!I74 -> 3298.4753 | T19: =+S19/Q19*100 -> 105.02559 | U19: ='5_IntTrade'!J74 -> 3051.7401 | V19: =+U19/S19*100 -> 92.51972 | W19: ='5_IntTrade'!K74 -> 3206.4144 | X19: =+W19/U19*100 -> 105.0684 | Z19: =S19/I19*100 -> 132.5807
A20: -воридот | C20: 5167.5 | D20: 122.8 | E20: =5880.1+748.281 -> 6628.381 | F20: =+E20/C20*100 -> 128.27056 | G20: 7007.6 | H20: =+G20/E20*100 -> 105.72114 | I20: 8305.2 | J20: =+I20/G20*100 -> 118.51704 | K20: ='5_IntTrade'!E75 -> 8349.0099 | L20: =+K20/I20*100 -> 100.5275 | M20: ='5_IntTrade'!F75 -> 8360.1413 | N20: =+M20/K20*100 -> 100.13333 | O20: ='5_IntTrade'!G75 -> 8363.1169 | P20: =+O20/M20*100 -> 100.03559 | Q20: ='5_IntTrade'!H75 -> 8523.9124 | R20: =+Q20/O20*100 -> 101.92268 | S20: ='5_IntTrade'!I75 -> 8680.9057 | T20: =+S20/Q20*100 -> 101.8418 | U20: ='5_IntTrade'!J75 -> 8924.3954 | V20: =+U20/S20*100 -> 102.80489 | W20: ='5_IntTrade'!K75 -> 9094.1011 | X20: =+W20/U20*100 -> 101.90159 | Z20: =S20/I20*100 -> 104.52374
G21: 2108.4 | J21: =I19/G21*100 -> 117.99943 | T21: =AVERAGE(L11,N11,P11,R11,T11) -> 114.14919
E22: =+G8-E8 -> 1942.3442 | F22: =+H8-F8 -> 4.7565408 | G22: =+I8-G8 -> 1685.8457 | H22: =+J8-H8 -> -3.6433823 | I22: =+K8-I8 -> 1777.501 | J22: =+L8-J8 -> -0.58827528 | K22: =+M8-K8 -> 1910.5465 | L22: =+N8-L8 -> -0.30641058 | ... N22: =+P8-N8 -> 0.14227548 | T22: =AVERAGE(L14,N14,P14,R14,T14) -> 112.88893
I23: =3119*109.8 -> 342466.2 | T23: =AVERAGE(L16,N16,P16,R16,T16) -> 112.07916
E24: =+E19/E18*100 -> 24.102731 | G24: =+G19/G18*100 -> 21.747384 | I24: =+I19/I18*100 -> 23.050838 | K24: =+K19/K18*100 -> 24.249998 | M24: =+M19/M18*100 -> 25.359879 | T24: =AVERAGE(L9,N9,P9,R9,T9) -> 124.03527
E25: =+E20/E18*100 -> 75.897269 | G25: =+G20/G18*100 -> 78.252616 | I25: =+I20/I18*100 -> 76.949162 | K25: =+K20/K18*100 -> 75.750002 | M25: =+M20/M18*100 -> 74.640121 | S25: =AVERAGE(K26,M26,O26,Q26,S26) -> 38.081699 | T25: =AVERAGE(L10,N10,P10,R10,T10) -> 108.45469
I26: =I12/I11*100 -> 46.215548 | K26: =K12/K11*100 -> 43.365928 | M26: =M12/M11*100 -> 40.158206 | O26: =O12/O11*100 -> 37.915455 | Q26: =Q12/Q11*100 -> 35.159484 | S26: =S12/S11*100 -> 33.809424 | T26: =S5/K5*100 -> 163.07686
C27: =C28+C29 -> 7013.824 | D27: =D28+D29 -> 0 | E27: =E28+E29 -> 8036.481 | F27: =F28+F29 -> 232.83271 | G27: =G28+G29 -> 9794.106 | H27: =H28+H29 -> 229.7365 | I27: =I28+I29 -> 10921.976 | J27: =J28+J29 -> 224.16668 | ... P27: =P28+P29 -> 214.68302 | T27: =S51/K51*100 -> 163.49721
A28: аз он: - содирот молњо ва хизматрасонї | C28: =[2]BoP!K14 -> 1752.9 | E28: =[2]BoP!L14 -> 2105 | F28: =+E28/C28*100 -> 120.08671 | G28: =[2]BoP!M14 -> 2108.405 | H28: =+G28/E28*100 -> 100.16176 | I28: =[2]BoP!N14 -> 2384.1837 | J28: =+I28/G28*100 -> 113.07997 | K28: =[2]BoP!O14 -> 2646.4817 | L28: =+K28/I28*100 -> 111.00158 | M28: =[2]BoP!P14 -> 2924.6196 | N28: =+M28/K28*100 -> 110.50973 | O28: =[2]BoP!Q14 -> 3161.1126 | P28: =+O28/M28*100 -> 108.08628 | T28: =S8/K8*100 -> 149.48195
A29: -воридот молњо ва хизматрасонї | C29: =[2]BoP!K15 -> 5260.924 | E29: =[2]BoP!L15 -> 5931.481 | F29: =+E29/C29*100 -> 112.74599 | G29: =[2]BoP!M15 -> 7685.701 | H29: =+G29/E29*100 -> 129.57474 | I29: =[2]BoP!N15 -> 8537.7923 | J29: =+I29/G29*100 -> 111.08671 | K29: =[2]BoP!O15 -> 11770.761 | L29: =+K29/I29*100 -> 137.86656 | M29: =[2]BoP!P15 -> 12569.072 | N29: =+M29/K29*100 -> 106.78216 | O29: =[2]BoP!Q15 -> 13398.221 | P29: =+O29/M29*100 -> 106.59674 | T29: =AVERAGE(L12,N12,P12,R12,T12) -> 107.2
A30: Ќурби миёнасолона (1 $ нисбат ба сомонї)* | C30: 11.0258 | D30: =+C30/11.3089*100 -> 97.496662 | E30: 10.8445 | F30: =+E30/C30*100 -> 98.355675 | G30: 10.7986 | H30: =+G30/E30*100 -> 99.576744 | I30: 10.0409 | J30: =+I30/G30*100 -> 92.98335 | K30: ='1_Prices'!E90 -> 9.176678 | L30: =+K30/I30*100 -> 91.392983 | M30: ='1_Prices'!F90 -> 9.414024 | N30: =+M30/K30*100 -> 102.5864 | O30: ='1_Prices'!G90 -> 9.692052 | P30: =+O30/M30*100 -> 102.95334 | Q30: ='1_Prices'!H90 -> 9.882669 | R30: =+Q30/O30*100 -> 101.96674 | S30: ='1_Prices'!I90 -> 10.01421 | T30: =+S30/Q30*100 -> 101.33103 | U30: ='1_Prices'!J90 -> 10.29836 | V30: =+U30/S30*100 -> 102.83747 | W30: ='1_Prices'!K90 -> 10.46302 | X30: =+W30/U30*100 -> 101.5989
E32: =E19/E18*100 -> 24.102731 | G32: =G19/G18*100 -> 21.747384 | I32: =I19/I18*100 -> 23.050838 | K32: =K19/K18*100 -> 24.249998 | M32: =M19/M18*100 -> 25.359879 | O32: =O19/O18*100 -> 26.22895
E33: =E20/E18*100 -> 75.897269 | G33: =G20/G18*100 -> 78.252616 | I33: =I20/I18*100 -> 76.949162 | K33: =K20/K18*100 -> 75.750002 | M33: =M20/M18*100 -> 74.640121 | O33: =O20/O18*100 -> 73.77105
I35: =I9/I5*1000 -> 377.15621 | K35: =K9/K5*1000 -> 417.66788 | M35: =M9/M5*1000 -> 465.21302 | O35: =O9/O5*1000 -> 516.88661 | Q35: =Q9/Q5*1000 -> 566.41731 | S35: =S9/S5*1000 -> 514.95314
L36: =L11+N11+P11+R11+T11 -> 570.74596
L37: =L36/5 -> 114.14919
L38: =L14+N14+P14+R14+T14 -> 564.44466
L39: =L38/5 -> 112.88893
L40: =L16+N16+P16+R16+T16 -> 560.39579
L41: =L40/5 -> 112.07916
L42: =L5+N5+P5+R5+T5 -> 542.1622
...

Sheet посл.вар.
A1: Сенарияи шиддатнок-Нишондиҳандаҳои асосии макроиќтисодии Љумҳурии Тољикистон барои солҳои 2026-2030
A2: Нишондињандањо | B2: Воњиди ченак | C2: Соли 2022 | E2: Соли 2023 | G2: Соли 2024 | I2: Соли 2025 | K2: Соли 2026 | M2: Соли 2027 | O2: Соли 2028 | Q2: Соли 2029 | S2: Соли 2030 | U2: Соли 2031 | W2: Соли 2032 | Y2: 2024
C3: Воќеї | D3: нисбат ба соли 2021 (бо фоиз) | E3: Воќеї | F3: нисбат ба соли 2022 (бо фоиз) | G3: Воќеї | H3: нисбат ба соли 2023 (бо фоиз) | I3: Бањодињї | J3: нисбат ба соли 2024 (бо фоиз) | K3: Дурнамо | L3: нисбат ба соли 2025 (бо фоиз) | M3: Дурнамо | N3: нисбат ба соли 2026 (бо фоиз) | O3: Дурнамо | P3: нисбат ба соли 2027 (бо фоиз) | Q3: Дурнамо | R3: нисбат ба соли 2027 (бо фоиз) | S3: Дурнамо | T3: нисбат ба соли 2027 (бо фоиз) | U3: Дурнамо | V3: нисбат ба соли 2027 (бо фоиз) | W3: Дурнамо | X3: нисбат ба соли 2027 (бо фоиз) | Z3: Соли 2023 | AB3: Соли 2024 | AD3: Соли 2025 | AF3: Соли 2026 | AH3: Соли 2027 | AJ3: Соли 2028
A4: Шумораи ањолї (ба њисоби миёнаи солона) | B4: Њазор нафар | C4: 9982.6 | D4: 101.8 | E4: 10183.4 | F4: =+E4/C4*100 -> 102.0115 | G4: 10382.1 | H4: =+G4/E4*100 -> 101.95121 | I4: =+G4*J4/100 -> 10589.742 | J4: 102 | K4: =+I4*L4/100 -> 10812.127 | L4: 102.1 | M4: =+K4*N4/100 -> 11049.993 | N4: 102.2 | O4: =+M4*P4/100 -> 11304.143 | P4: 102.3 | Q4: =+O4*P4/100 -> 11564.139 | R4: 102.3 | S4: =+Q4*R4/100 -> 11830.114 | T4: 102.4 | U4: =+S4*T4/100 -> 12114.036 | V4: 102.4 | W4: =+U4*V4/100 -> 12404.773 | X4: 102.4 | Y4: 10382.1 | Z4: =C4*D4/100 -> 10162.287 | AA4: =E4/C4*100 -> 102.0115 | AB4: =E4*F4/100 -> 10388.239 | AC4: =G4/E4*100 -> 101.95121 | AD4: =G4*H4/100 -> 10584.677 | AE4: =I4/G4*100 -> 102 | AF4: =I4*J4/100 -> 10801.537 | AG4: =K4/I4*100 -> 102.1 | AH4: =K4*L4/100 -> 11039.181 | AI4: =M4/K4*100 -> 102.2 | AJ4: =M4*N4/100 -> 11293.093 | AK4: =O4/M4*100 -> 102.3
A5: Маљмўи мањсулоти дохилї | B5: млн. сомонї | C5: =+[2]GDP!K2 -> 118181.7 | D5: =+[2]GDP!K3 -> 108.03592 | E5: =+[2]GDP!L2 -> 132781.9 | F5: =+[2]GDP!L3 -> 108.31977 | G5: 153402.2 | H5: 108.4 | I5: ='Итог-Модел CGE'!I5 -> 176919 | J5: ='Итог-Модел CGE'!J5 -> 108.4 | K5: ='Итог-Модел CGE'!K5 -> 199898.14 | L5: ='Итог-Модел CGE'!L5 -> 108.516 | M5: ='Итог-Модел CGE'!M5 -> 225457.17 | N5: ='Итог-Модел CGE'!N5 -> 108.37389 | O5: ='Итог-Модел CGE'!O5 -> 254612 | P5: ='Итог-Модел CGE'!P5 -> 108.6252 | ... X5: ='Итог-Модел CGE'!X5 -> 108.10939 | Y5: 153402.2
A6: Индекс-дефлятори ММД | B6: бо фоиз | D6: =+[2]GDP!K4 -> 108.22628 | F6: =+[2]GDP!L4 -> 103.7244 | H6: 108.2 | J6: =GDP!Q35 -> 104.07122 | L6: =GDP!R35 -> 103.9643 | N6: =GDP!S35 -> 105.06575 | P6: =GDP!T35 -> 103.85382 | R6: =GDP!AN35 -> 104.10115 | T6: =GDP!AQ35 -> 103.96034 | V6: =GDP!AS35 -> 0 | X6: =GDP!AU35 -> 106.39305
A7: Таваррум | B7: бо фоиз | D7: =+[2]Monetary!K3 -> 106.6 | F7: 103.7 | H7: 103.6 | J7: ='Итог-Модел CGE'!J7 -> 103.5 | L7: ='Итог-Модел CGE'!L7 -> 103.92894 | N7: ='Итог-Модел CGE'!N7 -> 104.00219 | P7: ='Итог-Модел CGE'!P7 -> 103.83918 | R7: ='Итог-Модел CGE'!R7 -> 103.94069 | T7: ='Итог-Модел CGE'!T7 -> 104.0531 | V7: ='Итог-Модел CGE'!V7 -> 104.40046 | X7: ='Итог-Модел CGE'!X7 -> 104.36099
A8: ММД ба њар нафар ањолї | B8: сомонї | C8: =+C5/C4*1000 -> 11838.769 | D8: =+C8/10312*100 -> 114.80576 | E8: =+E5/E4*1000 -> 13039.054 | F8: =+E8/C8*100 -> 110.13859 | G8: =+G5/G4*1000 -> 14775.643 | H8: =+G8/E8*100 -> 113.31837 | I8: ='Итог-Модел CGE'!I8 -> 16667.372 | J8: ='Итог-Модел CGE'!J8 -> 111.25283 | K8: ='Итог-Модел CGE'!K8 -> 18444.873 | L8: ='Итог-Модел CGE'!L8 -> 110.66455 | M8: ='Итог-Модел CGE'!M8 -> 20355.419 | N8: ='Итог-Модел CGE'!N8 -> 110.35814 | O8: ='Итог-Модел CGE'!O8 -> 22492.824 | P8: ='Итог-Модел CGE'!P8 -> 110.50042 | ... X8: ='Итог-Модел CGE'!X8 -> 109.97152 | Y8: =+Y5/Y4*1000 -> 14775.643
A9: Њаљми мањсулоти саноатї | B9: млн. сомонї | C9: 42804.2 | D9: 115.4 | E9: =+[2]Industry!M4 -> 53819 | F9: =+[2]Industry!M18 -> 120 | G9: 53819 | H9: 120 | I9: ='Итог-Модел CGE'!I9 -> 66726.1 | J9: ='Итог-Модел CGE'!J9 -> 122.1 | K9: ='Итог-Модел CGE'!K9 -> 83491.033 | L9: ='Итог-Модел CGE'!L9 -> 125 | M9: ='Итог-Модел CGE'!M9 -> 104885.61 | N9: ='Итог-Модел CGE'!N9 -> 125 | O9: ='Итог-Модел CGE'!O9 -> 131605.53 | P9: ='Итог-Модел CGE'!P9 -> 125.1 | ... X9: ='Итог-Модел CGE'!X9 -> 120.08717
A10: Њаљми мањсулоти кишоварзї | B10: млн. сомонї | C10: 49272.4 | D10: 108 | E10: =+[2]Agriculture!L2 -> 63028.4 | F10: =+[2]Agriculture!L3 -> 109 | G10: 73981.3 | H10: 110.6 | I10: ='Итог-Модел CGE'!I10 -> 84653.8 | J10: ='Итог-Модел CGE'!J10 -> 109.5 | K10: ='Итог-Модел CGE'!K10 -> 95155.45 | L10: ='Итог-Модел CGE'!L10 -> 108.92031 | M10: ='Итог-Модел CGE'!M10 -> 104590.97 | N10: ='Итог-Модел CGE'!N10 -> 108.61255 | O10: ='Итог-Модел CGE'!O10 -> 114715.95 | P10: ='Итог-Модел CGE'!P10 -> 108.27301 | ... X10: ='Итог-Модел CGE'!X10 -> 107.54578
A11: Маблаѓгузорї ба сармояи асосї | B11: млн. сомонї | C11: 16279.5 | D11: 111.4 | E11: =+[2]OEA!L22 -> 19859 | F11: =+E11/C11*100 -> 121.98778 | G11: 22543 | H11: 108.4 | I11: ='Итог-Модел CGE'!I11 -> 28736 | J11: ='Итог-Модел CGE'!J11 -> 123 | K11: ='Итог-Модел CGE'!K11 -> 32767.972 | L11: ='Итог-Модел CGE'!L11 -> 114.03108 | M11: ='Итог-Модел CGE'!M11 -> 38923.922 | N11: ='Итог-Модел CGE'!N11 -> 118.78648 | O11: ='Итог-Модел CGE'!O11 -> 44524.431 | P11: ='Итог-Модел CGE'!P11 -> 114.38835 | ... X11: ='Итог-Модел CGE'!X11 -> 115.81211
A12: аз чумла аз њисоби буљети давлатї | B12: млн. сомонї | C12: 6736.9 | D12: 110.3 | E12: =+[2]OEA!L23 -> 7922.5 | F12: =+E12/C12*100 -> 117.5986 | G12: 9830.5 | H12: 118.5 | I12: ='GDP-total'!E44 -> 15631.149 | J12: =+I12/G12*100 -> 159.00665 | K12: ='GDP-total'!F44 -> 16881.64 | L12: =+K12/I12*100 -> 108 | M12: ='GDP-total'!G44 -> 18063.355 | N12: =+M12/K12*100 -> 107 | O12: ='GDP-total'!H44 -> 18785.889 | P12: =+O12/M12*100 -> 104 | Q12: ='GDP-total'!I44 -> 19725.184 | R12: =+Q12/O12*100 -> 105 | S12: ='GDP-total'!J44 -> 21697.702 | T12: =+S12/Q12*100 -> 110 | U12: ='GDP-total'!L44 -> 1421.0135 | V12: =+U12/S12*100 -> 6.5491428 | W12: ='GDP-total'!N44 -> 1181.7148 | X12: =+W12/U12*100 -> 83.16
A13: Сармоягузории хориљї (қарз, грант, мустақим) | B13: млн. доллар | C13: 2577 | E13: 2690 | F13: =+E13/C13*100 -> 104.38494 | G13: 4905.6 | H13: =+G13/E13*100 -> 182.36431 | I13: ='Итог-Модел CGE'!I13 -> 6925.3 | J13: ='Итог-Модел CGE'!J13 -> 135.08563 | K13: ='Итог-Модел CGE'!K13 -> 7624.7553 | L13: ='Итог-Модел CGE'!L13 -> 110.1 | M13: ='Итог-Модел CGE'!M13 -> 8562.6002 | N13: ='Итог-Модел CGE'!N13 -> 112.3 | O13: ='Итог-Модел CGE'!O13 -> 9598.6748 | P13: ='Итог-Модел CGE'!P13 -> 112.1 | ... X13: ='Итог-Модел CGE'!X13 -> 112.1
A14: Гардиши савдои дохилӣ | B14: млн. сомонї | C14: 47563.4 | D14: 111.2 | E14: =+[2]Household!L3 -> 56124.4 | F14: =+[2]Household!L4 -> 113.4 | G14: 65783.8 | H14: 113.6 | I14: ='Итог-Модел CGE'!I14 -> 77307.1 | J14: ='Итог-Модел CGE'!J14 -> 113.9 | K14: ='Итог-Модел CGE'!K14 -> 89946.541 | L14: ='Итог-Модел CGE'!L14 -> 114.15336 | M14: ='Итог-Модел CGE'!M14 -> 105319.77 | N14: ='Итог-Модел CGE'!N14 -> 114.4858 | O14: ='Итог-Модел CGE'!O14 -> 120054.47 | P14: ='Итог-Модел CGE'!P14 -> 113.559 | ... X14: ='Итог-Модел CGE'!X14 -> 109.31575 | AH14: =K13*L13/100 -> 8394.8556 | AI14: =M13/K13*100 -> 112.3
A15: аз он: гардиши савдои чакана | B15: млн. сомонї | C15: 39586.2 | D15: 110.2 | E15: =+[2]Household!L9 -> 47540.5 | F15: =+[2]Household!L11 -> 115.4 | G15: 55663 | H15: 113.5 | I15: =+[2]Household!N9 -> 63081.371 | J15: =+[2]Household!N11 -> 107.9169 | K15: =+[2]Household!O9 -> 71753.534 | L15: =+[2]Household!O11 -> 107.40849 | M15: =+[2]Household!P9 -> 79859.123 | N15: =+[2]Household!P11 -> 105.64028 | O15: =+[2]Household!Q9 -> 87893.051 | P15: =+[2]Household!Q11 -> 104.57593 | Q15: =[3]Household!$AJ$9 -> 96368.262 | R15: =+[4]Household!R11 -> 104.54414 | S15: =[3]Household!$AK$9 -> 111046.18 | T15: =[3]Household!$AK$11 -> 109.99728 | U15: =[3]Household!$AK$9 -> 111046.18 | V15: =[3]Household!$AK$11 -> 109.99728 | W15: =[3]Household!$AK$9 -> 111046.18 | X15: =[3]Household!$AK$11 -> 109.99728
A16: Хизматрасонии пулакї | B16: млн. сомонї | C16: 18696.8 | D16: 116 | E16: =+[2]Household!L15 -> 21760.3 | F16: =+[2]Household!L16 -> 114.1 | G16: 25722.9 | H16: 113 | I16: ='Итог-Модел CGE'!I16 -> 30470.2 | J16: ='Итог-Модел CGE'!J16 -> 113.2 | K16: ='Итог-Модел CGE'!K16 -> 35439.755 | L16: ='Итог-Модел CGE'!L16 -> 114.93039 | M16: ='Итог-Модел CGE'!M16 -> 41254.485 | N16: ='Итог-Модел CGE'!N16 -> 113.90153 | O16: ='Итог-Модел CGE'!O16 -> 47612.182 | P16: ='Итог-Модел CGE'!P16 -> 113.70534 | ... X16: ='Итог-Модел CGE'!X16 -> 102.52799
A17: аз он: хизматрасонињои пулакї ба ањолї | B17: млн. сомонї | C17: 13866.9 | D17: 110.9 | E17: =+[2]Household!L18 -> 16740.8 | F17: =+[2]Household!L20 -> 118.4 | G17: 19094.9 | H17: 109 | I17: =+[2]Household!N18 -> 20828.754 | J17: =+[2]Household!N20 -> 109.0802 | K17: =+[2]Household!O18 -> 23917.845 | L17: =+[2]Household!O20 -> 120.87462 | M17: =+[2]Household!P18 -> 26619.708 | N17: =+[2]Household!P20 -> 111.29643 | O17: =+[2]Household!Q18 -> 30111.508 | P17: =+[2]Household!Q20 -> 114.25995 | Q17: =+[4]Household!R18 -> 34438.528 | R17: =+[4]Household!R20 -> 105.42107 | S17: =+[4]Household!S18 -> 38378.647 | T17: =+[4]Household!S20 -> 107.15483 | U17: =+[4]Household!U18 -> 0 | V17: =+[4]Household!U20 -> 0 | W17: =+[4]Household!W18 -> 0 | X17: =+[4]Household!W20 -> 0
A18: Гардиши савдои хориљї | B18: млн. доллар | C18: 7309.5 | D18: 114.9 | E18: =+E19+E20 -> 8328.9 | F18: =+E18/C18*100 -> 113.94623 | G18: =+G19+G20 -> 8955 | H18: =+G18/E18*100 -> 107.5172 | I18: ='Итог-Модел CGE'!I18 -> 10793.1 | J18: ='Итог-Модел CGE'!J18 -> 120.52462 | K18: ='Итог-Модел CGE'!K18 -> 11021.795 | L18: ='Итог-Модел CGE'!L18 -> 102.1189 | M18: ='Итог-Модел CGE'!M18 -> 11200.6 | N18: ='Итог-Модел CGE'!N18 -> 101.62229 | O18: ='Итог-Модел CGE'!O18 -> 11336.584 | P18: ='Итог-Модел CGE'!P18 -> 101.21408 | ... X18: ='Итог-Модел CGE'!X18 -> 102.70855
A19: аз он: - содирот | C19: 2142 | D19: 99.6 | E19: =[2]Results!L31 -> 2448.8 | F19: =+E19/C19*100 -> 114.32306 | G19: 1947.4 | H19: =+G19/E19*100 -> 79.524665 | I19: ='5_IntTrade'!F74 -> 2840.4586 | J19: =+I19/G19*100 -> 145.85902 | K19: ='5_IntTrade'!G74 -> 2973.4668 | L19: =+K19/I19*100 -> 104.68263 | M19: ='5_IntTrade'!H74 -> 3140.6396 | N19: =+M19/K19*100 -> 105.62215 | O19: ='5_IntTrade'!I74 -> 3298.4753 | P19: =+O19/M19*100 -> 105.02559 | Q19: ='5_IntTrade'!J74 -> 3051.7401 | R19: =+Q19/O19*100 -> 92.51972 | S19: ='5_IntTrade'!K74 -> 3206.4144 | T19: =+S19/Q19*100 -> 105.0684
A20: -воридот | C20: 5167.5 | D20: 122.8 | E20: =[2]Results!L33 -> 5880.1 | F20: =+E20/C20*100 -> 113.79003 | G20: 7007.6 | H20: =+G20/E20*100 -> 119.17484 | I20: ='5_IntTrade'!F75 -> 8360.1413 | J20: =+I20/G20*100 -> 119.30106 | K20: ='5_IntTrade'!G75 -> 8363.1169 | L20: =+K20/I20*100 -> 100.03559 | M20: ='5_IntTrade'!H75 -> 8523.9124 | N20: =+M20/K20*100 -> 101.92268 | O20: ='5_IntTrade'!I75 -> 8680.9057 | P20: =+O20/M20*100 -> 101.8418 | Q20: ='5_IntTrade'!J75 -> 8924.3954 | R20: =+Q20/O20*100 -> 102.80489 | S20: ='5_IntTrade'!K75 -> 9094.1011 | T20: =+S20/Q20*100 -> 101.90159
G21: 2108.4 | J21: =I19/G21*100 -> 134.72105
E22: =+G8-E8 -> 1736.5889 | F22: =+H8-F8 -> 3.1797763 | G22: =+I8-G8 -> 1891.729 | H22: =+J8-H8 -> -2.0655362 | I22: =+K8-I8 -> 1777.501 | J22: =+L8-J8 -> -0.58827528 | K22: =+M8-K8 -> 1910.5465 | L22: =+N8-L8 -> -0.30641058 | ... N22: =+P8-N8 -> 0.14227548
I23: =3119*109.8 -> 342466.2
E24: =+E19/E18*100 -> 29.401241 | G24: =+G19/G18*100 -> 21.74651 | I24: =+I19/I18*100 -> 26.317357 | K24: =+K19/K18*100 -> 26.978063 | M24: =+M19/M18*100 -> 28.039923
E25: =+E20/E18*100 -> 70.598759 | G25: =+G20/G18*100 -> 78.25349 | I25: =+I20/I18*100 -> 77.458203 | K25: =+K20/K18*100 -> 75.877993 | M25: =+M20/M18*100 -> 76.102284
C27: =C28+C29 -> 7013.824 | D27: =D28+D29 -> 0 | E27: =E28+E29 -> 8036.481 | F27: =F28+F29 -> 232.83271 | G27: =G28+G29 -> 9794.106 | H27: =H28+H29 -> 229.7365 | I27: =I28+I29 -> 10921.976 | J27: =J28+J29 -> 224.16668 | ... P27: =P28+P29 -> 214.68302
A28: аз он: - содирот молњо ва хизматрасонї | C28: =[2]BoP!K14 -> 1752.9 | E28: =[2]BoP!L14 -> 2105 | F28: =+E28/C28*100 -> 120.08671 | G28: =[2]BoP!M14 -> 2108.405 | H28: =+G28/E28*100 -> 100.16176 | I28: =[2]BoP!N14 -> 2384.1837 | J28: =+I28/G28*100 -> 113.07997 | K28: =[2]BoP!O14 -> 2646.4817 | L28: =+K28/I28*100 -> 111.00158 | M28: =[2]BoP!P14 -> 2924.6196 | N28: =+M28/K28*100 -> 110.50973 | O28: =[2]BoP!Q14 -> 3161.1126 | P28: =+O28/M28*100 -> 108.08628
A29: -воридот молњо ва хизматрасонї | C29: =[2]BoP!K15 -> 5260.924 | E29: =[2]BoP!L15 -> 5931.481 | F29: =+E29/C29*100 -> 112.74599 | G29: =[2]BoP!M15 -> 7685.701 | H29: =+G29/E29*100 -> 129.57474 | I29: =[2]BoP!N15 -> 8537.7923 | J29: =+I29/G29*100 -> 111.08671 | K29: =[2]BoP!O15 -> 11770.761 | L29: =+K29/I29*100 -> 137.86656 | M29: =[2]BoP!P15 -> 12569.072 | N29: =+M29/K29*100 -> 106.78216 | O29: =[2]BoP!Q15 -> 13398.221 | P29: =+O29/M29*100 -> 106.59674
A30: Ќурби миёнасолона (1 $ нисбат ба сомонї)* | C30: 11.0258 | D30: =+C30/11.3089*100 -> 97.496662 | E30: 10.8445 | F30: =+E30/C30*100 -> 98.355675 | G30: 10.7986 | H30: =+G30/E30*100 -> 99.576744 | I30: ='1_Prices'!F90 -> 9.414024 | J30: =+I30/G30*100 -> 87.17819 | K30: ='1_Prices'!G90 -> 9.692052 | L30: =+K30/I30*100 -> 102.95334 | M30: ='1_Prices'!H90 -> 9.882669 | N30: =+M30/K30*100 -> 101.96674 | O30: ='1_Prices'!I90 -> 10.01421 | P30: =+O30/M30*100 -> 101.33103
E32: =E19/E18*100 -> 29.401241 | G32: =G19/G18*100 -> 21.74651 | I32: =I19/I18*100 -> 26.317357 | K32: =K19/K18*100 -> 26.978063 | M32: =M19/M18*100 -> 28.039923 | O32: =O19/O18*100 -> 29.095849
E33: =E20/E18*100 -> 70.598759 | G33: =G20/G18*100 -> 78.25349 | I33: =I20/I18*100 -> 77.458203 | K33: =K20/K18*100 -> 75.877993 | M33: =M20/M18*100 -> 76.102284 | O33: =O20/O18*100 -> 76.574266
I35: =I9/I5*1000 -> 377.15621 | K35: =K9/K5*1000 -> 417.66788 | M35: =M9/M5*1000 -> 465.21302 | O35: =O9/O5*1000 -> 516.88661 | Q35: =Q9/Q5*1000 -> 566.41731 | S35: =S9/S5*1000 -> 514.95314
L36: =L11+N11+P11+R11+T11 -> 570.74596
L37: =L36/5 -> 114.14919
L38: =L14+N14+P14+R14+T14 -> 564.44466
L39: =L38/5 -> 112.88893
L40: =L16+N16+P16+R16+T16 -> 560.39579
L41: =L40/5 -> 112.07916
L42: =L5+N5+P5+R5+T5 -> 542.1622
L43: =L42/5 -> 108.43244
...

Sheet 2025-2029
A1: «Дар бораи дурнамои нишондиҳандаҳои асосии макроиќтисодии Љумҳурии Тољикистон барои солњои 2026-2029»
A2: Нишондињандањо | B2: Соли 2025 воќеї | D2: Соли 2026 баҳодиҳӣ | F2: Соли 2027 дурнамо | H2: Соли 2028 | J2: Соли 2029
B4: млрд. сомонї | C4: Рушд бо % | D4: млрд. сомонї | E4: Рушд бо % | F4: млрд. сомонї | G4: Рушд бо % | H4: млрд. сомонї | I4: Рушд бо % | J4: млрд. сомонї | K4: Рушд бо %
A5: Маљмўи мањсулоти дохилӣ | B5: ='Итог-Модел CGE'!I5/1000 -> 176.919 | C5: ='Итог-Модел CGE'!J5 -> 108.4 | D5: ='Итог-Модел CGE'!K5/1000 -> 199.89814 | E5: ='Итог-Модел CGE'!L5 -> 108.516 | F5: ='Итог-Модел CGE'!M5/1000 -> 225.45717 | G5: ='Итог-Модел CGE'!N5 -> 108.37389 | H5: ='Итог-Модел CGE'!O5/1000 -> 254.612 | I5: ='Итог-Модел CGE'!P5 -> 108.6252 | J5: ='Итог-Модел CGE'!Q5/1000 -> 290.95714 | K5: ='Итог-Модел CGE'!R5 -> 108.76495
A6: Маљмўи мањсулоти саноатї | B6: ='Итог-Модел CGE'!I9/1000 -> 66.7261 | C6: ='Итог-Модел CGE'!J9 -> 122.1 | D6: ='Итог-Модел CGE'!K9/1000 -> 83.491033 | E6: ='Итог-Модел CGE'!L9 -> 125 | F6: ='Итог-Модел CGE'!M9/1000 -> 104.88561 | G6: ='Итог-Модел CGE'!N9 -> 125 | H6: ='Итог-Модел CGE'!O9/1000 -> 131.60553 | I6: ='Итог-Модел CGE'!P9 -> 125.1 | J6: ='Итог-Модел CGE'!Q9/1000 -> 164.80316 | K6: ='Итог-Модел CGE'!R9 -> 125.1
A7: Маљмўи мањсулоти кишоварзї | B7: ='Итог-Модел CGE'!I10/1000 -> 84.6538 | C7: ='Итог-Модел CGE'!J10 -> 109.5 | D7: ='Итог-Модел CGE'!K10/1000 -> 95.15545 | E7: ='Итог-Модел CGE'!L10 -> 108.92031 | F7: ='Итог-Модел CGE'!M10/1000 -> 104.59097 | G7: ='Итог-Модел CGE'!N10 -> 108.61255 | H7: ='Итог-Модел CGE'!O10/1000 -> 114.71595 | I7: ='Итог-Модел CGE'!P10 -> 108.27301 | J7: ='Итог-Модел CGE'!Q10/1000 -> 125.43468 | K7: ='Итог-Модел CGE'!R10 -> 108.15402
A8: Маблаѓгузорї ба сармояи асосї | B8: ='Итог-Модел CGE'!I11/1000 -> 28.736 | C8: ='Итог-Модел CGE'!J11 -> 123 | D8: ='Итог-Модел CGE'!K11/1000 -> 32.767972 | E8: ='Итог-Модел CGE'!L11 -> 114.03108 | F8: ='Итог-Модел CGE'!M11/1000 -> 38.923922 | G8: ='Итог-Модел CGE'!N11 -> 118.78648 | H8: ='Итог-Модел CGE'!O11/1000 -> 44.524431 | I8: ='Итог-Модел CGE'!P11 -> 114.38835 | J8: ='Итог-Модел CGE'!Q11/1000 -> 51.375484 | K8: ='Итог-Модел CGE'!R11 -> 115.38718
A9: Сармоягузории хориҷӣ (қарз, грант, мустақим)
A10: Гардиши савдои дохилї | B10: ='Итог-Модел CGE'!I14/1000 -> 77.3071 | C10: ='Итог-Модел CGE'!J14 -> 113.9 | D10: ='Итог-Модел CGE'!K14/1000 -> 89.946541 | E10: ='Итог-Модел CGE'!L14 -> 114.15336 | F10: ='Итог-Модел CGE'!M14/1000 -> 105.31977 | G10: ='Итог-Модел CGE'!N14 -> 114.4858 | H10: ='Итог-Модел CGE'!O14/1000 -> 120.05447 | I10: ='Итог-Модел CGE'!P14 -> 113.559 | J10: ='Итог-Модел CGE'!Q14/1000 -> 138.35842 | K10: ='Итог-Модел CGE'!R14 -> 113.89538
A11: Хизматрасонии пулакї | B11: ='Итог-Модел CGE'!I16/1000 -> 30.4702 | C11: ='Итог-Модел CGE'!J16 -> 113.2 | D11: ='Итог-Модел CGE'!K16/1000 -> 35.439755 | E11: ='Итог-Модел CGE'!L16 -> 114.93039 | F11: ='Итог-Модел CGE'!M16/1000 -> 41.254485 | G11: ='Итог-Модел CGE'!N16 -> 113.90153 | H11: ='Итог-Модел CGE'!O16/1000 -> 47.612182 | I11: ='Итог-Модел CGE'!P16 -> 113.70534 | J11: ='Итог-Модел CGE'!Q16/1000 -> 51.548635 | K11: ='Итог-Модел CGE'!R16 -> 108.15958
A12: аз он: - ба ањолї | B12: ='Итог-Модел CGE'!I17/1000 -> 22.1485 | C12: ='Итог-Модел CGE'!J17 -> 110.9 | D12: ='Итог-Модел CGE'!K17/1000 -> 25.868434 | E12: ='Итог-Модел CGE'!L17 -> 111.23374 | F12: ='Итог-Модел CGE'!M17/1000 -> 29.679485 | G12: ='Итог-Модел CGE'!N17 -> 111.39072 | H12: ='Итог-Модел CGE'!O17/1000 -> 33.529706 | I12: ='Итог-Модел CGE'!P17 -> 111.85412 | J12: ='Итог-Модел CGE'!Q17/1000 -> 37.085349 | K12: ='Итог-Модел CGE'!R17 -> 110.49396
A13: Гардиши савдои хориљї (млн. доллар) | B13: ='Итог-Модел CGE'!I18 -> 10793.1 | C13: ='Итог-Модел CGE'!J18 -> 120.52462 | D13: ='Итог-Модел CGE'!K18 -> 11021.795 | E13: =+D13/B13*100 -> 102.1189 | F13: ='Итог-Модел CGE'!M18 -> 11200.6 | G13: =+F13/D13*100 -> 101.62229 | H13: ='Итог-Модел CGE'!O18 -> 11336.584 | I13: =+H13/F13*100 -> 101.21408 | J13: ='Итог-Модел CGE'!Q18 -> 11664.552 | K13: =+J13/H13*100 -> 102.89301
A14: аз он: - содирот | B14: ='Итог-Модел CGE'!I19 -> 2487.9 | C14: ='Итог-Модел CGE'!J19 -> 127.7484 | D14: ='Итог-Модел CGE'!K19 -> 2672.7851 | E14: =+D14/B14*100 -> 107.43137 | F14: ='Итог-Модел CGE'!M19 -> 2840.4586 | G14: =+F14/D14*100 -> 106.27336 | H14: ='Итог-Модел CGE'!O19 -> 2973.4668 | I14: =+H14/F14*100 -> 104.68263 | J14: ='Итог-Модел CGE'!Q19 -> 3140.6396 | K14: =+J14/H14*100 -> 105.62215
A15: -воридот | B15: ='Итог-Модел CGE'!I20 -> 8305.2 | C15: ='Итог-Модел CGE'!J20 -> 118.51704 | D15: ='Итог-Модел CGE'!K20 -> 8349.0099 | E15: =+D15/B15*100 -> 100.5275 | F15: ='Итог-Модел CGE'!M20 -> 8360.1413 | G15: =+F15/D15*100 -> 100.13333 | H15: ='Итог-Модел CGE'!O20 -> 8363.1169 | I15: =+H15/F15*100 -> 100.03559 | J15: ='Итог-Модел CGE'!Q20 -> 8523.9124 | K15: =+J15/H15*100 -> 101.92268
A16: Индекс-дефлятори ММД | B16: - | C16: ='Итог-Модел CGE'!J6 -> 106.4 | D16: - | E16: ='Итог-Модел CGE'!L6 -> 104.12161 | F16: - | G16: ='Итог-Модел CGE'!N6 -> 104.07122 | H16: - | I16: ='Итог-Модел CGE'!P6 -> 103.9643 | J16: - | K16: ='Итог-Модел CGE'!R6 -> 105.06575
A17: Сатњи таваррум* | B17: - | C17: ='Итог-Модел CGE'!J7-100 -> 3.5 | D17: - | E17: 4,0* | F17: - | G17: 3,5* | H17: - | I17: 3,7* | J17: - | K17: 4,2*
A18: Ќурби миёнасолона (1 $ нисбат ба сомонї)* | B18: ='Итог-Модел CGE'!I30 -> 10.0409 | C18: =+B18/10.7986*100 -> 92.98335 | D18: ='Итог-Модел CGE'!K30 -> 9.176678 | E18: =+D18/B18*100 -> 91.392983 | F18: ='Итог-Модел CGE'!M30 -> 9.414024 | G18: =+F18/D18*100 -> 102.5864 | H18: ='Итог-Модел CGE'!O30 -> 9.692052 | I18: =+H18/F18*100 -> 102.95334 | J18: ='Итог-Модел CGE'!Q30 -> 9.882669 | K18: =+J18/H18*100 -> 101.96674
A19: Ќурби миёнасолона (1 $ нисбат ба сомонї)* маълумоти Бонки миллии Тоҷикистон | B19: 10.0409 | C19: =+B19/10.7986*100 -> 92.98335 | E19: =+D19/B19*100 -> 0 | G19: =+F19/D19*100 -> #DIV/0! | I19: =+H19/F19*100 -> #DIV/0! | K19: =+J19/H19*100 -> #DIV/0!
A20: *-Нишондињандањои мазкур интишор карда намешаванд.
E22: ='6_Closures'!F20 -> 104.00219 | F22: ='6_Closures'!G20 -> 103.83918 | G22: ='6_Closures'!H20 -> 103.94069 | H22: ='6_Closures'!I20 -> 104.0531
E23: ='1_Prices'!F90 -> 9.414024 | F23: ='1_Prices'!G90 -> 9.692052 | G23: ='1_Prices'!H90 -> 9.882669 | H23: ='1_Prices'!I90 -> 10.01421
A24: ММД долл. | B24: =B5/B18 -> 17.619835 | D24: =D5/D18 -> 21.78328 | F24: =F5/F18 -> 23.949075 | H24: =H5/H18 -> 26.270185 | J24: =J5/J18 -> 29.44115
B25: =B14/B24 -> 141.19883
B28: 10793.1 | C28: 120.52462 | D28: 10621.795 | E28: 98.412829 | F28: 11030.6 | G28: 103.84874 | H28: 11336.584 | I28: 102.77395 | J28: 11664.552 | K28: 102.89301
B29: 2487.9 | C29: 127.7484 | D29: 2672.7851 | E29: 107.43137 | F29: 2840.4586 | G29: 106.27336 | H29: 2973.4668 | I29: 104.68263 | J29: 3140.6396 | K29: 105.62215
B30: 8305.2 | C30: 118.51704 | D30: 7949.0099 | E30: 95.71124 | F30: 8190.1413 | G30: 103.03348 | H30: 8363.1169 | I30: 102.112 | J30: 8523.9124 | K30: 101.92268

Sheet 1_Prices
B2: Block 1: Prices | E2: 0.923 | F2: 0.934 | G2: 0.9011 | H2: 0.90001 | I2: 0.88 | J2: 0.9301 | K2: 0.85
A3: 1 | B3: Source: p_grp | E3: 1.032 | F3: 1.012 | G3: 1.013 | H3: 1.011 | I3: 1.008 | J3: 1.005 | K3: 1.002
A4: Equation | B4: Gross Output prices | C4: 2024 | D4: =C4+1 -> 2025 | E4: =D4+1 -> 2026 | F4: =E4+1 -> 2027 | G4: =F4+1 -> 2028 | H4: =G4+1 -> 2029 | I4: =H4+1 -> 2030 | J4: =I4+1 -> 2031 | K4: =J4+1 -> 2032
A5: 1 | B5: Agriculture (p_a) | C5: 1.000879 | D5: 1.040396 | E5: 1.036174 | F5: 1.047091 | G5: 1.039209 | H5: 1.060155 | I5: 1.054533 | J5: 1.075063 | K5: 1.09542
A6: =A5+1 -> 2 | B6: Mining (p_mi) | C6: 1.009833 | D6: 1.031612 | E6: 1.041602 | F6: 0.905 | G6: 0.935 | H6: 0.935 | I6: 0.935 | J6: 0.905 | K6: 0.901
A7: =A6+1 -> 3 | B7: Manufacturing (p_m) | C7: 1.003147 | D7: 1.033837 | E7: 1.042326 | F7: 1.055848 | G7: 1.009 | H7: 1.009 | I7: 1.009 | J7: 0.91 | K7: 0.907
A8: =A7+1 -> 4 | B8: Energy and Water (p_e) | C8: 1.004254 | D8: 1.020014 | E8: 1.035124 | F8: 1.053312 | G8: 1.052226 | H8: 1.085796 | I8: 1.02 | J8: 1.076408 | K8: 1
A9: =A8+1 -> 5 | B9: Construction (p_c) | C9: 1 | D9: 1.06 | E9: 1.06 | F9: 1.07 | G9: 1.045 | H9: 1.021 | I9: 1.035 | J9: 1.045 | K9: 1.055
A10: =A9+1 -> 6 | B10: Transport (p_t) | C10: 1.004766 | D10: 1.025735 | E10: 1.049202 | F10: 1.088025 | G10: 1.094247 | H10: 1.146252 | I10: 1.088428 | J10: 1.1057 | K10: 1.12234
A11: =A10+1 -> 7 | B11: Trade (p_tr) | C11: 1.000093 | D11: 1.010111 | E11: 1.020294 | F11: 1.045241 | G11: 1.054977 | H11: 1.049495 | I11: 1.059468 | J11: 1.069699 | K11: 1.080588
A12: =A11+1 -> 8 | B12: Financial services (p_fs) | C12: 1.000483 | D12: 1.07119 | E12: 1.067118 | F12: 1.091531 | G12: 1.109512 | H12: 1.131571 | I12: 1.151267 | J12: 1.199551 | K12: 1.20014
A13: =A12+1 -> 9 | B13: Public Services (p_ps) | C13: 1.000129 | D13: 1.010253 | E13: 1.040199 | F13: 1.030356 | G13: 1.040031 | H13: 1.05068 | I13: 1.060781 | J13: 1.07104 | K13: 1.091057
A14: =A13+1 -> 10 | B14: Market Services (p_ms) | C14: 1.000181 | D14: 1.010285 | E14: 1.002134 | F14: 1.030502 | G14: 1.030043 | H14: 1.040947 | I14: 1.036071 | J14: 1.046373 | K14: 1.061275
B15: Source: pva_grp
B16: Value added prices | C16: 2024 | D16: =C16+1 -> 2025 | E16: =D16+1 -> 2026 | F16: =E16+1 -> 2027 | G16: =F16+1 -> 2028 | H16: =G16+1 -> 2029 | I16: =H16+1 -> 2030 | J16: =I16+1 -> 2031 | K16: =J16+1 -> 2032
A17: 11 | B17: Agriculture (pva_a) | C17: 0.9958141 | D17: 1.070785 | E17: 1.06048 | F17: 1.080147 | G17: 1.013892 | H17: 0.9705722 | I17: 0.939447 | J17: 0.8989173 | K17: 0.9359334
A18: =A17+1 -> 12 | B18: Mining (pva_mi) | C18: 1.020986 | D18: 1.224783 | E18: 1.251685 | F18: 1.285737 | G18: 0.9245005 | H18: 0.918577 | I18: 0.8939355 | J18: 0.8895337 | K18: 0.8938999
A19: =A18+1 -> 13 | B19: Manufacturing (pva_m) | C19: 0.9954861 | D19: 0.9831472 | E19: 1.049954 | F19: 0.9841733 | G19: 1.053318 | H19: 1.050349 | I19: 1.093903 | J19: 1.074273 | K19: 1.073668
A20: =A19+1 -> 14 | B20: Energy and Water (pva_e) | C20: 1.005361 | D20: 1.03293 | E20: 0.8565347 | F20: 0.8391973 | G20: 0.6327221 | H20: 0.6008687 | I20: 0.5893384 | J20: 0.5732561 | K20: 0.6060239
A21: =A20+1 -> 15 | B21: Construction (pva_c) | C21: 0.9369689 | D21: 1.068781 | E21: 1.147408 | F21: 1.190035 | G21: 1.191113 | H21: 1.180669 | I21: 1.21292 | J21: 1.254364 | K21: 1.285813
A22: =A21+1 -> 16 | B22: Transport (pva_t) | C22: 1.001906 | D22: 1.074133 | E22: 1.137099 | F22: 1.404508 | G22: 1.405637 | H22: 1.418685 | I22: 1.402125 | J22: 1.531533 | K22: 1.618333
A23: =A22+1 -> 17 | B23: Trade (pva_tr) | C23: 0.9921399 | D23: 0.9773986 | E23: 0.9218877 | F23: 0.9924737 | G23: 0.8944123 | H23: 0.8589714 | I23: 0.8436901 | J23: 0.8823803 | K23: 0.8588048
A24: =A23+1 -> 18 | B24: Financial services (pva_fs) | C24: 1.163395 | D24: 1.221282 | E24: 1.176507 | F24: 1.157249 | G24: 1.161612 | H24: 1.148914 | I24: 0.9496975 | J24: 0.9214652 | K24: 0.8862919
A25: =A24+1 -> 19 | B25: Public Services (pva_ps) | C25: 0.9988407 | D25: 0.913445 | E25: 0.9205453 | F25: 0.9186769 | G25: 0.9258954 | H25: 0.9460649 | I25: 0.959806 | J25: 0.9788029 | K25: 0.9945043
A26: =A25+1 -> 20 | B26: Market Services (pva_ms) | C26: 0.3277719 | D26: 0.2614986 | E26: 0.216421 | F26: 0.2325555 | G26: 0.1930372 | H26: 0.1889256 | I26: 0.1700383 | J26: 0.1637706 | K26: 0.171378
B27: Source: pc_grp
B28: Purchaser's price of commodity | C28: 2024 | D28: =C28+1 -> 2025 | E28: =D28+1 -> 2026 | F28: =E28+1 -> 2027 | G28: =F28+1 -> 2028 | H28: =G28+1 -> 2029 | I28: =H28+1 -> 2030 | J28: =I28+1 -> 2031 | K28: =J28+1 -> 2032
A29: 21 | B29: Agriculture (pc_a) | C29: 1.041787 | D29: 1.08291 | E29: 1.084011 | F29: 1.09741 | G29: 1.088556 | H29: 1.108769 | I29: 1.104173 | J29: 1.125941 | K29: 1.145297
A30: =A29+1 -> 22 | B30: Mining (pc_mi) | C30: 1.085293 | D30: 1.122346 | E30: 1.126317 | F30: 1.141462 | G30: 1.160984 | H30: 1.177234 | I30: 1.188016 | J30: 1.203188 | K30: 1.1988
A31: =A30+1 -> 23 | B31: Manufacturing (pc_m) | C31: 1.068337 | D31: 1.108502 | E31: 1.124811 | F31: 1.142457 | G31: 1.16831 | H31: 1.160557 | I31: 1.16397 | J31: 1.185302 | K31: 1.194204
A32: =A31+1 -> 24 | B32: Energy and Water (pc_e) | C32: 1.088096 | D32: 1.100802 | E32: 1.112357 | F32: 1.129743 | G32: 1.142269 | H32: 1.153639 | I32: 1.170466 | J32: 1.122482 | K32: 1.151509
A33: =A32+1 -> 25 | B33: Construction (pc_c) | C33: 1.049556 | D33: 1.114042 | E33: 1.114077 | F33: 1.133341 | G33: 1.099701 | H33: 1.077389 | I33: 1.092021 | J33: 1.103971 | K33: 1.114146
A34: =A33+1 -> 26 | B34: Transport (pc_t) | C34: 1.049271 | D34: 1.081324 | E34: 1.099591 | F34: 1.135001 | G34: 1.157018 | H34: 1.193628 | I34: 1.144873 | J34: 1.173816 | K34: 1.189199
A35: =A34+1 -> 27 | B35: Trade (pc_tr) | C35: 1.024319 | D35: 1.034606 | E35: 1.044913 | F35: 1.070499 | G35: 1.080781 | H35: 1.074683 | I35: 1.084934 | J35: 1.095225 | K35: 1.106508
A36: =A35+1 -> 28 | B36: Financial services (pc_fs) | C36: 1.122912 | D36: 1.187823 | E36: 1.218403 | F36: 1.233254 | G36: 1.262584 | H36: 1.290641 | I36: 1.307805 | J36: 1.362435 | K36: 1.364337
A37: =A36+1 -> 29 | B37: Public Services (pc_ps) | C37: 1.044415 | D37: 1.057326 | E37: 1.088405 | F37: 1.082075 | G37: 1.097818 | H37: 1.110595 | I37: 1.122551 | J37: 1.136072 | K37: 1.155637
A38: =A37+1 -> 30 | B38: Market Services (pc_ms) | C38: 1.031891 | D38: 1.063449 | E38: 1.089969 | F38: 1.122195 | G38: 1.155365 | H38: 1.170013 | I38: 1.190202 | J38: 1.227756 | K38: 1.249274
B39: Source: pe_grp
B40: Export prices | C40: 2024 | D40: =C40+1 -> 2025 | E40: =D40+1 -> 2026 | F40: =E40+1 -> 2027 | G40: =F40+1 -> 2028 | H40: =G40+1 -> 2029 | I40: =H40+1 -> 2030 | J40: =I40+1 -> 2031 | K40: =J40+1 -> 2032
A41: 31 | B41: Agriculture (pe_a) | C41: 1.029226 | D41: 1.053384 | E41: 1.07359 | F41: 1.111289 | G41: 1.158822 | H41: 1.202739 | I41: 1.205697 | J41: 1.238696 | K41: 1.267527
...

Sheet 2_Production_1
R1: 1-вар.
B2: Block 2: Production (1) | R2: Block 2: Production (1)
B4: Intermediate consumption of commodity i in industry j (in real terms) | R4: Intermediate consumption of commodity i in industry j (in real terms)
B5: Source: di_a_grp | R5: Source: di_a_grp
B6: Agriculture | C6: 2024 | D6: =C6+1 -> 2025 | E6: =D6+1 -> 2026 | F6: =E6+1 -> 2027 | G6: =F6+1 -> 2028 | H6: =G6+1 -> 2029 | I6: =H6+1 -> 2030 | J6: =I6+1 -> 2031 | K6: =J6+1 -> 2032 | L6: Description | R6: Agriculture | S6: 2024 | T6: =S6+1 -> 2025 | U6: =T6+1 -> 2026 | V6: =U6+1 -> 2027 | W6: =V6+1 -> 2028 | X6: =W6+1 -> 2029 | Y6: =X6+1 -> 2030 | Z6: =Y6+1 -> 2031 | AA6: =Z6+1 -> 2032 | AB6: Description
B7: di_a_a | C7: 22311.89 | D7: 23949.15 | E7: 25153.86 | F7: 26119.58 | G7: 26875.09 | H7: 27778.03 | I7: 28209.41 | J7: 28862.45 | K7: 30113.7 | L7: Intermediate consumption of agriculture paid for agr, Commodities | R7: di_a_a | S7: 16464.13 | T7: 17682.88 | U7: 18563.21 | V7: 19275.91 | W7: 19841.17 | X7: 20509.8 | Y7: 20831.11 | Z7: 21312.3 | AA7: 22235.73 | AB7: Intermediate consumption of agriculture paid for agr, Commodities
B8: di_mi_a | C8: 296.3033 | D8: 318.0463 | E8: 334.0449 | F8: 346.8697 | G8: 356.903 | H8: 368.8941 | I8: 374.6229 | J8: 383.2953 | K8: 399.9119 | L8: Intermediate consumption of agriculture paid for mining commodities | R8: di_mi_a | S8: 218.6448 | T8: 234.8299 | U8: 246.5207 | V8: 255.9854 | W8: 263.492 | X8: 272.3715 | Y8: 276.6386 | Z8: 283.0287 | AA8: 295.2919 | AB8: Intermediate consumption of agriculture paid for mining commodities
B9: di_m_a | C9: 9523.852 | D9: 10222.72 | E9: 10736.95 | F9: 11149.17 | G9: 11471.66 | H9: 11857.08 | I9: 12041.22 | J9: 12319.97 | K9: 12854.06 | L9: Intermediate consumption of agriculture paid for manufact, Commodities | R9: di_m_a | S9: 7027.731 | T9: 7547.957 | U9: 7923.725 | V9: 8227.944 | W9: 8469.223 | X9: 8754.629 | Y9: 8891.782 | Z9: 9097.176 | AA9: 9491.343 | AB9: Intermediate consumption of agriculture paid for manufact, Commodities
B10: di_e_a | C10: 2353.256 | D10: 2525.94 | E10: 2653.002 | F10: 2754.857 | G10: 2834.542 | H10: 2929.776 | I10: 2975.274 | J10: 3044.151 | K10: 3176.121 | L10: Intermediate consumption of agriculture paid for energy commodities | R10: di_e_a | S10: 1736.488 | T10: 1865.031 | U10: 1957.88 | V10: 2033.049 | W10: 2092.667 | X10: 2163.188 | Y10: 2197.078 | Z10: 2247.829 | AA10: 2345.224 | AB10: Intermediate consumption of agriculture paid for energy commodities
B11: di_c_a | C11: 1577.79 | D11: 1693.57 | E11: 1778.761 | F11: 1847.052 | G11: 1900.478 | H11: 1964.33 | I11: 1994.835 | J11: 2041.015 | K11: 2129.497 | L11: Intermediate consumption of agriculture paid for construct, Commodities | R11: di_c_a | S11: 1164.265 | T11: 1250.449 | U11: 1312.702 | V11: 1363.101 | W11: 1403.073 | X11: 1450.355 | Y11: 1473.077 | Z11: 1507.104 | AA11: 1572.405 | AB11: Intermediate consumption of agriculture paid for construct, Commodities
B12: di_t_a | C12: 1893.044 | D12: 2031.957 | E12: 2134.17 | F12: 2216.106 | G12: 2280.208 | H12: 2356.817 | I12: 2393.418 | J12: 2448.825 | K12: 2554.986 | L12: Intermediate consumption of agriculture paid for trans, Services | R12: di_t_a | S12: 1396.893 | T12: 1500.298 | U12: 1574.989 | V12: 1635.458 | W12: 1683.417 | X12: 1740.147 | Y12: 1767.408 | Z12: 1808.234 | AA12: 1886.583 | AB12: Intermediate consumption of agriculture paid for trans, Services
B13: di_tr_a | C13: 110.991 | D13: 119.1356 | E13: 125.1284 | F13: 129.9324 | G13: 133.6907 | H13: 138.1824 | I13: 140.3283 | J13: 143.5769 | K13: 149.8012 | L13: Intermediate consumption of agriculture paid for trade services | R13: di_tr_a | S13: 81.90118 | T13: 87.96389 | U13: 92.34309 | V13: 95.88845 | W13: 98.70032 | X13: 102.0264 | Y13: 103.6248 | Z13: 106.0185 | AA13: 110.6121 | AB13: Intermediate consumption of agriculture paid for trade services
B14: di_fs_a | C14: 1881.664 | D14: 2019.742 | E14: 2121.341 | F14: 2202.784 | G14: 2266.5 | H14: 2342.65 | I14: 2379.03 | J14: 2434.104 | K14: 2539.627 | L14: Intermediate consumption of agriculture paid for fin, services | R14: di_fs_a | S14: 1388.496 | T14: 1491.279 | U14: 1565.521 | V14: 1625.627 | W14: 1673.297 | X14: 1729.686 | Y14: 1756.784 | Z14: 1797.364 | AA14: 1875.241 | AB14: Intermediate consumption of agriculture paid for fin, services
B15: di_ps_a | C15: 140.9403 | D15: 151.2826 | E15: 158.8925 | F15: 164.9928 | G15: 169.7652 | H15: 175.4689 | I15: 178.1939 | J15: 182.319 | K15: 190.2229 | L15: Intermediate consumption of agriculture paid for public services | R15: di_ps_a | S15: 104.001 | T15: 111.6997 | U15: 117.2605 | V15: 121.7626 | W15: 125.3332 | X15: 129.5568 | Y15: 131.5865 | Z15: 134.626 | AA15: 140.4592 | AB15: Intermediate consumption of agriculture paid for public services
B16: di_ms_a | C16: 250.3777 | D16: 268.7507 | E16: 282.2696 | F16: 293.1066 | G16: 301.5847 | H16: 311.7173 | I16: 316.5581 | J16: 323.8863 | K16: 337.9274 | L16: Intermediate consumption of agriculture paid market services | R16: di_ms_a | S16: 184.7559 | T16: 198.4324 | U16: 208.3111 | V16: 216.3089 | W16: 222.652 | X16: 230.1552 | Y16: 233.7609 | Z16: 239.1606 | AA16: 249.5231 | AB16: Intermediate consumption of agriculture paid market services
B17: ci_a | C17: 40340.11 | D17: 43300.3 | E17: 45478.42 | F17: 47224.45 | G17: 48590.42 | H17: 50222.95 | I17: 51002.89 | J17: 52183.59 | K17: 54445.85 | L17: Total intermediate consumption in agricultural sector | N17: =C17/'2_Production_2'!AX21*100 -> 51.725265 | R17: ci_a | S17: 29767.31 | T17: 31970.83 | U17: 33562.46 | V17: 34851.04 | W17: 35873.03 | X17: 37081.92 | Y17: 37662.85 | Z17: 38532.84 | AA17: 40202.41 | AB17: Total intermediate consumption in agricultural sector | AD17: =S17/'2_Production_2'!AX21*100 -> 38.168513 | AE17: 51.66246
L18: = expenses of agriculture on the intermediate consumption | AB18: = expenses of agriculture on the intermediate consumption
B19: ci_a_im | C19: 5552.509 | D19: 5959.957 | E19: 6259.759 | F19: 6500.087 | G19: 6688.102 | H19: 6912.808 | I19: 7020.161 | J19: 7182.675 | K19: 7494.058 | L19: of which the intermediate consumption of imported goods | R19: ci_a_im | S19: 4097.244 | T19: 4400.541 | U19: 4619.618 | V19: 4796.981 | W19: 4937.649 | X19: 5104.044 | Y19: 5184.005 | Z19: 5303.753 | AA19: 5533.556 | AB19: of which the intermediate consumption of imported goods
B20: Source: di_mi_grp | R20: Source: di_mi_grp
B21: Mining | C21: 2024 | D21: =C21+1 -> 2025 | E21: =D21+1 -> 2026 | F21: =E21+1 -> 2027 | G21: =F21+1 -> 2028 | H21: =G21+1 -> 2029 | I21: =H21+1 -> 2030 | J21: =I21+1 -> 2031 | K21: =J21+1 -> 2032 | L21: Description | R21: Mining | S21: 2024 | T21: =S21+1 -> 2025 | U21: =T21+1 -> 2026 | V21: =U21+1 -> 2027 | W21: =V21+1 -> 2028 | X21: =W21+1 -> 2029 | Y21: =X21+1 -> 2030 | Z21: =Y21+1 -> 2031 | AA21: =Z21+1 -> 2032 | AB21: Description
B22: di_a_mi | C22: 0 | D22: 0 | E22: 0 | F22: 0 | G22: 0 | H22: 0 | I22: 0 | J22: 0 | K22: 0 | L22: Intermediate consumption of mining paid for agr. commodities | R22: di_a_mi | S22: 0 | T22: 0 | U22: 0 | V22: 0 | W22: 0 | X22: 0 | Y22: 0 | Z22: 0 | AA22: 0 | AB22: Intermediate consumption of mining paid for agr. commodities
B23: di_mi_mi | C23: 1160.229 | D23: 1444.166 | E23: 1537.133 | F23: 1630.58 | G23: 1692.322 | H23: 1757.118 | I23: 1831.811 | J23: 1926.386 | K23: 2015.434 | L23: Intermediate consumption of mining paid for mining commodities | R23: di_mi_mi | S23: 533.6855 | T23: 664.2057 | U23: 707.0685 | V23: 749.2703 | W23: 779.4724 | X23: 809.5709 | Y23: 844.9853 | Z23: 889.1173 | AA23: 930.2194 | AB23: Intermediate consumption of mining paid for mining commodities
B24: di_m_mi | C24: 4107.026 | D24: 5112.116 | E24: 5441.204 | F24: 5771.992 | G24: 5990.549 | H24: 6219.918 | I24: 6484.318 | J24: 6819.1 | K24: 7134.316 | L24: Intermediate consumption of mining paid for manufact, commodities | R24: di_m_mi | S24: 1889.162 | T24: 2351.182 | U24: 2502.91 | V24: 2652.297 | W24: 2759.208 | X24: 2865.752 | Y24: 2991.113 | Z24: 3147.333 | AA24: 3292.828 | AB24: Intermediate consumption of mining paid for manufact, commodities
B25: di_e_mi | C25: 249.9291 | D25: 311.0928 | E25: 331.1191 | F25: 351.2489 | G25: 364.549 | H25: 378.507 | I25: 394.5968 | J25: 414.9697 | K25: 434.1518 | L25: Intermediate consumption of mining paid for energy commodities | R25: di_e_mi | S25: 114.9631 | T25: 143.0789 | U25: 152.3121 | V25: 161.403 | W25: 167.9089 | X25: 174.3925 | Y25: 182.0213 | Z25: 191.5279 | AA25: 200.3818 | AB25: Intermediate consumption of mining paid for energy commodities
B26: di_c_mi | C26: 315.201 | D26: 392.3385 | E26: 417.5949 | F26: 442.9818 | G26: 459.7554 | H26: 477.3587 | I26: 497.6505 | J26: 523.344 | K26: 547.5358 | L26: Intermediate consumption of mining paid for construct, commodities | R26: di_c_mi | S26: 144.9871 | T26: 180.4457 | U26: 192.0903 | V26: 203.5553 | W26: 211.7603 | X26: 219.9372 | Y26: 229.5583 | Z26: 241.5477 | AA26: 252.714 | AB26: Intermediate consumption of mining paid for construct, commodities
B27: di_t_mi | C27: 166.0148 | D27: 206.6427 | E27: 219.9451 | F27: 233.3163 | G27: 242.1508 | H27: 251.4224 | I27: 262.11 | J27: 275.6426 | K27: 288.3843 | L27: Intermediate consumption of mining paid for trans, Services | R27: di_t_mi | S27: 76.36395 | T27: 95.03981 | U27: 101.173 | V27: 107.2115 | W27: 111.5331 | X27: 115.8398 | Y27: 120.9072 | Z27: 127.2219 | AA27: 133.1032 | AB27: Intermediate consumption of mining paid for trans, Services
B28: di_tr_mi | C28: 64.15786 | D28: 79.85887 | E28: 84.99971 | F28: 90.16711 | G28: 93.58129 | H28: 97.16438 | I28: 101.2947 | J28: 106.5245 | K28: 111.4486 | L28: Intermediate consumption of mining paid for trade services | R28: di_tr_mi | S28: 29.51152 | T28: 36.72897 | U28: 39.09917 | V28: 41.43283 | W28: 43.10294 | X28: 44.76731 | Y28: 46.72564 | Z28: 49.16603 | AA28: 51.43888 | AB28: Intermediate consumption of mining paid for trade services
B29: di_fs_mi | C29: 226.265 | D29: 281.6376 | E29: 299.7678 | F29: 317.9916 | G29: 330.0324 | H29: 342.6689 | I29: 357.2352 | J29: 375.6791 | K29: 393.045 | L29: Intermediate consumption of mining paid for fin, services | R29: di_fs_mi | S29: 104.078 | T29: 129.5318 | U29: 137.8907 | V29: 146.1208 | W29: 152.0108 | X29: 157.8805 | Y29: 164.7869 | Z29: 173.3934 | AA29: 181.4091 | AB29: Intermediate consumption of mining paid for fin, services
B30: di_ps_mi | C30: 9.354959 | D30: 11.64435 | E30: 12.39394 | F30: 13.14741 | G30: 13.64524 | H30: 14.16769 | I30: 14.76994 | J30: 15.53251 | K30: 16.2505 | L30: Intermediate consumption of mining paid for public services | R30: di_ps_mi | S30: 4.303121 | T30: 5.355508 | U30: 5.701112 | V30: 6.041387 | W30: 6.284907 | X30: 6.527592 | Y30: 6.813139 | Z30: 7.168976 | AA30: 7.500384 | AB30: Intermediate consumption of mining paid for public services
B31: di_ms_mi | C31: 10.54939 | D31: 13.13109 | E31: 13.97639 | F31: 14.82606 | G31: 15.38745 | H31: 15.97661 | I31: 16.65575 | J31: 17.51568 | K31: 18.32535 | L31: Intermediate consumption of mining paid for market services | R31: di_ms_mi | S31: 4.852539 | T31: 6.039294 | U31: 6.429024 | V31: 6.812745 | W31: 7.087357 | X31: 7.361028 | Y31: 7.683034 | Z31: 8.084304 | AA31: 8.458025 | AB31: Intermediate consumption of mining paid for market services
B32: ci_mi | C32: 6308.727 | D32: 7852.628 | E32: 8358.133 | F32: 8866.251 | G32: 9201.972 | H32: 9554.302 | I32: 9960.441 | J32: 10474.69 | K32: 10958.89 | L32: Total intermediate consumption in mining sector | N32: =C32/'2_Production_2'!AX23*100 -> 49.81371 | R32: ci_mi | S32: 2901.906 | T32: 3611.608 | U32: 3844.673 | V32: 4074.145 | W32: 4238.368 | X32: 4402.028 | Y32: 4594.594 | Z32: 4834.561 | AA32: 5058.053 | AB32: Total intermediate consumption in mining sector | AD32: =S32/'2_Production_2'!AX23*100 -> 22.91345 | AE32: 49.102771
L33: = expenses of mining on the intermediate consumption | AB33: = expenses of mining on the intermediate consumption
B34: ci_mi_im | C34: 2019.652 | D34: 2513.91 | E34: 2675.741 | F34: 2838.408 | G34: 2945.884 | H34: 3058.678 | I34: 3188.698 | J34: 3353.329 | K34: 3508.338 | L34: of which the intermediate consumption of imported goods | R34: ci_mi_im | S34: 929.0052 | T34: 1156.206 | U34: 1230.819 | V34: 1304.281 | W34: 1356.855 | X34: 1409.249 | Y34: 1470.896 | Z34: 1547.718 | AA34: 1619.266 | AB34: of which the intermediate consumption of imported goods
B35: Source: di_m_grp | R35: Source: di_m_grp
B36: Manufacturing | C36: 2024 | D36: =C36+1 -> 2025 | E36: =D36+1 -> 2026 | F36: =E36+1 -> 2027 | G36: =F36+1 -> 2028 | H36: =G36+1 -> 2029 | I36: =H36+1 -> 2030 | J36: =I36+1 -> 2031 | K36: =J36+1 -> 2032 | L36: Description | R36: Manufacturing | S36: 2024 | T36: =S36+1 -> 2025 | U36: =T36+1 -> 2026 | V36: =U36+1 -> 2027 | W36: =V36+1 -> 2028 | X36: =W36+1 -> 2029 | Y36: =X36+1 -> 2030 | Z36: =Y36+1 -> 2031 | AA36: =Z36+1 -> 2032 | AB36: Description
B37: di_a_m | C37: 8192.94 | D37: 8527.142 | E37: 9245.99 | F37: 10012.2 | G37: 10963.55 | H37: 12205.55 | I37: 12601.31 | J37: 12950.2 | K37: 13207.94 | L37: Intermediate consumption of manufacturing paid for agr, commodities | R37: di_a_m | S37: 6982.956 | T37: 7270.973 | U37: 7886.666 | V37: 8539.849 | W37: 9359.093 | X37: 10423.09 | Y37: 10764.93 | Z37: 11063.37 | AA37: 11284.21 | AB37: Intermediate consumption of manufacturing paid for agr, commodities
B38: di_mi_m | C38: 3804.83 | D38: 3960.035 | E38: 4293.87 | F38: 4649.699 | G38: 5091.512 | H38: 5668.3 | I38: 5852.091 | J38: 6014.118 | K38: 6133.816 | L38: Intermediate consumption of manufacturing paid for mining commodities | R38: di_mi_m | S38: 3242.909 | T38: 3376.665 | U38: 3662.595 | V38: 3965.936 | W38: 4346.396 | X38: 4840.518 | Y38: 4999.271 | Z38: 5137.866 | AA38: 5240.425 | AB38: Intermediate consumption of manufacturing paid for mining commodities
B39: di_m_m | C39: 17755.54 | D39: 18479.81 | E39: 20037.68 | F39: 21698.18 | G39: 23759.94 | H39: 26451.56 | I39: 27309.24 | J39: 28065.35 | K39: 28623.93 | L39: Intermediate consumption of manufacturing paid for manufact, commodities | R39: di_m_m | S39: 15133.29 | T39: 15757.47 | U39: 17091.79 | V39: 18507.35 | W39: 20282.79 | X39: 22588.66 | Y39: 23329.49 | Z39: 23976.25 | AA39: 24454.85 | AB39: Intermediate consumption of manufacturing paid for manufact, commodities
