Workbook

Sheet S-1 реалистичный сценарий
A1: Сенарияи 2. Воќеї-Баҳодиҳии пешакии нишондиҳандаҳои асосии макроиќтисодии Љумҳурии Тољикистон барои соли 2025 ва дурнамои он барои солҳои 2026-2028
A2: Нишондињандањо | B2: Воњиди ченак | C2: Соли 2022 | E2: Соли 2023 | G2: Соли 2024 | I2: Соли 2025 | K2: Соли 2026 | M2: Соли 2027 | O2: Соли 2028 | Q2: Соли 2029 | S2: Соли 2030 | U2: Соли 2031 | W2: Соли 2032 | Y2: Соли 2033 | AA2: Соли 2034 | AC2: Соли 2035 | AE2: 2024
C3: Воќеї | D3: нисбат ба соли 2021 (бо фоиз) | E3: Воќеї | F3: нисбат ба соли 2022 (бо фоиз) | G3: Воќеї | H3: нисбат ба соли 2023 (бо фоиз) | I3: Бањодињї | J3: нисбат ба соли 2024 (бо фоиз) | K3: Дурнамо | L3: нисбат ба соли 2025 (бо фоиз) | M3: Дурнамо | N3: нисбат ба соли 2026 (бо фоиз) | O3: Дурнамо | P3: нисбат ба соли 2027 (бо фоиз) | Q3: Дурнамо | R3: нисбат ба соли 2027 (бо фоиз) | S3: Дурнамо | T3: нисбат ба соли 2027 (бо фоиз) | U3: Дурнамо | V3: нисбат ба соли 2027 (бо фоиз) | W3: Дурнамо | X3: нисбат ба соли 2027 (бо фоиз) | Y3: Дурнамо | Z3: нисбат ба соли 2027 (бо фоиз) | AA3: Дурнамо | AB3: нисбат ба соли 2027 (бо фоиз) | AC3: Дурнамо | AD3: нисбат ба соли 2027 (бо фоиз) | AF3: Соли 2023 | AH3: Соли 2024 | AJ3: Соли 2025 | AL3: Соли 2026 | AN3: Соли 2027 | AP3: Соли 2028
A4: Шумораи ањолї (ба њисоби миёнаи солона) | B4: Њазор нафар | C4: 9982.6 | D4: 101.8 | E4: 10183.3 | F4: =+E4/C4*100 -> 102.0105 | G4: 10398.4 | H4: =+G4/E4*100 -> 102.11228 | I4: 10614.691 | J4: =+I4/G4*100 -> 102.08004 | K4: =+I4*L4/100 -> 10837.6 | L4: 102.1 | M4: =+K4*N4/100 -> 11076.027 | N4: 102.2 | O4: =+M4*N4/100 -> 11319.699 | P4: 102.2 | Q4: =+O4*P4/100 -> 11568.733 | R4: 102.2 | S4: =+Q4*R4/100 -> 11823.245 | T4: 102.2 | U4: =+S4*T4/100 -> 12083.356 | V4: 102.2 | W4: =+U4*V4/100 -> 12349.19 | X4: 102.3 | Y4: =+W4*X4/100 -> 12633.221 | Z4: 102.4 | AA4: =+Y4*Z4/100 -> 12936.419 | AB4: 102.3 | AC4: =+AA4*AB4/100 -> 13233.956 | AD4: 102.3 | AE4: 10382.1 | AF4: =C4*D4/100 -> 10162.287 | AG4: =E4/C4*100 -> 102.0105 | AH4: =E4*F4/100 -> 10388.035 | AI4: =G4/E4*100 -> 102.11228 | AJ4: =G4*H4/100 -> 10618.044 | AK4: =I4/G4*100 -> 102.08004 | AL4: =I4*J4/100 -> 10835.481 | AM4: =K4/I4*100 -> 102.1 | AN4: =K4*L4/100 -> 11065.189 | AO4: =M4/K4*100 -> 102.2 | AP4: =M4*N4/100 -> 11319.699 | AQ4: =O4/M4*100 -> 102.2
A5: Маљмўи мањсулоти дохилї | B5: млн. сомонї | C5: =+GDP!AC2 -> 118181.7 | D5: =+GDP!AC3 -> 108.03592 | E5: =+GDP!AD2 -> 132781.9 | F5: =+GDP!AD3 -> 108.31977 | G5: =+GDP!AE2 -> 155783.9 | H5: =+GDP!AE3 -> 108.42918 | I5: =+GDP!AF2 -> 176919 | J5: =+GDP!AF3 -> 108.43563 | K5: =+GDP!AG2 -> 199898.14 | L5: =+GDP!AG3 -> 108.49433 | M5: =+GDP!AH2 -> 225457.21 | N5: =+GDP!AH3 -> 108.43204 | O5: =+GDP!AI2 -> 254610.41 | P5: =+GDP!AI3 -> 108.58847 | Q5: =GDP!AJ2 -> 290955.28 | R5: =GDP!AJ3 -> 108.78201 | S5: =GDP!AK2 -> 325987.6 | T5: =GDP!AK3 -> 108.04844 | U5: =GDP!AL2 -> 368330.8 | V5: =+GDP!AL3 -> 108.54826 | W5: =GDP!AM2 -> 413970.29 | X5: =+GDP!AM3 -> 108.06837 | Y5: =GDP!AN2 -> 460417.18 | Z5: =+GDP!AN3 -> 108.10105 | AA5: =GDP!AO2 -> 511101.74 | AB5: =+GDP!AO3 -> 108.24891 | AC5: =GDP!AP2 -> 568732.06 | AD5: =+GDP!AP3 -> 108.60848 | AE5: 153402.2
A6: Индекс-дефлятори ММД | B6: бо фоиз | D6: =+GDP!AC4 -> 108.22628 | F6: =+GDP!AD4 -> 103.7244 | H6: =+GDP!AE4 -> 108.20255 | J6: =+GDP!AF4 -> 106.43212 | L6: =+GDP!AG4 -> 104.14231 | N6: =+GDP!AH4 -> 104.11542 | P6: =+GDP!AI4 -> 103.9988 | R6: =GDP!AJ4 -> 105.14926 | T6: =GDP!AK4 -> 103.99465 | V6: =+GDP!AL4 -> 104.09122 | X6: =+GDP!AM4 -> 103.9998 | Z6: =+GDP!AN4 -> 102.88509 | AB6: =+GDP!AO4 -> 102.54921 | AD6: =+GDP!AP4 -> 102.45581
A7: Таваррум | B7: бо фоиз | D7: =+Monetary!AC15 -> 104.2 | F7: =+Monetary!AD15 -> 103.8 | H7: =Monetary!AE15 -> 103.6 | J7: =Monetary!AF15 -> 103.5 | L7: =Monetary!AG3 -> 103.93407 | N7: =Monetary!AH3 -> 104.03272 | P7: =Monetary!AI3 -> 103.79573 | R7: =Monetary!AJ3 -> 103.90476 | T7: =Monetary!AK3 -> 104.06104 | V7: =Monetary!AL3 -> 104.427 | X7: =Monetary!AM3 -> 104.43909 | Z7: =Monetary!AN3 -> 104.16684 | AB7: =Monetary!AO3 -> 103.79413 | AD7: =Monetary!AP3 -> 104.06565
A8: ММД ба њар нафар ањолї | B8: сомонї | C8: =+C5/C4*1000 -> 11838.769 | D8: =+C8/10312*100 -> 114.80576 | E8: =+E5/E4*1000 -> 13039.182 | F8: =+E8/C8*100 -> 110.13967 | G8: =+G5/G4*1000 -> 14981.526 | H8: =+G8/E8*100 -> 114.89621 | I8: =+I5/I4*1000 -> 16667.372 | J8: =+I8/G8*100 -> 111.25283 | K8: =+K5/K4*1000 -> 18444.872 | L8: =+K8/I8*100 -> 110.66455 | M8: =+M5/M4*1000 -> 20355.423 | N8: =+M8/K8*100 -> 110.35817 | O8: =+O5/O4*1000 -> 22492.683 | P8: =+O8/M8*100 -> 110.49971 | Q8: =+Q5/Q4*1000 -> 25150.142 | R8: =+Q8/O8*100 -> 111.81477 | S8: =+S5/S4*1000 -> 27571.754 | T8: =+S8/Q8*100 -> 109.62862 | U8: =+U5/U4*1000 -> 30482.492 | V8: =+U8/S8*100 -> 110.55695 | W8: =+W5/W4*1000 -> 33522.06 | X8: =+W8/U8*100 -> 109.97152 | Y8: =+Y5/Y4*1000 -> 36444.955 | Z8: =+Y8/W8*100 -> 108.71932 | AA8: =+AA5/AA4*1000 -> 39508.75 | AB8: =+AA8/Y8*100 -> 108.40664 | AC8: =+AC5/AC4*1000 -> 42975.21 | AD8: =+AC8/AA8*100 -> 108.7739 | AE8: =+AE5/AE4*1000 -> 14775.643
A9: Њаљми мањсулоти саноатї | B9: млн. сомонї | C9: =Industry!AC4 -> 42221.4 | D9: =Industry!AC18 -> 115.4 | E9: =Industry!AD4 -> 46816 | F9: =Industry!AD18 -> 112 | G9: =Industry!AE4 -> 53819 | H9: =Industry!AE18 -> 120 | I9: =+Industry!AF4 -> 66726.1 | J9: =+Industry!AF18 -> 122.1 | K9: =+Industry!AG4 -> 83491.032 | L9: =+Industry!AG18 -> 125.02097 | M9: =+Industry!AH4 -> 104885.65 | N9: =+Industry!AH18 -> 125.0001 | O9: =+Industry!AI4 -> 131605.53 | P9: =+Industry!AI18 -> 125.10772 | Q9: =Industry!AJ4 -> 164803.16 | R9: =Industry!AJ18 -> 125.0738 | S9: =Industry!AK4 -> 167867.77 | T9: =Industry!AK18 -> 119.95581 | U9: =+Industry!AL4 -> 171881.25 | V9: =+Industry!AL18 -> 119.92603 | W9: =+Industry!AM4 -> 172762.85 | X9: =+Industry!AM18 -> 120.07027 | Y9: =+Industry!AN4 -> 196491.13 | Z9: =+Industry!AN18 -> 111.30175 | AA9: =+Industry!AO4 -> 216673.07 | AB9: =+Industry!AO18 -> 109.17267 | AC9: =+Industry!AP4 -> 241220.44 | AD9: =+Industry!AP18 -> 122.3396
A10: -саноати истихроҷи маъдан | B10: млн. сомонї | C10: =Industry!AC5 -> 8890.9 | D10: =Industry!AC19 -> 97.7 | E10: =Industry!AD5 -> 9373 | F10: =Industry!AD19 -> 111.7 | G10: =Industry!AE5 -> 13363.1 | H10: =Industry!AE19 -> 143 | I10: =Industry!AF5 -> 20000.2 | J10: =+Industry!AF19 -> 136.2 | K10: =Industry!AG5 -> 26754.532 | L10: =+Industry!AG19 -> 121.23928 | M10: =Industry!AH5 -> 29788.981 | N10: =+Industry!AH19 -> 127.31865 | O10: =Industry!AI5 -> 40744.262 | P10: =+Industry!AI19 -> 157.14609 | Q10: =Industry!AJ5 -> 48047.335 | R10: =Industry!AJ19 -> 118.05099 | S10: =Industry!AK5 -> 51160.518 | T10: =Industry!AK19 -> 77.11757 | U10: =Industry!AL5 -> 37883.054 | V10: =+Industry!AL19 -> 72.072546 | W10: =Industry!AM5 -> 26182.762 | X10: =+Industry!AM19 -> 67.986265 | Y10: =Industry!AN5 -> 30415.987 | Z10: =+Industry!AN19 -> 117.51327 | AA10: =Industry!AO5 -> 36342.377 | AB10: =+Industry!AO19 -> 119.45571 | AC10: =Industry!AP5 -> 43559.306 | AD10: =+Industry!AP19 -> 119.8637
A11: -саноати коркард | B11: млн. сомонї | C11: =Industry!AC8 -> 25708.7 | D11: =Industry!AC22 -> 116.4 | E11: =Industry!AD8 -> 28459.8 | F11: =Industry!AD22 -> 112.4 | G11: =Industry!AE8 -> 30275.6 | H11: =Industry!AE22 -> 107.6 | I11: =Industry!AF8 -> 34595.4 | J11: =+Industry!AF22 -> 110.5 | K11: =Industry!AG8 -> 43621.32 | L11: =+Industry!AG22 -> 132.91232 | M11: =Industry!AH8 -> 60339.771 | N11: =+Industry!AH22 -> 127.14443 | O11: =Industry!AI8 -> 73035.004 | P11: =+Industry!AI22 -> 110.19673 | Q11: =Industry!AJ8 -> 95177.148 | R11: =Industry!AJ22 -> 129.91494 | S11: =Industry!AK8 -> 93137.6 | T11: =Industry!AK22 -> 143.95848 | U11: =Industry!AL8 -> 108597.04 | V11: =+Industry!AL22 -> 149.21789 | W11: =Industry!AM8 -> 119233.48 | X11: =+Industry!AM22 -> 141.07614 | Y11: =Industry!AN8 -> 136686.93 | Z11: =+Industry!AN22 -> 110.7975 | AA11: =Industry!AO8 -> 148738.68 | AB11: =+Industry!AO22 -> 107.23612 | AC11: =Industry!AP8 -> 163710.02 | AD11: =+Industry!AP22 -> 126.03137
A12: -таъминоти нерўи барќ, газ, буѓ ва тозакунии њаво | B12: млн. сомонї | C12: =Industry!AC15 -> 7621.8 | D12: =Industry!AC29 -> 117.5 | E12: =Industry!AD15 -> 8983.2 | F12: =Industry!AD29 -> 107.1 | G12: =Industry!AE15+Industry!AE17 -> 10180.3 | H12: =Industry!AE29 -> 105.7 | I12: =Industry!AF15+Industry!AF17 -> 12130.5 | J12: =+Industry!AF29 -> 113 | K12: =Industry!AG15+Industry!AG17 -> 13115.18 | L12: =+Industry!AG29+2 -> 110.22722 | M12: =Industry!AH15+Industry!AH17 -> 14756.897 | N12: =+Industry!AH29 -> 112.76929 | O12: =Industry!AI15+Industry!AI17 -> 17826.267 | P12: =+Industry!AI29 -> 121.29669 | Q12: =Industry!AJ15+Industry!AJ17 -> 21578.678 | R12: =Industry!AJ29 -> 121.19792 | S12: =Industry!AK15+Industry!AK17 -> 23569.656 | T12: =Industry!AK29 -> 109.2266 | U12: =Industry!AL15+Industry!AL17 -> 25401.162 | V12: =+Industry!AL29 -> 107.77061 | W12: =Industry!AM15+Industry!AM17 -> 27346.612 | X12: =+Industry!AM29 -> 107.6589 | Y12: =Industry!AN15+Industry!AN17 -> 29388.222 | Z12: =+Industry!AN29 -> 107.46567 | AA12: =Industry!AO15+Industry!AO17 -> 31592.015 | AB12: =+Industry!AO29 -> 107.4989 | AC12: =Industry!AP15+Industry!AP17 -> 33951.116 | AD12: =+Industry!AP29 -> 107.46739
A13: Њаљми мањсулоти кишоварзї | B13: млн. сомонї | C13: =Agriculture!AC2 -> 61337.9 | D13: =Agriculture!AC3 -> 108 | E13: =+Agriculture!AD2 -> 66907.2 | F13: =+Agriculture!AD3 -> 109 | G13: =+Agriculture!AE2 -> 73976.6 | H13: =+Agriculture!AE3 -> 110.6 | I13: =+Agriculture!AF2 -> 84653.8 | J13: =+Agriculture!AF3 -> 109.5 | K13: =+Agriculture!AG2 -> 95155.365 | L13: =+Agriculture!AG3 -> 108.91987 | M13: =+Agriculture!AH2 -> 104591.34 | N13: =+Agriculture!AH3 -> 108.61303 | O13: =Agriculture!AI2 -> 114715.98 | P13: =+Agriculture!AI3 -> 108.27265 | Q13: =Agriculture!AJ2 -> 125434.67 | R13: =Agriculture!AJ3 -> 108.15398 | S13: =Agriculture!AK2 -> 136949.66 | T13: =+Agriculture!AK3 -> 108.31356 | U13: =Agriculture!AL2 -> 148095.75 | V13: =+Agriculture!AL3 -> 107.60081 | W13: =Agriculture!AM2 -> 159589.23 | X13: =+Agriculture!AM3 -> 107.54575 | Y13: =Agriculture!AN2 -> 172013.18 | Z13: =+Agriculture!AN3 -> 107.24871 | AA13: =Agriculture!AO2 -> 184982.77 | AB13: =+Agriculture!AO3 -> 107.00486 | AC13: =Agriculture!AP2 -> 199395.93 | AD13: =+Agriculture!AP3 -> 107.25535
A14: -растанипарварӣ | B14: млн. сомонї | C14: =Agriculture!AC5 -> 42115 | D14: =Agriculture!AC6 -> 107.7 | E14: =+Agriculture!AD5 -> 44976.1 | F14: =+Agriculture!AD6 -> 106.8 | G14: =+Agriculture!AE5 -> 50984.9 | H14: =+Agriculture!AE6 -> 113.4 | I14: =+Agriculture!AF5 -> 56588 | J14: =+Agriculture!AF6 -> 109.9 | K14: =+Agriculture!AG5 -> 61242.178 | L14: =+Agriculture!AG6 -> 107.25934 | M14: =+Agriculture!AH5 -> 66836.044 | N14: =+Agriculture!AH6 -> 106.99413 | O14: =Agriculture!AI5 -> 72556.838 | P14: =+Agriculture!AI6 -> 108.34276 | Q14: =Agriculture!AJ5 -> 78788.347 | R14: =Agriculture!AJ6 -> 107.51332 | S14: =Agriculture!AK5 -> 85058.32 | T14: =+Agriculture!AK6 -> 107.42089 | U14: =Agriculture!AL5 -> 90393.172 | V14: =+Agriculture!AL6 -> 105.74328 | W14: =Agriculture!AM5 -> 95752.602 | X14: =+Agriculture!AM6 -> 105.61219 | Y14: =Agriculture!AN5 -> 100785.75 | Z14: =+Agriculture!AN6 -> 104.94159 | AA14: =Agriculture!AO5 -> 105499.67 | AB14: =+Agriculture!AO6 -> 104.46823 | AC14: =Agriculture!AP5 -> 109860.02 | AD14: =+Agriculture!AP6 -> 101.29673
A15: -чорводорӣ | B15: млн. сомонї | C15: =Agriculture!AC8 -> 19222.9 | D15: =Agriculture!AC9 -> 108.7 | E15: =+Agriculture!AD8 -> 21931.1 | F15: =+Agriculture!AD9 -> 114.1 | G15: =+Agriculture!AE8 -> 22991.7 | H15: =+Agriculture!AE9 -> 104.8 | I15: =+Agriculture!AF8 -> 28065.8 | J15: =+Agriculture!AF9 -> 108.5 | K15: =+Agriculture!AG8 -> 33724.207 | L15: =+Agriculture!AG9 -> 107.4085 | M15: =+Agriculture!AH8 -> 37549.307 | N15: =+Agriculture!AH9 -> 106.622 | O15: =Agriculture!AI8 -> 41934.825 | P15: =+Agriculture!AI9 -> 104.4435 | Q15: =Agriculture!AJ8 -> 46401.587 | R15: =Agriculture!AJ9 -> 103.5132 | S15: =Agriculture!AK8 -> 51624.557 | T15: =+Agriculture!AK9 -> 105.0056 | U15: =Agriculture!AL8 -> 57411.246 | V15: =+Agriculture!AL9 -> 105.4467 | W15: =Agriculture!AM8 -> 63518.787 | X15: =+Agriculture!AM9 -> 105.897 | Y15: =Agriculture!AN8 -> 70880.981 | Z15: =+Agriculture!AN9 -> 107 | AA15: =Agriculture!AO8 -> 79106.511 | AB15: =+Agriculture!AO9 -> 107 | AC15: =Agriculture!AP8 -> 89127.317 | AD15: =+Agriculture!AP9 -> 108
A16: Маблаѓгузорї ба сармояи асосї аз њисоби њамаи манбаъњои маблаѓгузорї | B16: млн. сомонї | C16: 16279.5 | D16: 111.4 | E16: =+OEA!AD22 -> 19859 | F16: =+E16/C16*100 -> 121.98778 | G16: =OEA!AE22 -> 22543 | H16: 108.4 | I16: =OEA!AF22 -> 28736 | J16: 123 | K16: =OEA!AG22 -> 32767.972 | L16: =+K16/I16*100 -> 114.03108 | M16: =+OEA!AH22 -> 38923.922 | N16: =+M16/K16*100 -> 118.78648 | O16: =+OEA!AI22 -> 44524.431 | P16: =+O16/M16*100 -> 114.38835 | Q16: =OEA!AJ22 -> 51375.484 | R16: =+Q16/O16*100 -> 115.38718 | S16: =+OEA!AK22 -> 55564.062 | T16: =+S16/Q16*100 -> 108.15287 | U16: =+OEA!AL22 -> 63254.949 | V16: =+U16/S16*100 -> 113.84148 | W16: =+OEA!AM22 -> 73256.893 | X16: =+W16/U16*100 -> 115.81211 | Y16: =+OEA!AN22 -> 91342.986 | Z16: =+Y16/W16*100 -> 124.68859 | AA16: =+OEA!AO22 -> 114213.1 | AB16: =+AA16/W16*100 -> 155.90765 | AC16: =+OEA!AP22 -> 143190.44 | AD16: =+AC16/Y16*100 -> 156.76129
A17: аз чумла аз њисоби буљети давлатї | B17: млн. сомонї | C17: 6736.9 | D17: 110.3 | E17: =+OEA!AD23 -> 7922.5 | F17: =+E17/C17*100 -> 117.5986 | G17: =OEA!AE23 -> 9830.5 | H17: 118.5 | I17: =OEA!AF23 -> 13280.5 | J17: 130.4 | K17: =OEA!AG23 -> 14210.135 | L17: =+K17/I17*100 -> 107 | M17: =+OEA!AH23 -> 15631.149 | N17: =+M17/K17*100 -> 110 | O17: =+OEA!AI23 -> 16881.64 | P17: =+O17/M17*100 -> 108 | Q17: =OEA!AJ23 -> 18063.355 | R17: =+Q17/O17*100 -> 107 | S17: =+OEA!AK23 -> 18785.889 | T17: =+S17/Q17*100 -> 104 | U17: =+OEA!AL23 -> 19725.184 | V17: =+U17/S17*100 -> 105 | W17: =+OEA!AM23 -> 21697.702 | X17: =+W17/U17*100 -> 110 | Y17: =+OEA!AN23 -> 26037.243 | Z17: =+Y17/W17*100 -> 120 | AA17: =+OEA!AO23 -> 31244.691 | AB17: =+AA17/Y17*100 -> 120 | AC17: =+OEA!AP23 -> 37493.63 | AD17: =+AC17/AA17*100 -> 120
A18: Сармоягузории хориљї (қарз, грант, мустақим) | B18: млн. доллар | C18: 2577 | E18: 2690 | F18: =+E18/C18*100 -> 104.38494 | G18: =OEA!AE34 -> 5126.6 | H18: =+G18/E18*100 -> 190.57993 | I18: =OEA!AF34 -> 6925.3 | J18: =+I18/G18*100 -> 135.08563 | K18: =OEA!AG34 -> 7624.7553 | L18: =+K18/I18*100 -> 110.1 | M18: =OEA!AH34 -> 8562.6002 | N18: =+M18/K18*100 -> 112.3 | O18: =OEA!AI34 -> 9598.6748 | P18: =+O18/M18*100 -> 112.1 | Q18: =OEA!AJ34 -> 10769.713 | R18: =+Q18/O18*100 -> 112.2 | S18: =OEA!AK34 -> 12094.388 | T18: =+S18/Q18*100 -> 112.3 | U18: =OEA!AL34 -> 13545.714 | V18: =+U18/S18*100 -> 112 | W18: =OEA!AM34 -> 15184.746 | X18: =+W18/U18*100 -> 112.1 | Y18: =OEA!AN34 -> 17037.285 | Z18: =+Y18/W18*100 -> 112.2 | AA18: =OEA!AO34 -> 19132.871 | AB18: =+AA18/Y18*100 -> 112.3 | AC18: =OEA!AP34 -> 21428.815 | AD18: =+AC18/AA18*100 -> 112
A19: Њаљми умумии гардиши савдо дар њама соњањо | B19: млн. сомонї | C19: 47563.4 | D19: 111.2 | E19: =+Household!AD3 -> 56124.4 | F19: =+Household!AD4 -> 113.4 | G19: =+Household!AE3 -> 65783.8 | H19: =+Household!AE4 -> 113.6 | I19: =+Household!AF3 -> 77307.1 | J19: =+Household!AF4 -> 113.9 | K19: =+Household!AG3 -> 89946.541 | L19: =+Household!AG4 -> 114.32794 | M19: =+Household!AH3 -> 105319.77 | N19: =+Household!AH4 -> 114.46523 | O19: =+Household!AI3 -> 120054.47 | P19: =+Household!AI4 -> 113.63166 | Q19: =Household!AJ3 -> 138358.42 | R19: =+Household!AJ4 -> 113.89224 | S19: =+Household!AK3 -> 149157.72 | T19: =+Household!AK4 -> 108.36872 | U19: =+Household!AL3 -> 160879.07 | V19: =+Household!AL4 -> 109.84897 | W19: =+Household!AM3 -> 174656.34 | X19: =+Household!AM4 -> 109.32916 | Y19: =+Household!AN3 -> 194923.92 | Z19: =+Household!AN4 -> 109.35302 | AA19: =+Household!AO3 -> 210618.08 | AB19: =+Household!AO4 -> 106.10895 | AC19: =+Household!AP3 -> 228337.25 | AD19: =+Household!AP4 -> 106.39789 | AN19: =K18*L18/100 -> 8394.8556 | AO19: =M18/K18*100 -> 112.3
A20: аз он: гардиши савдои чакана | B20: млн. сомонї | C20: 39586.2 | D20: 110.2 | E20: =+Household!AD9 -> 47540.5 | F20: =+Household!AD11 -> 115.4 | G20: =+Household!AE9 -> 55663 | H20: =+Household!AE11 -> 113.5 | I20: =+Household!AF9 -> 65705.6 | J20: =+Household!AF11 -> 114.4 | K20: =+Household!AG9 -> 78696.141 | L20: =+Household!AG11 -> 113.99326 | M20: =+Household!AH9 -> 91582.412 | N20: =+Household!AH11 -> 114.2111 | O20: =+Household!AI9 -> 104395.19 | P20: =+Household!AI11 -> 113.29285 | Q20: =Household!AJ9 -> 119274.5 | R20: =+Household!AJ11 -> 113.4711 | S20: =+Household!AK9 -> 129702.36 | T20: =+Household!AK11 -> 108.22317 | U20: =+Household!AL9 -> 139894.85 | V20: =+Household!AL11 -> 107.54877 | W20: =+Household!AM9 -> 151875.08 | X20: =+Household!AM11 -> 107.27654 | Y20: =+Household!AN9 -> 163801.61 | Z20: =+Household!AN11 -> 103.74588 | AA20: =+Household!AO9 -> 176989.99 | AB20: =+Household!AO11 -> 104.16539 | AC20: =+Household!AP9 -> 191880.04 | AD20: =+Household!AP11 -> 104.45022
A21: Њаљми хизматрасонињои пулакї дар њамаи соњањо | B21: млн. сомонї | C21: 18696.8 | D21: 116 | E21: =+Household!AD15 -> 21760.3 | F21: =+Household!AD16 -> 114.1 | G21: =+Household!AE15 -> 25722.9 | H21: =+Household!AE16 -> 113 | I21: =+Household!AF15 -> 30470.2 | J21: =+Household!AF16 -> 113.2 | K21: =+Household!AG15 -> 35439.755 | L21: =+Household!AG16 -> 114.93039 | M21: =+Household!AH15 -> 41254.485 | N21: =+Household!AH16 -> 113.90153 | O21: =+Household!AI15 -> 47612.182 | P21: =+Household!AI16 -> 113.70534 | Q21: =Household!AJ15 -> 51548.635 | R21: =+Household!AJ16 -> 108.15958 | S21: =+Household!AK15 -> 56661.404 | T21: =+Household!AK16 -> 109.69894 | U21: =+Household!AL15 -> 62425.439 | V21: =+Household!AL16 -> 109.62465 | W21: =+Household!AM15 -> 64323.564 | X21: =+Household!AM16 -> 102.52799 | Y21: =+Household!AN15 -> 76394.869 | Z21: =+Household!AN16 -> 118.17566 | AA21: =+Household!AO15 -> 87007.682 | AB21: =+Household!AO16 -> 113.32542 | AC21: =+Household!AP15 -> 83427.507 | AD21: =+Household!AP16 -> 95.408178
A22: аз он: хизматрасонињои пулакї ба ањолї | B22: млн. сомонї | C22: 13866.9 | D22: 110.9 | E22: =+Household!AD18 -> 16740.8 | F22: =+Household!AD20 -> 118.4 | G22: =+Household!AE18 -> 19094.9 | H22: =+Household!AE20 -> 109 | I22: =+Household!AF18 -> 22148.5 | J22: =+Household!AF20 -> 110.9 | K22: =+Household!AG18 -> 25868.434 | L22: =+Household!AG20 -> 111.23374 | M22: =+Household!AH18 -> 29679.485 | N22: =+Household!AH20 -> 111.39072 | O22: =+Household!AI18 -> 33529.706 | P22: =+Household!AI20 -> 111.85412 | Q22: =+Household!AJ18 -> 37085.349 | R22: =+Household!AJ20 -> 110.49396 | S22: =+Household!AK18 -> 40763.6 | T22: =+Household!AK20 -> 108.83004 | U22: =+Household!AL18 -> 43351 | V22: =+Household!AL20 -> 105.81824 | W22: =+Household!AM18 -> 45945.403 | X22: =+Household!AM20 -> 103.90651 | Y22: =+Household!AN18 -> 50929.913 | Z22: =+Household!AN20 -> 108.67526 | AA22: =+Household!AO18 -> 58005.122 | AB22: =+Household!AO20 -> 108.26241 | AC22: =+Household!AP18 -> 64175.005 | AD22: =+Household!AP20 -> 109.54138
A23: Гардиши савдои хориљї | B23: млн. доллар | C23: 7309.5 | D23: 114.9 | E23: =+E24+E25 -> 8733.359 | F23: =+E23/C23*100 -> 119.47957 | G23: =+G24+G25 -> 8955.1 | H23: =+G23/E23*100 -> 102.53901 | I23: =+I24+I25 -> 10793.1 | J23: =+I23/G23*100 -> 120.52462 | K23: =+K24+K25 -> 11021.821 | L23: =+K23/I23*100 -> 102.11914 | M23: =+M24+M25 -> 11200.543 | N23: =+M23/K23*100 -> 101.62153 | O23: =+O24+O25 -> 11336.519 | P23: =+O23/M23*100 -> 101.21401 | Q23: =+Q24+Q25 -> 11664.519 | R23: =+Q23/O23*100 -> 102.8933 | S23: =+S24+S25 -> 11979.383 | T23: =+S23/Q23*100 -> 102.69934 | U23: =+U24+U25 -> 11976.167 | V23: =+U23/S23*100 -> 99.973148 | W23: =+W24+W25 -> 12300.476 | X23: =+W23/U23*100 -> 102.70796 | Y23: =+Y24+Y25 -> 11840.393 | Z23: =+Y23/W23*100 -> 96.25963 | AA23: =+AA24+AA25 -> 11378.757 | AB23: =+AA23/Y23*100 -> 96.101176 | AC23: =+AC24+AC25 -> 13564.672 | AD23: =+AC23/AA23*100 -> 119.2105
A24: аз он: - содирот | C24: 2142 | D24: 99.6 | E24: =Results!L31+Trade!AD4 -> 2104.978 | F24: =+E24/C24*100 -> 98.271615 | G24: =Results!M31 -> 1947.5 | H24: =+G24/E24*100 -> 92.518782 | I24: =Results!N31 -> 2487.9 | J24: =+I24/G24*100 -> 127.7484 | K24: =Results!O31 -> 2672.7851 | L24: =+K24/I24*100 -> 107.43137 | M24: =Results!P31 -> 2840.4586 | N24: =+M24/K24*100 -> 106.27336 | O24: =Results!Q31 -> 2973.4668 | P24: =+O24/M24*100 -> 104.68263 | Q24: =Results!R31 -> 3140.6396 | R24: =+Q24/O24*100 -> 105.62215 | S24: =Results!S31 -> 3298.4753 | T24: =+S24/Q24*100 -> 105.02559 | U24: =Results!T31 -> 3051.7187 | V24: =+U24/S24*100 -> 92.519072 | W24: =Results!U31 -> 3206.4233 | X24: =+W24/U24*100 -> 105.06942 | Y24: =Results!V31 -> 3486.8409 | Z24: =+Y24/W24*100 -> 108.7455 | AA24: =Results!W31 -> 3794.5847 | AB24: =+AA24/Y24*100 -> 108.82586 | AC24: =Results!X31 -> 4161.3641 | AD24: =+AC24/AA24*100 -> 109.66586
A25: -воридот | C25: 5167.5 | D25: 122.8 | E25: =Results!L33+Trade!AD42 -> 6628.381 | F25: =+E25/C25*100 -> 128.27056 | G25: =Results!M33 -> 7007.6 | H25: =+G25/E25*100 -> 105.72114 | I25: =Results!N33 -> 8305.2 | J25: =+I25/G25*100 -> 118.51704 | K25: =Results!O33 -> 8349.036 | L25: =+K25/I25*100 -> 100.52781 | M25: =Results!P33 -> 8360.0848 | N25: =+M25/K25*100 -> 100.13234 | O25: =Results!Q33 -> 8363.0527 | P25: =+O25/M25*100 -> 100.0355 | Q25: =Results!R33 -> 8523.8791 | R25: =+Q25/O25*100 -> 101.92306 | S25: =Results!S33 -> 8680.908 | T25: =+S25/Q25*100 -> 101.84222 | U25: =Results!T33 -> 8924.4479 | V25: =+U25/S25*100 -> 102.80546 | W25: =Results!U33 -> 9094.0526 | X25: =+W25/U25*100 -> 101.90045 | Y25: =Results!V33 -> 8353.5517 | Z25: =+Y25/W25*100 -> 91.857305 | AA25: =Results!W33 -> 7584.1718 | AB25: =+AA25/Y25*100 -> 90.789788 | AC25: =Results!X33 -> 9403.3084 | AD25: =+AC25/AA25*100 -> 123.98596
E27: =+G8-E8 -> 1942.3442 | F27: =+H8-F8 -> 4.7565408 | G27: =+I8-G8 -> 1685.8457 | H27: =+J8-H8 -> -3.6433823 | I27: =+K8-I8 -> 1777.5005 | J27: =+L8-J8 -> -0.58827826 | K27: =+M8-K8 -> 1910.5508 | L27: =+N8-L8 -> -0.30638389 | ... N27: =+P8-N8 -> 0.14154121
I28: =3119*109.8 -> 342466.2
E29: =+E24/E23*100 -> 24.102731 | G29: =+G24/G23*100 -> 21.747384 | I29: =+I24/I23*100 -> 23.050838 | K29: =+K24/K23*100 -> 24.249941 | M29: =+M24/M23*100 -> 25.360007
E30: =+E25/E23*100 -> 75.897269 | G30: =+G25/G23*100 -> 78.252616 | I30: =+I25/I23*100 -> 76.949162 | K30: =+K25/K23*100 -> 75.750059 | M30: =+M25/M23*100 -> 74.639993
C32: =C33+C34 -> 7013.824 | D32: =D33+D34 -> 0 | E32: =E33+E34 -> 8036.481 | F32: =F33+F34 -> 232.83271 | G32: =G33+G34 -> 8524.488 | H32: =H33+H34 -> 193.28926 | I32: =I33+I34 -> 11393.136 | J32: =J33+J34 -> 286.77984 | ... P32: =P33+P34 -> 207.58787
A33: аз он: - содирот молњо ва хизматрасонї | C33: =BoP!AC14 -> 1752.9 | E33: =BoP!AD14 -> 2105 | F33: =+E33/C33*100 -> 120.08671 | G33: =BoP!AE14 -> 1617.57 | H33: =+G33/E33*100 -> 76.844181 | I33: =BoP!AF14 -> 2573.297 | J33: =+I33/G33*100 -> 159.08412 | K33: =BoP!AG14 -> 2769.4661 | L33: =+K33/I33*100 -> 107.62326 | M33: =BoP!AH14 -> 2940.1717 | N33: =+M33/K33*100 -> 106.16385 | O33: =BoP!AI14 -> 3075.4343 | P33: =+O33/M33*100 -> 104.6005
A34: -воридот молњо ва хизматрасонї | C34: =BoP!AC15 -> 5260.924 | E34: =BoP!AD15 -> 5931.481 | F34: =+E34/C34*100 -> 112.74599 | G34: =BoP!AE15 -> 6906.918 | H34: =+G34/E34*100 -> 116.44508 | I34: =BoP!AF15 -> 8819.839 | J34: =+I34/G34*100 -> 127.69572 | K34: =BoP!AG15 -> 8896.2761 | L34: =+K34/I34*100 -> 100.86665 | M34: =BoP!AH15 -> 9176.3859 | N34: =+M34/K34*100 -> 103.14862 | O34: =BoP!AI15 -> 9450.5185 | P34: =+O34/M34*100 -> 102.98737

Sheet GDP
B1: Var. Name | C1: Наименование индикатора | D1: 1997 | E1: 1998 | F1: 1999 | G1: 2000 | H1: 2001 | I1: 2002 | J1: 2003 | K1: 2004 | L1: 2005 | M1: 2006 | N1: 2007 | O1: 2008 | P1: 2009 | Q1: 2010 | R1: 2011 | S1: 2012 | T1: 2013 | U1: 2014 | V1: 2015 | W1: 2016 | X1: 2017 | Y1: 2018 | Z1: 2019 | AA1: 2020 | AB1: 2021 | AC1: 2022 | AD1: 2023 | AE1: 2024 | AF1: 2025 | AG1: 2026 | AH1: 2027 | AI1: 2028 | AJ1: 2029 | AK1: 2030 | AL1: 2031 | AM1: 2032 | AN1: 2033 | AO1: 2034 | AP1: 2035
B2: GDPmp,t | C2: ВВП в рыночных ценах, млн. сомони | D2: 518.4 | E2: 1025.2 | F2: 1345 | G2: 1786.8 | H2: 2563.8 | I2: 3375.3 | J2: 4761.5 | K2: 6167.2 | L2: 7206.6 | M2: 9335.3 | N2: 12804.3 | O2: 17706.9 | P2: 20629 | Q2: 24707.1 | R2: 30071.1 | S2: 36163.1 | T2: 40525.2 | U2: 45606.6 | V2: =V13 -> 50977.4 | W2: =W13 -> 54790.3 | X2: =X13 -> 64434.3 | Y2: =Y13 -> 71059.2 | Z2: =Z13 -> 79109.8 | AA2: =AA13 -> 83958.3 | AB2: =AB13 -> 101076.3 | AC2: =AC13 -> 118181.7 | ... AP2: =AP13 -> 568732.06 | AS2: GDPmp,t = GDPmp,t
B3: gGDPt | C3: Реальный рост ВВП, % | D3: 101.7 | E3: 105.3 | F3: 103.7 | G3: 108.3 | H3: 109.6 | I3: 110.8 | J3: 111.1 | K3: 110.3 | L3: 106.7 | M3: 107 | N3: 107.8 | O3: 107.9 | P3: 103.9 | Q3: 106.5 | R3: 107.4 | S3: 107.5 | T3: 107.4 | U3: 106.7 | V3: =V30 -> 106 | W3: =W30 -> 106.9 | X3: =X30 -> 107.1 | Y3: =Y30 -> 106.95739 | Z3: =Z30 -> 107.44243 | AA3: =AA30 -> 104.63389 | AB3: =AB30 -> 110.98125 | AC3: =AC30 -> 108.03592 | ... AP3: =AP30 -> 108.60848 | AS3: gGDPt = gGDPmp,t
B4: defGDPt | C4: Дефлятор ВВП, % | D4: 165.22999 | E4: 187.8085 | F4: 126.51293 | G4: 122.66628 | H4: 130.91748 | I4: 118.81971 | J4: 126.97475 | K4: 117.42721 | L4: 109.5161 | M4: 121.06374 | N4: 127.23565 | O4: 128.16376 | P4: 112.12955 | Q4: 112.44802 | R4: 113.32436 | S4: 111.86852 | T4: 104.34106 | U4: 105.47223 | V4: =V64 -> 105.4494 | W4: =W64 -> 100.54218 | X4: =X64 -> 109.80547 | Y4: =Y64 -> 103.10801 | Z4: =Z64 -> 103.61775 | AA4: =AA64 -> 101.42872 | AB4: =AB64 -> 108.47661 | AC4: =AC64 -> 108.22628 | ... AP4: =AP64 -> 102.45581 | AS4: defGDPt = defGDPmp,t
B5: GDP2009mp,t | C5: ВВП в рыночных ценах 2009 года | D5: 8495.6919 | E5: 8945.9636 | F5: 9276.9643 | G5: 10046.952 | H5: 11011.46 | I5: 12200.697 | J5: 13554.975 | K5: 14951.137 | L5: 15952.863 | M5: 17069.564 | N5: 18400.99 | O5: 19854.668 | P5: 20629 | Q5: 21969.885 | R5: 23595.656 | S5: 25365.331 | T5: 27242.365 | U5: 29067.604 | V5: =V47 -> 30811.66 | W5: =W47 -> 32937.664 | X5: =X47 -> 35276.239 | Y5: =Y47 -> 37730.543 | Z5: =Z47 -> 40538.613 | AA5: =AA47 -> 42417.129 | AB5: =AB47 -> 47075.058 | AC5: =AC47 -> 50857.973 | ... AP5: =AP47 -> 144993.17 | AS5: GDP2009mp,t = GDP2009mp,t
B6: GDPPCUS,t | C6: ВВП на душу населения, долл. США | G6: 147.60889 | H6: 170.46641 | I6: 187.4139 | J6: 234.21412 | K6: 306.17541 | L6: 334.15138 | M6: 400.65841 | N6: 515.4486 | O6: 702.8013 | P6: 661.30182 | Q6: 750.4 | R6: 845.64821 | S6: 961.47143 | T6: 1053.5032 | U6: 1119.3135 | V6: =V7/Assumptions!V12 -> 978.4573 | W6: =W7/Assumptions!W12 -> 808.65537 | X6: =X7/Assumptions!X12 -> 852.82525 | Y6: =Y7/Assumptions!Y12 -> 860.01836 | Z6: =Z7/Assumptions!Z12 -> 900.31584 | AA6: =AA7/Assumptions!AA12 -> 864.39922 | AB6: =AB7/Assumptions!AB12 -> 911.84819 | AC6: =AC7/Assumptions!AC12 -> 1073.7361 | ... AP6: =AP7/Assumptions!AP12 -> 4458.2603 | AS6: GDPPCUS,t = GDPmp,t/erUSDt/POPt
C7: ВВП на душу населения, в сомони | Q7: 3285.8 | R7: 3898.1 | S7: 4579.2 | T7: 5019.1 | U7: 5523.7 | V7: 6031.7 | W7: 6336.3 | X7: 7291.4 | Y7: 7870.2 | Z7: 8580.1 | AA7: 8922.2423 | AB7: 10312 | AC7: 11838.8 | AD7: =AD2/Assumptions!AD63 -> 13039.182 | AE7: =AE2/Assumptions!AE63 -> 14981.526 | AF7: =AF2/Assumptions!AF63 -> 16684.49 | AG7: =AG2/Assumptions!AG63 -> 18464.635 | AH7: =AH2/Assumptions!AH63 -> 20375.708 | AI7: =AI2/Assumptions!AI63 -> 22515.954 | AJ7: =AJ2/Assumptions!AJ63 -> 25175.675 | AK7: =AK2/Assumptions!AK63 -> 27600.338 | ... AP7: =AP2/Assumptions!AP63 -> 46099.705
B8: ИПЦ, в том числе: (дек/дек), факт | C8: Inflation (dec/dec), fact, incl. | G8: 160.62781 | H8: 112.47905 | I8: 114.50567 | J8: 113.65265 | K8: 105.62006 | L8: 106.89379 | M8: 111.9 | N8: 121.5 | O8: 120.4 | P8: 106.4 | Q8: 106.5 | R8: 112.5 | S8: 105.8 | T8: 103.7 | U8: 107.4 | V8: =Monetary!V15 -> 105.1 | W8: =Monetary!W15 -> 106.1 | X8: =Monetary!X15 -> 106.7411 | Y8: =Monetary!Y15 -> 105.37889 | Z8: =Monetary!Z15 -> 108 | AA8: =Monetary!AA15 -> 109.4 | AB8: =Monetary!AB15 -> 108 | AC8: =Monetary!AC15 -> 104.2 | ... AP8: =Monetary!AP15 -> 104.91717
W9: =W2-V2 -> 3812.9 | X9: =X2-W2 -> 9644 | Y9: =Y2-X2 -> 6624.9 | Z9: =Z2-Y2 -> 8050.6 | AA9: =AA2-Z2 -> 4848.5 | AB9: =AB2-AA2 -> 17118 | AC9: =AC2-AB2 -> 17105.4 | AD9: =AD2-AC2 -> 14600.2 | ... AP9: =AP2-AO2 -> 57630.323
C13: ВВП в рыночных ценах, млн. сомони | D13: 518.4 | E13: 1025.2 | F13: 1345 | G13: 1786.8 | H13: 2563.8 | I13: 3375.3 | J13: 4761.5 | K13: 6167.2 | L13: 7206.6 | M13: 9335.3 | N13: 12804.3 | O13: 17706.9 | P13: 20629 | Q13: 24707.1 | R13: 30071.1 | S13: 36163.1 | T13: 40525.2 | U13: 45606.6 | V13: =V14+V15 -> 50977.4 | W13: =W14+W15 -> 54790.3 | X13: =X14+X15 -> 64434.3 | Y13: =Y14+Y15 -> 71059.2 | Z13: =Z14+Z15 -> 79109.8 | AA13: =AA14+AA15 -> 83958.3 | AB13: =AB14+AB15 -> 101076.3 | AC13: =AC14+AC15 -> 118181.7 | ... AP13: =AP14+AP15 -> 568732.06 | AS13: GDPmp,t = NITt+GDPfc,t
C14: Чистые косвенные налоги | D14: 49.8 | E14: 77.8 | F14: 98 | G14: 149.7 | H14: 230.3 | I14: 332.8 | J14: 508.4 | K14: 679.7 | L14: 831.2 | M14: 1059.7 | N14: 1603.5 | O14: 2235.9 | P14: 2286.6 | Q14: 2781.7 | R14: 3727.5 | S14: 4455.8 | T14: 5159.5 | U14: 6361.6 | V14: =5453.6-83.4 -> 5370.2 | W14: =5755.1-95 -> 5660.1 | X14: =6467.9-130.8 -> 6337.1 | Y14: =7131.5-112.4 -> 7019.1 | Z14: =7827.1-134.4 -> 7692.7 | AA14: =7718-175.3 -> 7542.7 | AB14: =9880.8-184.3 -> 9696.5 | AC14: 10687.4 | AD14: =13443.4-246.2 -> 13197.2 | AE14: =14824.4-299.5 -> 14524.9 | AF14: =18541.5-384.5 -> 18157 | AG14: =gateway!AG12 -> 18610.317 | AH14: =gateway!AH12 -> 20494.299 | AI14: =gateway!AI12 -> 21611.49 | AJ14: =gateway!AJ12 -> 21722.856 | AK14: =gateway!AK12 -> 21977.798 | AL14: =gateway!AL12 -> 22429.217 | AM14: =gateway!AM12 -> 23764.345 | AN14: =gateway!AN12 -> 26851.732 | ... AP14: =gateway!AP12 -> 34282.491 | AS14: NITt = NITt
C15: ВВП в основных ценах | D15: 468.6 | E15: 947.4 | F15: 1247 | G15: 1637.1 | H15: 2333.5 | I15: 3042.5 | J15: 4253.1 | K15: 5487.5 | L15: 6375.4 | M15: 8275.6 | N15: 11200.8 | O15: 15471 | P15: 18342 | Q15: 21925.4 | R15: 26343.6 | S15: 31707.3 | T15: 35365.7 | U15: 39245 | V15: =SUM(V16:V22) -> 45607.2 | W15: =SUM(W16:W22) -> 49130.2 | X15: =SUM(X16:X22) -> 58097.2 | Y15: =SUM(Y16:Y22) -> 64040.1 | Z15: =SUM(Z16:Z22) -> 71417.1 | AA15: =SUM(AA16:AA22) -> 76415.6 | AB15: =SUM(AB16:AB22) -> 91379.8 | AC15: =SUM(AC16:AC22) -> 107494.3 | ... AP15: =SUM(AP16:AP22) -> 534449.57 | AS15: GDPfc,t = (VAAB,t+VACDE,t+VAF,t+VAGoodsO,t+VAGH,t+VAI,t+VAOther,t)
C16: Сельское хозяйство и рыболовство | D16: 165.9 | E16: 257.4 | F16: 341.4 | G16: 448.9 | H16: 610.4 | I16: 750.5 | J16: 1151.9 | K16: 1185.6 | L16: 1527.2 | M16: 2002.6 | N16: 2488.3 | O16: 3517.9 | P16: 3827 | Q16: 4839.3 | R16: 7167.6 | S16: 8435.7 | T16: 8279.6 | U16: 10692.6 | V16: 11006.4 | W16: =11399.2+28.4 -> 11427.6 | X16: =13069.4 -> 13069.4 | Y16: 14049.8 | Z16: 16507.9 | AA16: 19050.5 | AB16: 22690.7 | AC16: 27104.8 | AD16: 30352.5 | AE16: 35915.7 | AF16: 38820.5 | AG16: =AF16*AG33*AG67/10000+1248.5 -> 44884.803 | AH16: =AG16*AH33*AH67/10000+1704.63810892211 -> 51040.391 | AI16: =AH16*AI33*AI67/10000+8291.37299199111 -> 64272.573 | AJ16: =AI16*AJ33*AJ67/10000-3122.74235819066 -> 67155.25 | AK16: =AJ16*AK33*AK67/10000-4017.1778005868 -> 69302.972 | AL16: =AK16*AL33*AL67/10000+12207.0045852159 -> 87150.42 | AM16: =AL16*AM33*AM67/10000-6139.99815483247 -> 87774.032 | AN16: =AM16*AN33*AN67/10000 -> 94607.201 | AO16: =AN16*AO33*AO67/10000 -> 101740.47 | AP16: =AO16*AP33*AP67/10000 -> 109667.71 | AS16: VAAB,t = VAAB,t-1·gVAAB,t·defVAAB,t/10000
C17: Промышленность | D17: 114 | E17: 206.1 | F17: 291.6 | G17: 592.3 | H17: 858 | I17: 1117.2 | J17: 1440.2 | K17: 1644.4 | L17: 1645.1 | M17: 1987 | N17: 2349.4 | O17: 2515.8 | P17: 2957.4 | Q17: 3642.7 | R17: 4368.9 | S17: 4947.8 | T17: 5103.1 | U17: 5510.9 | V17: =811.2+5471.4+1443.7 -> 7726.3 | W17: =1550+6233.9+1483 -> 9266.9 | X17: =2463.1+8251+2074.6+51.2 -> 12839.9 | Y17: =2528.5+9400.4+3025.7+76.9 -> 15031.5 | Z17: =2642.3+10626.3+3505.5+99.7 -> 16873.8 | AA17: =2410.7+13119.2+3890.1+91.3 -> 19511.3 | AB17: =4669.7+15160.3+4189.5+119.5 -> 24139 | AC17: =5027.2+17893.5+4728.3+113 -> 27762 | AD17: =5407.1+19402.9+4817.5+115.2 -> 29742.7 | AE17: =6456.6+20620.3+5452+137.8 -> 32666.7 | AF17: 28632 | AG17: =Industry!AG57-617.266632765852 -> 45302.801 | AH17: =Industry!AH57-4154.07814403639 -> 51435.316 | AI17: =Industry!AI57-8880.00859164027 -> 59554.869 | AJ17: =Industry!AJ57-14262.8971884416 -> 70610.731 | AK17: =Industry!AK57+2034.25522852303 -> 86152.797 | AL17: =Industry!AL57+7027.27848704623 -> 96405.531 | AM17: =Industry!AM57+35248.2981221771 -> 126812.61 | AN17: =Industry!AN57 -> 106105.21 | AO17: =Industry!AO57+1000 -> 118003.46 | AP17: =Industry!AP57+1000 -> 131259.04 | AS17: VACDE,t = VACDE,t
C18: Строительство | D18: 14.3 | E18: 39.5 | F18: 73 | G18: 38 | H18: 69.7 | I18: 68.9 | J18: 136.6 | K18: 262.3 | L18: 327.1 | M18: 567.5 | N18: 1034.6 | O18: 1832.6 | P18: 2098.4 | Q18: 2528.2 | R18: 2387.5 | S18: 3023.5 | T18: 4200.8 | U18: 4660 | V18: 7679.3 | W18: 8382.9 | X18: 7680.4 | Y18: 9411.7 | Z18: 9281.6 | AA18: 8863.7 | AB18: 11417.3 | AC18: 13250.1 | AD18: 14923.6 | AE18: 17873.3 | AF18: 12608.5 | AG18: =0.44*OEA!AG22+10484.5 -> 24902.408 | AH18: =0.49*OEA!AH22+8390.09 -> 27462.812 | AI18: =0.55*OEA!AI22+4741.75560268844 -> 29230.193 | AJ18: =0.69*OEA!AJ22-362.524 -> 35086.56 | AK18: =0.67*OEA!AK22+1692.83849206156 -> 38920.76 | AL18: =0.63*OEA!AL22+3693.52 -> 43544.138 | AM18: =0.602*OEA!AM22+3836.468 -> 47937.118 | AN18: =0.7*OEA!AN22 -> 63940.09 | AO18: =0.69*OEA!AO22 -> 78807.039 | AP18: =0.69*OEA!AP22 -> 98801.407 | AS18: VAF,t = 0,58·InvNAF,t
C19: Прочие товары | D19: 6 | E19: 10.2 | F19: 4.8 | G19: 5.9 | H19: 7.5 | I19: 13.4 | J19: 14.5 | K19: 24.2 | L19: 20.9 | M19: 20.8 | N19: 29.1 | O19: 34.9 | P19: 29.5 | Q19: 13.8 | AS19: VAGoodsO,t = VAGoodsO,t-1·VACDE,t/VACDE,t-1
C20: Розничная и оптовая торговля | D20: 108.6 | E20: 231.8 | F20: 270 | G20: 193.9 | H20: 274.9 | I20: 394.7 | J20: 544.1 | K20: 1017.5 | L20: 1191.6 | M20: 1593.8 | N20: 2119.7 | O20: 3577.3 | P20: 4345.8 | Q20: 4999.9 | R20: 3949.2 | S20: 5032.7 | T20: 5823.3 | U20: 6419.6 | V20: =4102.8+1331.1 -> 5433.9 | W20: =4625.3+1485.7 -> 6111 | X20: =6353.5 -> 6353.5 | Y20: =7359.6+1699.1 -> 9058.7 | Z20: =8764.1+1938.6 -> 10702.7 | AA20: =8978.4+1744.5 -> 10722.9 | AB20: =10956+2405.8 -> 13361.8 | AC20: =13042+3060.8 -> 16102.8 | AD20: =13851.7+3687.1 -> 17538.8 | AE20: =16467.3+4495.4 -> 20962.7 | AF20: 29189.2 | AG20: =(Household!AG3)*0.2718062-93 -> 24355.028 | AH20: =(Household!AH3-600)*0.31-4486.97 -> 27976.16 | AI20: =(Household!AI3-600)*0.29-3258 -> 31383.796 | AJ20: =(Household!AJ3)*0.29-3080.55 -> 37043.392 | AK20: =(Household!AK3)*0.31-2552.221 -> 43686.672 | AL20: =(Household!AL3-600)*0.31-1982.426 -> 47704.087 | AM20: =(Household!AM3-600)*0.31-3149.142 -> 50808.325 | AN20: =(Household!AN3-600)*0.4 -> 77729.567 | AO20: =(Household!AO3-600)*0.39 -> 81907.053 | AP20: =(Household!AP3-600)*0.38 -> 86540.154 | AS20: VAGH,t = RETt·0,447-750
C21: Транспорт и связь | D21: 15.1 | E21: 42.7 | F21: 99 | G21: 85 | H21: 127.6 | I21: 185.7 | J21: 260.2 | K21: 409 | L21: 533.3 | M21: 673.1 | N21: 1221.9 | O21: 1782.2 | P21: 2264.9 | Q21: 2758 | R21: 4356.3 | S21: 5535.2 | T21: 6172.2 | U21: 6523.8 | V21: 4859.2 | W21: 4875.2 | X21: 4870 | Y21: 4277.6 | Z21: 4829.2 | AA21: 3818.8 | AB21: =3735+1473.6 -> 5208.6 | AC21: =4401.1+1622.4 -> 6023.5 | AD21: =5272.4+1967.1 -> 7239.5 | AE21: =6358.5+2407.1 -> 8765.6 | AF21: 15892.7 | AG21: =AF21+(Household!AG9+Household!AG18-Household!AF9-Household!AF18)*0.001-4289.5 -> 11619.91 | AH21: =AG21+(Household!AH9+Household!AH18-Household!AG9-Household!AG18)*0.02+1094.44 -> 13048.297 | AI21: =AH21+(Household!AI9+Household!AI18-Household!AH9-Household!AH18)*0.02-507.6 -> 12873.957 | AJ21: =AI21+(Household!AJ9+Household!AJ18-Household!AI9-Household!AI18)*0.13+1568.47 -> 16838.971 | AK21: =AJ21+(Household!AK9+Household!AK18-Household!AJ9-Household!AJ18)*0.03+2122.039 -> 19384.193 | AL21: =AK21+(Household!AL9+Household!AL18-Household!AK9-Household!AK18)*0.09+199.3816 -> 20733.764 | AM21: =AL21+(Household!AM9+Household!AM18-Household!AL9-Household!AL18)*0.099+737.1796 -> 22913.833 | AN21: =AM21+(Household!AN9+Household!AN18-Household!AM9-Household!AM18)*0.5 -> 31369.352 | AO21: =AN21+(Household!AO9+Household!AO18-Household!AN9-Household!AN18)*0.04 -> 32179.896 | AP21: =AO21+(Household!AP9+Household!AP18-Household!AO9-Household!AO18)*0.03 -> 32811.694 | AS21: VAI,t = VAI,t-1+(RETt+SERt-RETt-1-SERt-1)·0,24
C22: Прочие услуги (остатком) | D22: 44.7 | E22: 159.7 | F22: 167.2 | G22: 273.2 | H22: 385.6 | I22: 512.2 | J22: 706.1 | K22: 945 | L22: 1130.7 | M22: 1431.2 | N22: 1958.1 | O22: 2214.2 | P22: 2823.8 | Q22: 3143.4 | R22: 4114.1 | S22: 4732.4 | T22: 5786.7 | U22: 5438.1 | V22: =2197.5+694+1492.8+2522.7+1152.2+1619.3-776.4 -> 8902.1 | W22: =1091.7+765.3+1708.6+2871.3+1292.1+1644.1-306.5 -> 9066.6 | X22: =1697.8+1533.8+1994.4+740.6+237.2+57.7+1874.8+3022.7+1359.1+296.7+736.4+275-542.2 -> 13284 | Y22: =1366.8+2078.9+791.4+237.7+60.1+2005.6+3256.3+1440.9+328.2+923.2+286-564.3 -> 12210.8 | Z22: =1424.1+1925.1+852.7+288.9+81.5+2139.9+3752.6+1651.2+366+972.3+347.6-580 -> 13221.9 | AA22: =1492.9+2157.1+1103.3+269.5+97.4+2247.4+4086.8+1842.9+408+888+462.1-607 -> 14448.4 | AB22: =2055.7+1228.9+568.4+207.9+2411.3+4778.7+2072.3+525.4+844.2+471.6-602 -> 14562.4 | AC22: =4066.6+1323+474.1+242.5+2620.7+5058.3+2146.1+571.5+1142.2+541.1-935 -> 17251.1 | AD22: =4831.1+1339.3+464.6+320.1+3473.8+6075.3+2451.3+559.2+1173.7+619.5-1520.3 -> 19787.6 | AE22: =5899.9+1692.9+665.1+351.4+4308.3+7589+3376.6+737.4+1725.8+714.2-1985.6 -> 25075 | AF22: 33619.1 | AG22: =AF22*(Household!AG18/Household!AF18)-9042.7 -> 30222.87 | AH22: =AG22*(Household!AH18/Household!AG18)-675.502 -> 33999.934 | AI22: =AH22*(Household!AI18/Household!AH18)-2727.1 -> 35683.531 | AJ22: =AI22*(Household!AJ18/Household!AI18)+3029.94 -> 42497.516 | AK22: =AJ22*(Household!AK18/Household!AJ18)-150.1586 -> 46562.406 | AL22: =AK22*(Household!AL18/Household!AK18)+845.7732 -> 50363.648 | AM22: =AL22*(Household!AM18/Household!AL18)+582.2976 -> 53960.031 | AN22: =AM22*(Household!AN18/Household!AM18) -> 59814.029 | AO22: =AN22*(Household!AO18/Household!AN18) -> 68123.424 | AP22: =AO22*(Household!AP18/Household!AO18) -> 75369.57 | AS22: VAOther,t = VAOther,t-1·(SERt/SERt-1)
C23: Справочно:
C24: Товары | D24: 300.2 | E24: 513.2 | F24: 710.8 | G24: 1085.1 | H24: 1545.6 | I24: 1950 | J24: 2743.2 | K24: 3116.5 | L24: 3520.3 | M24: 4577.9 | N24: 5901.4 | O24: 7901.2 | P24: 8912.3 | Q24: 11024 | R24: 13924 | S24: 16407 | T24: 17583.5 | U24: 20863.5 | V24: =V16+V17+V18+V19 -> 26412 | W24: =W16+W17+W18+W19 -> 29077.4 | X24: =X16+X17+X18+X19 -> 33589.7 | Y24: =Y16+Y17+Y18+Y19 -> 38493 | Z24: =Z16+Z17+Z18+Z19 -> 42663.3 | AA24: =AA16+AA17+AA18+AA19 -> 47425.5 | AB24: =AB16+AB17+AB18+AB19 -> 58247 | AC24: =AC16+AC17+AC18+AC19 -> 68116.9 | ... AP24: =AP16+AP17+AP18+AP19 -> 339728.15 | AS24: VAGoods,t = VAAB,t+VACDE,t+VAF,t+VAGoodsO,t
C25: Услуги | D25: 168.4 | E25: 434.2 | F25: 536.2 | G25: 552 | H25: 787.9 | I25: 1092.5 | J25: 1509.9 | K25: 2371 | L25: 2855.1 | M25: 3697.7 | N25: 5299.4 | O25: 7744.3 | P25: 9429.7 | Q25: 10901.3 | R25: 12419.6 | S25: 15300.3 | T25: 17782.2 | U25: 18381.5 | V25: =V20+V21+V22 -> 19195.2 | W25: =W20+W21+W22 -> 20052.8 | X25: =X20+X21+X22 -> 24507.5 | Y25: =Y20+Y21+Y22 -> 25547.1 | Z25: =Z15-Z24 -> 28753.8 | AA25: =AA15-AA24 -> 28990.1 | AB25: =AB15-AB24 -> 33132.8 | AC25: =AC15-AC24 -> 39377.4 | AD25: =AD15-AD24 -> 44565.9 | AE25: =AE15-AE24 -> 54803.3 | AF25: =AF15-AF24 -> 78701 | AG25: =AG15-AG24 -> 66197.808 | ... AP25: =AP15-AP24 -> 194721.42 | AS25: VAServces,t = GDPfc,t-VAGoods,t
V27: 5370.8 | W27: =W13-V13 -> 3812.9 | X27: =X13-W13 -> 9644 | Y27: =Y13-X13 -> 6624.9 | Z27: =Z13-Y13 -> 8050.6 | AA27: =AA13-Z13 -> 4848.5 | AB27: =AB13-AA13 -> 17118 | AC27: =AC13-AB13 -> 17105.4 | AD27: =AD13-AC13 -> 14600.2 | ... AP27: =AP13-AO13 -> 57630.323
C30: ВВП в рыночных ценах, % | D30: 101.7 | E30: 105.3 | F30: 103.7 | G30: 108.3 | H30: 109.6 | I30: 110.8 | J30: 111.1 | K30: 110.3 | L30: 106.7 | M30: 107 | N30: 107.8 | O30: 107.9 | P30: 103.9 | Q30: 106.5 | R30: 107.4 | S30: 107.5 | T30: 107.4 | U30: 106.7 | V30: 106 | W30: =(V14*W31+W32*V15)/(V14+V15) -> 106.9 | X30: =(W14*X31+X32*W15)/(W14+W15) -> 107.1 | Y30: =(X14*Y31+Y32*X15)/(X14+X15) -> 106.95739 | Z30: =(Y14*Z31+Z32*Y15)/(Y14+Y15) -> 107.44243 | AA30: =(Z14*AA31+AA32*Z15)/(Z14+Z15) -> 104.63389 | AB30: =(AA14*AB31+AB32*AA15)/(AA14+AA15) -> 110.98125 | AC30: =(AB14*AC31+AC32*AB15)/(AB14+AB15) -> 108.03592 | AD30: =(AC14*AD31+AD32*AC15)/(AC14+AC15) -> 108.31977 | ... AP30: =(AO14*AP31+AP32*AO15)/(AO14+AO15) -> 108.60848 | AS30: gGDPmp,t = (NITt-1·gNITt+gGDPfc,t·GDPfc,t-1)/(NITt-1+GDPfc,t-1)
C31: Чистые косвенные налоги | H31: 110 | I31: 111.8 | J31: 111.9 | K31: 111 | L31: 107.3 | M31: 107.4 | N31: 108.3 | O31: 107.9 | P31: 102 | Q31: 106.5 | R31: 107.4 | S31: 107.5 | T31: 107.4 | U31: 106.7 | V31: 106 | W31: 106.9 | X31: 107.1 | Y31: 104.8 | Z31: 103 | AA31: 100 | AB31: 100 | AC31: 100 | AD31: 100 | AE31: =(AE32/100)^1*100 -> 108.42918 | AF31: =(AF32/100)^1*100 -> 108.43563 | AG31: =(AG32/100)^1*100 -> 108.49433 | AH31: =(AH32/100)^1*100 -> 108.43204 | AI31: =(AI32/100)^1*100 -> 108.58847 | AJ31: =(AJ32/100)^1*100 -> 108.78201 | AK31: =(AK32/100)^1*100 -> 108.04844 | AL31: =(AL32/100)^1*100 -> 108.54826 | ... AP31: =(AP32/100)^1*100 -> 108.60848 | AS31: gNITt = (gGDPfc,t/100)^1,00·100
C32: ВВП в основных ценах | H32: 109.60139 | I32: 110.72988 | J32: 111.0332 | K32: 110.16366 | L32: 106.66415 | M32: 106.90176 | N32: 107.66178 | O32: 107.89471 | P32: 103.9 | Q32: 106.5 | R32: 107.4 | S32: 107.5 | T32: 107.4 | U32: 106.7 | V32: 106 | W32: 106.9 | X32: 107.1 | Y32: =SUMPRODUCT(Y33:Y39,X16:X22)/SUM(X16:X22) -> 107.19271 | Z32: =SUMPRODUCT(Z33:Z39,Y16:Y22)/SUM(Y16:Y22) -> 107.92934 | AA32: =SUMPRODUCT(AA33:AA39,Z16:Z22)/SUM(Z16:Z22) -> 105.13303 | AB32: =SUMPRODUCT(AB33:AB39,AA16:AA22)/SUM(AA16:AA22) -> 112.06516 | AC32: =SUMPRODUCT(AC33:AC39,AB16:AB22)/SUM(AB16:AB22) -> 108.88863 | AD32: =SUMPRODUCT(AD33:AD39,AC16:AC22)/SUM(AC16:AC22) -> 109.14694 | AE32: =SUMPRODUCT(AE33:AE39,AD16:AD22)/SUM(AD16:AD22) -> 108.42918 | AF32: =SUMPRODUCT(AF33:AF39,AE16:AE22)/SUM(AE16:AE22) -> 108.43563 | ... AP32: =SUMPRODUCT(AP33:AP39,AO16:AO22)/SUM(AO16:AO22) -> 108.60848 | AS32: gGDPfc,t = (gVAAB,t·VAAB,t-1+gVACDE,t·VACDE,t-1+gVAF,t·VAF,t-1+gVAGoodsO,t·VAGoodsO,t-1+gVAGH,t·VAGH,t-1+gVAI,t·VAI,t-1+gVAOther,t·VAOther,t-1)/(VAAB,t-1+VACDE,t-1+VAF,t-1+VAGoodsO,t-1+VAGH,t-1+VAI,t-1+VAOther,t-1)
C33: Сельское хозяйство и рыболовство | L33: 101.4 | M33: 105.7 | N33: 103.5 | O33: 106.1 | P33: 110.5 | Q33: 106.8 | R33: 107.9 | S33: 110.4 | T33: 107.6 | U33: 104.5 | V33: =Agriculture!V3 -> 103.2 | W33: =Agriculture!W3 -> 105.2 | X33: =Agriculture!X3 -> 106.8 | Y33: =Agriculture!Y3 -> 104 | Z33: =Agriculture!Z3 -> 107.1 | AA33: =Agriculture!AA3 -> 108.8 | AB33: =Agriculture!AB3 -> 106.6 | AC33: =Agriculture!AC3 -> 108 | AD33: 112.2 | AE33: =Agriculture!AE3 -> 110.6 | AF33: =Agriculture!AF3 -> 109.5 | AG33: =Agriculture!AG3 -> 108.91987 | AH33: =Agriculture!AH3 -> 108.61303 | AI33: =Agriculture!AI3 -> 108.27265 | AJ33: =Agriculture!AJ3 -> 108.15398 | AK33: =Agriculture!AK3 -> 108.31356 | AL33: =Agriculture!AL3 -> 107.60081 | ... AP33: =Agriculture!AP3 -> 107.25535 | AS33: gVAAB,t = (1+gVAAB,t/100)·100
C34: Промышленность | L34: 106.4 | M34: 105.5 | N34: 109.9 | O34: 96.5 | P34: 93.5 | Q34: 109.2 | R34: 105.7 | S34: 110.8 | T34: 103.8 | U34: 105 | V34: =Industry!V58 -> 111.3 | W34: =Industry!W58 -> 116 | X34: =Industry!X58 -> 121.3 | Y34: =Industry!Y58 -> 110.6 | Z34: =Industry!Z58 -> 113.2 | AA34: =Industry!AA58 -> 108.8 | AB34: =Industry!AB58 -> 120.8 | AC34: =Industry!AC58 -> 115.4 | AD34: 109.7 | AE34: =Industry!AE58 -> 120 | AF34: =Industry!AF58 -> 122.1 | AG34: =Industry!AG58 -> 125.02097 | AH34: =Industry!AH58 -> 125.0001 | AI34: =Industry!AI58 -> 125.10772 | AJ34: =Industry!AJ58 -> 125.0738 | AK34: =Industry!AK58 -> 119.95581 | AL34: =Industry!AL58 -> 119.92603 | ... AP34: =Industry!AP58 -> 122.3396 | AS34: gVACDE,t = gVACDE,t
C35: Строительство | L35: 116.4 | M35: 107.2 | N35: 110.4 | O35: 121.2 | P35: 84.5 | Q35: 109.52934 | R35: 105.5 | S35: 75.6 | T35: 117.2 | U35: 125.3 | V35: =OEA!V39 -> 121.2 | W35: =OEA!W39 -> 120.3 | X35: =OEA!X39 -> 104.1 | Y35: =OEA!Y39 -> 110.2 | Z35: =OEA!Z39 -> 104.6 | AA35: =OEA!AA39 -> 104 | AB35: 132.1 | AC35: =OEA!AC39 -> 111.4 | AD35: =OEA!AD39 -> 112.3 | AE35: =OEA!AE39 -> 114.38905 | AF35: =OEA!AF39 -> 68.092444 | AG35: =OEA!AG39 -> 173.24993 | AH35: =OEA!AH39 -> 116.08606 | AI35: =OEA!AI39 -> 110.87036 | AJ35: =OEA!AJ39 -> 125.03681 | ... AP35: =OEA!AP39 -> 130.5951 | AS35: gVAF,t = gCONSTRt
C36: Прочие товары | L36: 100 | M36: 100 | N36: 110.2 | O36: 100 | P36: 100 | Q36: 109.2 | R36: 105.7 | S36: 110.8 | T36: 103.8 | U36: 105 | V36: =V34 -> 111.3 | W36: =W34 -> 116 | X36: =X34 -> 121.3 | Y36: =Y34 -> 110.6 | Z36: =Z34 -> 113.2 | AA36: =AA34 -> 108.8 | AB36: =AB34 -> 120.8 | AC36: =AC34 -> 115.4 | ... AP36: =AP34 -> 122.3396 | AS36: gVAGoodsO,t = gVACDE,t
C37: Розничная и оптовая торговля | L37: 108.9 | M37: 110.8 | N37: 105.3 | O37: 112.4 | P37: 112.5 | Q37: 107.5 | R37: 109.1 | S37: 115.9 | T37: 118.8 | U37: 106.7 | V37: 105.6 | W37: 106 | X37: 106.6 | Y37: 112.2 | Z37: 109.6 | AA37: 94.1 | AB37: 110.2 | AC37: =Household!AC4 -> 111.2 | AD37: 98.6 | AE37: =Household!AE4 -> 113.6 | AF37: =Household!AF4 -> 113.9 | AG37: =Household!AG4 -> 114.32794 | AH37: =Household!AH4 -> 114.46523 | AI37: =Household!AI4 -> 113.63166 | AJ37: =Household!AJ4 -> 113.89224 | AK37: =Household!AK4 -> 108.36872 | AL37: =Household!AL4 -> 109.84897 | ... AP37: =Household!AP4 -> 106.39789 | AS37: gVAGH,t = VAGH,t/VAGH,t-1/defVAGH,t·10000
C38: Транспорт и связь | L38: 130 | M38: 118.1 | N38: 183.8 | O38: 143.3 | P38: 153.5 | Q38: 119.39626 | R38: 150.89372 | S38: 124.05492 | T38: 110.30013 | U38: 105.11255 | V38: 102.1 | W38: =(W21/V21)^0.4*100 -> 100.13158 | X38: =(X21/W21)^3*100 -> 99.680354 | Y38: 93.3 | Z38: 115.7 | AA38: 79.4 | AB38: 95.3 | AC38: 96 | AD38: 121.7 | AE38: =(AE21/AD21)^0.82*100 -> 116.98224 | AF38: =(AF21/AE21)^0.54*100 -> 137.89377 | AG38: =(AG21/AF21)^2.85*100 -> 40.965148 | AH38: =(AH21/AG21)^0.2*100 -> 102.34584 | AI38: =(AI21/AH21)^1.22*100 -> 98.372346 | AJ38: =(AJ21/AI21)^0.11*100 -> 102.99743 | AK38: =(AK21/AJ21)^0.1*100 -> 101.41757 | AL38: =(AL21/AK21)^0.2*100 -> 101.35521 | AM38: =(AM21/AL21)^0.1*100 -> 101.00479 | AN38: =(AN21/AM21)^1.22*100 -> 146.69575 | AO38: =(AO21/AN21)^1.22*100 -> 103.16122 | AP38: =(AP21/AO21)^1.22*100 -> 102.40041 | AS38: gVAI,t = (VAI,t/VAI,t-1)^0,9·100
C39: Прочие услуги (остатком) | L39: 97.001641 | M39: 96.376863 | N39: 78.00434 | O39: 92.627551 | P39: 73.250437 | Q39: 93 | R39: 97 | S39: 95 | T39: 95 | U39: 102 | V39: 97 | W39: 97 | X39: 101 | Y39: 108 | Z39: 101 | AA39: 115 | AB39: 101 | AC39: 100 | AD39: 106.5 | AE39: 75.5 | AF39: 103 | AG39: 96.5 | AH39: 74.5 | AI39: 82 | AJ39: 67 | AK39: 84 | AL39: 84 | AM39: 82 | AN39: 57 | AO39: 92.5 | AP39: 67 | AS39: gVAOther,t = gVAOther,t
C40: Справочно:
C41: Товары | H41: 112.4 | I41: 111 | J41: 111.5 | K41: 105.3 | L41: 105.8 | M41: 105.2 | N41: 104.4 | O41: 103.4 | P41: 99 | Q41: 106.1 | R41: 106.9 | S41: 103.6 | T41: 105.9 | U41: 112.2 | V41: 109.7 | W41: 114.1 | X41: 107.4 | Y41: =SUMPRODUCT(Y33:Y36,X16:X19)/SUM(X16:X19) -> 107.94055 | Z41: =SUMPRODUCT(Z33:Z36,Y16:Y19)/SUM(Y16:Y19) -> 108.87079 | AA41: =SUMPRODUCT(AA33:AA36,Z16:Z19)/SUM(Z16:Z19) -> 107.75574 | AB41: =SUMPRODUCT(AB33:AB36,AA16:AA19)/SUM(AA16:AA19) -> 117.2079 | AC41: =SUMPRODUCT(AC33:AC36,AB16:AB19)/SUM(AB16:AB19) -> 111.7332 | AD41: =SUMPRODUCT(AD33:AD36,AC16:AC19)/SUM(AC16:AC19) -> 111.20054 | AE41: =SUMPRODUCT(AE33:AE36,AD16:AD19)/SUM(AD16:AD19) -> 115.08058 | AF41: =SUMPRODUCT(AF33:AF36,AE16:AE19)/SUM(AE16:AE19) -> 105.70049 | ... AP41: =SUMPRODUCT(AP33:AP36,AO16:AO19)/SUM(AO16:AO19) -> 119.37834 | AS41: gVAGoods,t = (gVAAB,t·VAAB,t-1+gVACDE,t·VACDE,t-1+gVAF,t·VAF,t-1+gVAGoodsO,t·VAGoodsO,t-1)/(VAAB,t-1+VACDE,t-1+VAF,t-1+VAGoodsO,t-1)
C42: Услуги | H42: 104.1 | I42: 110.2 | J42: 110.2 | K42: 119 | L42: 107.8 | M42: 109 | N42: 111.7 | O42: 112.9 | P42: 109.7 | Q42: 106.9 | R42: 107.7 | S42: 112 | T42: 109.1 | U42: 101.2 | V42: 101.7 | W42: 98.9 | X42: 106.6 | Y42: =(Y37*X20+X21*Y38+Y39*X22)/X25 -> 106.16773 | Z42: =(Z37*Y20+Y21*Z38+Z39*Y22)/Y25 -> 106.51082 | AA42: =(AA37*Z20+Z21*AA38+AA39*Z22)/Z25 -> 101.24161 | AB42: =(AB37*AA20+AA21*AB38+AB39*AA22)/AA25 -> 103.65206 | AC42: =(AC37*AB20+AB21*AC38+AC39*AB22)/AB25 -> 103.88792 | AD42: =(AD37*AC20+AC21*AD38+AD39*AC22)/AC25 -> 105.59453 | AE42: =(AE37*AD20+AD21*AE38+AE39*AD22)/AD25 -> 97.232736 | AF42: =(AF37*AE20+AE21*AF38+AF39*AE22)/AE25 -> 112.75048 | ... AP42: =(AP37*AO20+AO21*AP38+AP39*AO22)/AO25 -> 90.962117 | AS42: gVAServces,t = (gVAGH,t·VAGH,t-1+VAI,t-1·gVAI,t+gVAOther,t·VAOther,t-1)/VAServces,t-1
C46: В постоянных ценах 2009 года, млн. сомони
C47: ВВП в рыночных ценах 2009 года | G47: 10046.952 | H47: 11011.46 | I47: 12200.697 | J47: 13554.975 | K47: 14951.137 | L47: 15952.863 | M47: 17069.564 | N47: 18400.99 | O47: 19854.668 | P47: 20629 | Q47: 21969.885 | R47: 23595.656 | S47: 25365.331 | T47: 27242.365 | U47: 29067.604 | V47: 30811.66 | W47: =V47*W30/100 -> 32937.664 | X47: =W47*X30/100 -> 35276.239 | Y47: =X47*Y30/100 -> 37730.543 | Z47: =Y47*Z30/100 -> 40538.613 | AA47: =Z47*AA30/100 -> 42417.129 | AB47: =AA47*AB30/100 -> 47075.058 | AC47: =AB47*AC30/100 -> 50857.973 | AD47: =AC47*AD30/100 -> 55089.238 | ... AP47: =AO47*AP30/100 -> 144993.17 | AS47: GDP2009mp,t = GDP2009mp,t-1·gGDPmp,t/100
C48: Чистые косвенные налоги | H48: 1198.9946 | I48: 1340.4759 | J48: 1499.9926 | K48: 1664.9918 | L48: 1786.5362 | M48: 1918.7398 | N48: 2077.9952 | O48: 2242.1569 | P48: 2287 | Q48: 2435.655 | R48: 2615.8935 | S48: 2812.0855 | T48: 3020.1798 | U48: 3222.5319 | V48: 3415.8838 | W48: =V48*W31/100 -> 3651.5797 | X48: =W48*X31/100 -> 3910.8419 | Y48: =X48*Y31/100 -> 4098.5623 | Z48: =Y48*Z31/100 -> 4221.5192 | AA48: =Z48*AA31/100 -> 4221.5192 | AB48: =AA48*AB31/100 -> 4221.5192 | AC48: =AB48*AC31/100 -> 4221.5192 | AD48: =AC48*AD31/100 -> 4221.5192 | ... AP48: =AO48*AP31/100 -> 11110.908 | AS48: NIT2009t = NIT2009t-1·gNITt/100
C49: ВВП в основных ценах | K49: 13293.54 | L49: 14180.584 | M49: 15155.605 | N49: 16320.036 | O49: 17598.221 | P49: 18342 | Q49: 19534.23 | R49: 20979.763 | S49: 22553.245 | T49: 24222.185 | U49: 25845.072 | V49: 27395.776 | W49: =V49*W32/100 -> 29286.085 | X49: =W49*X32/100 -> 31365.397 | Y49: =X49*Y32/100 -> 33621.419 | Z49: =Y49*Z32/100 -> 36287.376 | AA49: =Z49*AA32/100 -> 38150.019 | AB49: =AA49*AB32/100 -> 42752.882 | AC49: =AB49*AC32/100 -> 46553.027 | AD49: =AC49*AD32/100 -> 50811.206 | ... AP49: =AO49*AP32/100 -> 133733.53 | AS49: GDP2009fc,t = GDP2009fc,t-1·gGDPfc,t/100
...

Sheet Agriculture
D1: 1997 | E1: 1998 | F1: 1999 | G1: 2000 | H1: 2001 | I1: 2002 | J1: 2003 | K1: 2004 | L1: 2005 | M1: 2006 | N1: 2007 | O1: 2008 | P1: 2009 | Q1: 2010 | R1: 2011 | S1: 2012 | T1: 2013 | U1: 2014 | V1: 2015 | W1: 2016 | X1: 2017 | Y1: 2018 | Z1: 2019 | AA1: 2020 | AB1: 2021 | AC1: 2022 | AD1: 2023 | AE1: 2024 | AF1: 2025 | AG1: 2026 | AH1: 2027 | AI1: 2028 | AJ1: 2029 | AK1: 2030 | AL1: 2031 | AM1: 2032 | AN1: 2033 | AO1: 2034 | AP1: 2035
B2: СЕЛЬСКОЕ ХОЗЯЙСТВО | C2: млн. Сомони | L2: 6855.9 | M2: 7246.7 | N2: 7500.4 | O2: 7957.9 | P2: 8793.5 | Q2: 9391.4 | R2: 14853.3 | S2: 16477.5 | T2: 16756.6 | U2: 21021.9 | V2: 21577.8 | W2: =W5+W8 -> 22907.672 | X2: =X5+X8 -> 24576 | Y2: =Y5+Y8 -> 45645.8 | Z2: =Z5+Z8 -> 48889.8 | AA2: =AA5+AA8 -> 53235.2 | AB2: =AB5+AB8 -> 56806.7 | AC2: =AC5+AC8 -> 61337.9 | AD2: =AD5+AD8 -> 66907.2 | ... AF2: =AF5+AF8 -> 84653.8 | AG2: =AG5+AG8+AG125 -> 95155.365 | AH2: =AH5+AH8+AH125 -> 104591.34 | AI2: =AI5+AI8+AI125 -> 114715.98 | AJ2: =AJ5+AJ8+AJ125 -> 125434.67 | AK2: =AK5+AK8+AK125 -> 136949.66 | AL2: =AL5+AL8+AL125 -> 148095.75 | AM2: =AM5+AM8+AM125 -> 159589.23 | AN2: =AN5+AN8+AN125 -> 172013.18 | ... AP2: =AP5+AP8+AP125 -> 199395.93 | AQ2: N5+N8
B3: темп роста | C3: % | L3: 101.6 | M3: 105.7 | N3: 103.5 | O3: 107.9 | P3: 110.5 | Q3: 106.8 | R3: 107.9 | S3: 110.4 | T3: 107.6 | U3: 104.5 | V3: 103.2 | W3: 105.2 | X3: 106.8 | Y3: 104 | Z3: 107.1 | AA3: 108.8 | AB3: 106.6 | AC3: 108 | AD3: 109 | AE3: 110.6 | AF3: 109.5 | AG3: =AG2/AF2/AG4*10000 -> 108.91987 | AH3: =AH2/AG2/AH4*10000 -> 108.61303 | AI3: =AI2/AH2/AI4*10000 -> 108.27265 | AJ3: =AJ2/AI2/AJ4*10000 -> 108.15398 | AK3: =AK2/AJ2/AK4*10000 -> 108.31356 | AL3: =AL2/AK2/AL4*10000 -> 107.60081 | AM3: =AM2/AL2/AM4*10000 -> 107.54575 | AN3: =AN2/AM2/AN4*10000 -> 107.24871 | ... AP3: =AP2/AO2/AP4*10000 -> 107.25535 | AQ3: N2/M2/N4*10000
B4: дефлятор | C4: % | M4: 100.00019 | N4: 100.00087 | O4: 98.331487 | P4: 100.00023 | Q4: 99.999382 | R4: 146.5788 | S4: 100.48455 | T4: 94.51099 | U4: 120.0521 | V4: 99.461614 | W4: =W2/V2/W3*10000 -> 100.91554 | X4: =X2/W2/X3*10000 -> 100.45209 | Y4: =Y2/X2/Y3*10000 -> 178.58965 | Z4: =Z2/Y2/Z3*10000 -> 100.00644 | AA4: =AA2/Z2/AA3*10000 -> 100.08102 | AB4: =AB2/AA2/AB3*10000 -> 100.10216 | AC4: =AC2/AB2/AC3*10000 -> 99.978263 | AD4: =AD2/AC2/AD3*10000 -> 100.07312 | ... AF4: =AF2/AE2/AF3*10000 -> 104.50522 | AG4: 103.2 | AH4: 101.2 | AI4: 101.3 | AJ4: 101.1 | AK4: 100.8 | AL4: 100.5 | AM4: 100.2 | AN4: 100.5 | AO4: 100.5 | AP4: 100.5
B5: РАСТЕНИЕВОДСТВО | C5: млн. Сомони | L5: 4724.9 | M5: 5032 | N5: 5147.7 | O5: 5523.5 | P5: 6219.5 | Q5: 6617.5 | R5: 10894.7 | S5: 11836.3 | T5: 11502.5 | U5: 14532.8 | V5: 14623.7 | W5: 15066.6 | X5: 16977.8 | Y5: 31669.6 | Z5: 34124 | AA5: 36919.4 | AB5: 39115.6 | AC5: 42115 | AD5: 44976.1 | AE5: 50984.9 | AF5: 56588 | AG5: =AG28+AG40+AG50+AG56+AG66+AG72+AG78+AG82 -> 61242.178 | AH5: =AH28+AH40+AH50+AH56+AH66+AH72+AH78+AH82 -> 66836.044 | AI5: =AI28+AI40+AI50+AI56+AI66+AI72+AI78+AI82 -> 72556.838 | AJ5: =AJ28+AJ40+AJ50+AJ56+AJ66+AJ72+AJ78+AJ82 -> 78788.347 | AK5: =AK28+AK40+AK50+AK56+AK66+AK72+AK78+AK82 -> 85058.32 | AL5: =AL28+AL40+AL50+AL56+AL66+AL72+AL78+AL82 -> 90393.172 | AM5: =AM28+AM40+AM50+AM56+AM66+AM72+AM78+AM82 -> 95752.602 | AN5: =AN28+AN40+AN50+AN56+AN66+AN72+AN78+AN82 -> 100785.75 | ... AP5: =AP28+AP40+AP50+AP56+AP66+AP72+AP78+AP82 -> 109860.02 | AQ5: N27+N39+N49+N55+N65+N71+N77+N81
B6: темп роста | C6: % | L6: 98.6 | M6: 106.5 | N6: 102.3 | O6: 108.4 | P6: 112.6 | Q6: 106.4 | R6: 108.2 | S6: 110.6 | T6: 107.6 | U6: 104.5 | V6: 101.4 | W6: 105.1 | X6: 107.4 | Y6: 103.4 | Z6: 107.8 | AA6: 108.2 | AB6: 105.9 | AC6: 107.7 | AD6: 106.8 | AE6: 113.4 | AF6: 109.9 | AG6: =AG5/AF5/AG7*10000 -> 107.25934 | AH6: =AH5/AG5/AH7*10000 -> 106.99413 | AI6: =AI5/AH5/AI7*10000 -> 108.34276 | AJ6: =AJ5/AI5/AJ7*10000 -> 107.51332 | AK6: =AK5/AJ5/AK7*10000 -> 107.42089 | AL6: =AL5/AK5/AL7*10000 -> 105.74328 | AM6: =AM5/AL5/AM7*10000 -> 105.61219 | AN6: =AN5/AM5/AN7*10000 -> 104.94159 | ... AP6: =AP5/AO5/AP7*10000 -> 101.29673 | AQ6: N5/M5/N7*10000
B7: дефлятор | C7: % | M7: 99.999632 | N7: 99.999301 | O7: 98.985561 | P7: 100.00063 | Q7: 99.999275 | R7: 152.15775 | S7: 98.230321 | T7: 90.315857 | U7: 120.90403 | V7: 99.236175 | W7: =W5/V5/W6*10000 -> 98.029158 | X7: =X5/W5/X6*10000 -> 104.92087 | Y7: =Y5/X5/Y6*10000 -> 180.4017 | Z7: =Z5/Y5/Z6*10000 -> 99.953635 | AA7: =AA5/Z5/AA6*10000 -> 99.992503 | AB7: =AB5/AA5/AB6*10000 -> 100.04592 | AC7: =AC5/AB5/AC6*10000 -> 99.970325 | AD7: =AD5/AC5/AD6*10000 -> 99.993953 | ... AF7: =AF5/AE5/AF6*10000 -> 100.99156 | AG7: 100.9 | AH7: 102 | AI7: 100.2 | AJ7: 101 | AK7: 100.5 | AL7: 100.5 | AM7: 100.3 | AN7: 100.3 | AO7: 100.2 | AP7: 102.8
B8: ЖИВОТНОВОДСТВО | C8: млн. Сомони | L8: 2134.1 | M8: 2208.8 | N8: 2356.8 | O8: 2429.8 | P8: 2573.2 | Q8: 2773.9 | R8: 3958.6 | S8: 3958.6 | T8: 3958.6 | U8: 3958.6 | V8: 6954.1 | W8: 7841.0717 | X8: 7598.2 | Y8: 13976.2 | Z8: 14765.8 | AA8: 16315.8 | AB8: 17691.1 | AC8: 19222.9 | AD8: 21931.1 | AE8: 22991.7 | AF8: 28065.8 | AG8: =AF8*AG9*AG10/10000-AG125 -> 33724.207 | AH8: =AG8*AH9*AH10/10000-AH125 -> 37549.307 | AI8: =AH8*AI9*AI10/10000-AI125 -> 41934.825 | AJ8: =AI8*AJ9*AJ10/10000-AJ125 -> 46401.587 | AK8: =AJ8*AK9*AK10/10000-AK125 -> 51624.557 | AL8: =AK8*AL9*AL10/10000-AL125 -> 57411.246 | AM8: =AL8*AM9*AM10/10000-AM125 -> 63518.787 | AN8: =AM8*AN9*AN10/10000-AN125 -> 70880.981 | ... AP8: =AO8*AP9*AP10/10000-AP125 -> 89127.317
B9: темп роста | C9: % | L9: 110.1 | M9: 103.5 | N9: 106.7 | O9: 106.7 | P9: 105.9 | Q9: 107.7 | R9: 107 | S9: 109.7 | T9: 107.5 | U9: 112.5 | V9: 107.2 | W9: 105.5 | X9: 105.6 | Y9: 105.3 | Z9: 105.7 | AA9: 110.5 | AB9: 108.4 | AC9: 108.7 | AD9: 114.1 | AE9: 104.8 | AF9: 108.5 | AG9: 107.4085 | AH9: 106.622 | AI9: 104.4435 | AJ9: 103.5132 | AK9: 105.0056 | AL9: 105.4467 | AM9: 105.897 | AN9: 107 | AO9: 107 | AP9: 108
B10: дефлятор | C10: % | M10: 100.00029 | N10: 100.00044 | O10: 96.623637 | P10: 100.00162 | Q10: 100.0925 | R10: 133.37273 | S10: 91.157703 | T10: 93.023256 | U10: 88.888889 | V10: 163.87191 | W10: =W8/V8/W9*10000 -> 106.87645 | X10: =X8/W8/X9*10000 -> 91.763797 | Y10: =Y8/X8/Y9*10000 -> 174.68275 | Z10: =Z8/Y8/Z9*10000 -> 99.952322 | AA10: =AA8/Z8/AA9*10000 -> 99.997493 | AB10: =AB8/AA8/AB9*10000 -> 100.02699 | AC10: =AC8/AB8/AC9*10000 -> 99.961905 | AD10: =AD8/AC8/AD9*10000 -> 99.989838 | ... AF10: =AF8/AE8/AF9*10000 -> 112.50624 | AG10: 112.5 | AH10: 105 | AI10: 107.5 | AJ10: 107.46 | AK10: 106.5 | AL10: 106 | AM10: 105 | AN10: 104.8 | AO10: =AN10 -> 104.8 | AP10: =AO10 -> 104.8
W11: =W2-V2 -> 1329.8717 | X11: =X2-W2 -> 1668.3283 | Y11: =Y2-X2 -> 21069.8 | Z11: =Z2-Y2 -> 3244 | AA11: =AA2-Z2 -> 4345.4 | AB11: =AB2-AA2 -> 3571.5 | AC11: =AC2-AB2 -> 4531.2 | AD11: =AD2-AC2 -> 5569.3 | ... AP11: =AP2-AO2 -> 14413.161
V12: =V5-U5 -> 90.9 | W12: =W5-V5 -> 442.9 | X12: =X5-W5 -> 1911.2 | Y12: =Y5-X5 -> 14691.8 | Z12: =Z5-Y5 -> 2454.4 | AA12: =AA5-Z5 -> 2795.4 | AB12: =AB5-AA5 -> 2196.2 | AC12: =AC5-AB5 -> 2999.4 | ... AP12: =AP5-AO5 -> 4360.3453
AB13: =AB8-AA8 -> 1375.3 | AC13: =AC8-AB8 -> 1531.8 | AD13: =AD8-AC8 -> 2708.2 | AE13: =AE8-AD8 -> 1060.6 | AF13: =AF8-AE8 -> 5074.1 | AG13: =AG8-AF8 -> 5658.4066 | AH13: =AH8-AG8 -> 3825.0999 | AI13: =AI8-AH8 -> 4385.518 | ... AP13: =AP8-AO8 -> 10020.806
B14: Общая земельная площадь | C14: га | L14: 14255397 | M14: 14255397 | N14: 14255397 | O14: 14255397 | P14: 14255397 | Q14: 14255397 | R14: 14255397 | S14: 14255397 | T14: 14255397 | U14: 14137685 | V14: 14137685 | W14: 14137685 | X14: 14137685 | Y14: 14137900 | Z14: =Y14 -> 14137900 | AA14: 14137907 | AB14: 14137907 | AC14: =AB14 -> 14137907 | AD14: =AC14 -> 14137907 | AE14: =AD14 -> 14137907 | AF14: =AE14 -> 14137907 | AG14: =AF14 -> 14137907 | AH14: =AG14 -> 14137907 | AI14: =AH14 -> 14137907 | AJ14: =AI14 -> 14137907 | ... AP14: =AO14 -> 14137907
B15: площадь орошаемых земель (оби) | C15: га | L15: 737694 | M15: 741539 | N15: 742051 | O15: 741626 | P15: 743621 | Q15: 743856 | R15: 748256 | S15: 749000 | T15: 749995 | U15: 753000 | V15: 753000 | W15: 753000 | X15: 598522 | Y15: 602593 | Z15: 604142 | AA15: 604537 | AB15: 605065 | AC15: 604289 | AD15: 606920 | AE15: 608046 | AF15: =AE15 -> 608046 | AG15: =AF15 -> 608046 | AH15: =AG15 -> 608046 | AI15: =AH15 -> 608046 | AJ15: =AI15 -> 608046 | AK15: =AJ15 -> 608046 | AL15: =AK15 -> 608046 | AM15: =AL15 -> 608046 | ... AP15: =AO15 -> 608046
