Workbook

Sheet GDP
B1: Var. Name | C1: Наименование индикатора | D1: 1997 | E1: 1998 | F1: 1999 | G1: 2000 | H1: 2001 | I1: 2002 | J1: 2003 | K1: 2004 | L1: 2005 | M1: 2006 | N1: 2007 | O1: 2008 | P1: 2009 | Q1: 2010 | R1: 2011 | S1: 2012 | T1: 2013 | U1: 2014 | V1: 2015 | W1: 2016 | X1: 2017 | Y1: 2018 | Z1: 2019 | AA1: 2020 | AB1: 2021 | AC1: 2022 | AD1: 2023 | AE1: 2024
B2: GDPmp,t | C2: ВВП в рыночных ценах, млн. сомони | D2: 518.4 | E2: 1025.2 | F2: 1345 | G2: 1786.8 | H2: 2563.8 | I2: 3375.3 | J2: 4761.5 | K2: 6167.2 | L2: 7206.6 | M2: 9335.3 | N2: 12804.3 | O2: 17706.9 | P2: 20629 | Q2: 24707.1 | R2: 30071.1 | S2: 36163.1 | T2: 40525.2 | U2: 45606.6 | V2: =V13 -> 50977.4 | W2: =W13 -> 54790.3 | X2: =X13 -> 64434.3 | Y2: =Y13 -> 71059.2 | Z2: =Z13 -> 79109.8 | AA2: =AA13 -> 83958.3 | AB2: =AB13 -> 101076.3 | AC2: =AC13 -> 118181.7 | ... AE2: =AE13 -> 153402.2 | AG2: GDPmp,t = GDPmp,t
B3: gGDPt | C3: Реальный рост ВВП, % | D3: 101.7 | E3: 105.3 | F3: 103.7 | G3: 108.3 | H3: 109.6 | I3: 110.8 | J3: 111.1 | K3: 110.3 | L3: 106.7 | M3: 107 | N3: 107.8 | O3: 107.9 | P3: 103.9 | Q3: 106.5 | R3: 107.4 | S3: 107.5 | T3: 107.4 | U3: 106.7 | V3: =V30 -> 106 | W3: =W30 -> 106.9 | X3: =X30 -> 107.1 | Y3: =Y30 -> 107.56589 | Z3: =Z30 -> 107.42266 | AA3: =AA30 -> 104.44609 | AB3: =AB30 -> 109.41561 | AC3: =AC30 -> 108.03592 | ... AE3: =AE30 -> 108.35354 | AG3: gGDPt = gGDPmp,t
B4: defGDPt | C4: Дефлятор ВВП, % | D4: 165.2 | E4: 187.8 | F4: 123.5 | G4: 124.3 | H4: 130.9 | I4: 118.8 | J4: 127.1 | K4: 117.5 | L4: 109.5161 | M4: 121.06374 | N4: 127.23565 | O4: 128.16376 | P4: 112.12955 | Q4: 112.44802 | R4: 113.32436 | S4: 111.86852 | T4: 104.34106 | U4: 105.47223 | V4: =V64 -> 105.4494 | W4: =W64 -> 100.54218 | X4: =X64 -> 109.80547 | Y4: =Y64 -> 102.52473 | Z4: =Z64 -> 103.63682 | AA4: =AA64 -> 101.6111 | AB4: =AB64 -> 110.02881 | AC4: =AC64 -> 108.22628 | ... AE4: =AE64 -> 106.62268 | AG4: defGDPt = defGDPmp,t
B5: GDP2009mp,t | C5: ВВП в рыночных ценах 2009 года | D5: 8495.6919 | E5: 8945.9636 | F5: 9276.9643 | G5: 10046.952 | H5: 11011.46 | I5: 12200.697 | J5: 13554.975 | K5: 14951.137 | L5: 15952.863 | M5: 17069.564 | N5: 18400.99 | O5: 19854.668 | P5: 20629 | Q5: 21969.885 | R5: 23595.656 | S5: 25365.331 | T5: 27242.365 | U5: 29067.604 | V5: =V47 -> 30811.66 | W5: =W47 -> 32937.664 | X5: =X47 -> 35276.239 | Y5: =Y47 -> 37945.199 | Z5: =Z47 -> 40761.741 | AA5: =AA47 -> 42574.045 | AB5: =AB47 -> 46582.649 | AC5: =AC47 -> 50325.994 | ... AE5: =AE47 -> 59066.766 | AG5: GDP2009mp,t = GDP2009mp,t
B6: GDPPCUS,t | C6: ВВП на душу населения, долл. США | D6: 158.7 | E6: 221.8 | F6: 178.2 | G6: 158 | H6: 171.2 | I6: 190 | J6: 236.7 | K6: 309.7 | L6: 337.5 | M6: 410 | N6: 529 | O6: 719.8 | P6: 678.8 | Q6: 750.4 | R6: 845.64821 | S6: 961.47143 | T6: 1053.5032 | U6: 1119.3135 | V6: =V7/Assumptions!V12 -> 978.4573 | W6: =W7/Assumptions!W12 -> 808.65537 | X6: =X7/Assumptions!X12 -> 852.82525 | Y6: =Y7/Assumptions!Y12 -> 860.01836 | Z6: =Z7/Assumptions!Z12 -> 900.31584 | AA6: =AA7/Assumptions!AA12 -> 864.39922 | AB6: =AB7/Assumptions!AB12 -> 911.84819 | AC6: =AC7/Assumptions!AC12 -> 1073.7361 | ... AE6: =AE7/Assumptions!AE12 -> 1368.3056 | AG6: GDPPCUS,t = GDPmp,t/erUSDt/POPt
C7: ВВП на душу населения, в сомони | D7: 89.2 | E7: 172.9 | F7: 222.1 | G7: 288.4 | H7: 405.8 | I7: 525 | J7: 727.7 | K7: 926.2 | L7: 1062.8 | M7: 1352.2 | N7: 1821.1 | O7: 2468.3 | P7: 2812.7 | Q7: 3285.8 | R7: 3898.1 | S7: 4579.2 | T7: 5019.1 | U7: 5523.7 | V7: 6031.7 | W7: 6336.3 | X7: 7291.4 | Y7: 7870.2 | Z7: 8580.1 | AA7: 8922.2423 | AB7: 10312 | AC7: 11838.8 | AD7: =AD2/Assumptions!AD63 -> 13039.566 | AE7: =AE2/Assumptions!AE63 -> 14775.785
B8: =[1]Monetary!B15 -> ИПЦ, в том числе: (дек/дек), факт | C8: =[1]Monetary!C15 -> Inflation (dec/dec), fact, incl. | G8: 160.62781 | H8: 112.47905 | I8: 114.50567 | J8: 113.65265 | K8: 105.62006 | L8: 106.89379 | M8: 111.9 | N8: 121.5 | O8: 120.4 | P8: 106.4 | Q8: 106.5 | R8: 112.5 | S8: 105.8 | T8: 103.7 | U8: 107.4 | V8: =Monetary!V15 -> 105.1 | W8: =Monetary!W15 -> 106.1 | X8: =Monetary!X15 -> 106.7411 | Y8: =Monetary!Y15 -> 105.37889 | Z8: =Monetary!Z15 -> 108 | AA8: =Monetary!AA15 -> 109.4 | AB8: =Monetary!AB15 -> 108 | AC8: =Monetary!AC15 -> 104.2 | ... AE8: =Monetary!AE15 -> 103.6
C10: Среднегодовая численность населения , тысяч человек | D10: 5814.4 | E10: 5930.5 | F10: 6056 | G10: 6196.5 | H10: 6317.9 | I10: 6429.2 | J10: 6543 | K10: 6658.9 | L10: 6780.6 | M10: 6903.9 | N10: 7031.2 | O10: 7173.8 | P10: 7334.1 | Q10: 7519.3 | R10: 7714.2 | S10: 7897.3 | T10: 8074.3 | U10: 8256.6 | V10: 8451.6 | W10: 8647 | X10: 8837 | Y10: 9028.9 | Z10: 9220.2 | AA10: 9410 | AB10: 9801.812 | AC10: 9982.6 | AD10: 10183.3 | AE10: 10382.1
C13: ВВП в рыночных ценах, млн. сомони | D13: 518.4 | E13: 1025.2 | F13: 1345 | G13: 1786.8 | H13: 2563.8 | I13: 3375.3 | J13: 4761.5 | K13: 6167.2 | L13: 7206.6 | M13: 9335.3 | N13: 12804.3 | O13: 17706.9 | P13: 20629 | Q13: 24707.1 | R13: 30071.1 | S13: 36163.1 | T13: 40525.2 | U13: 45606.6 | V13: =V14+V15 -> 50977.4 | W13: =W14+W15 -> 54790.3 | X13: =X14+X15 -> 64434.3 | Y13: =Y14+Y15 -> 71059.2 | Z13: =Z14+Z15 -> 79109.8 | AA13: =AA14+AA15 -> 83958.3 | AB13: =AB14+AB15 -> 101076.3 | AC13: =AC14+AC15 -> 118181.7 | ... AE13: =AE14+AE15 -> 153402.2 | AG13: GDPmp,t = NITt+GDPfc,t
C14: Чистые косвенные налоги | D14: 49.8 | E14: 77.8 | F14: 98 | G14: 149.7 | H14: 230.3 | I14: 332.8 | J14: 508.4 | K14: 679.7 | L14: 831.2 | M14: 1059.7 | N14: 1603.5 | O14: 2235.9 | P14: 2286.6 | Q14: 2781.7 | R14: 3727.5 | S14: 4455.8 | T14: 5159.5 | U14: 6361.6 | V14: =5453.6-83.4 -> 5370.2 | W14: =5755.1-95 -> 5660.1 | X14: =6467.9-130.8 -> 6337.1 | Y14: =7131.5-112.4 -> 7019.1 | Z14: =7827.1-134.4 -> 7692.7 | AA14: =7718-175.3 -> 7542.7 | AB14: =9880.8-184.3 -> 9696.5 | AC14: 10687.4 | AD14: =13443.4-246.2 -> 13197.2 | AE14: 14425.9 | AG14: NITt = NITt
C15: ВВП в основных ценах | D15: 468.6 | E15: 947.4 | F15: 1247 | G15: 1637.1 | H15: 2333.5 | I15: 3042.5 | J15: 4253.1 | K15: 5487.5 | L15: 6375.4 | M15: 8275.6 | N15: 11200.8 | O15: 15471 | P15: 18342 | Q15: 21925.4 | R15: 26343.6 | S15: 31707.3 | T15: 35365.7 | U15: 39245 | V15: =SUM(V16:V22) -> 45607.2 | W15: =SUM(W16:W22) -> 49130.2 | X15: =SUM(X16:X22) -> 58097.2 | Y15: =SUM(Y16:Y22) -> 64040.1 | Z15: =SUM(Z16:Z22) -> 71417.1 | AA15: =SUM(AA16:AA22) -> 76415.6 | AB15: =SUM(AB16:AB22) -> 91379.8 | AC15: =SUM(AC16:AC22) -> 107494.3 | ... AE15: =SUM(AE16:AE22) -> 138976.3 | AG15: GDPfc,t = (VAAB,t+VACDE,t+VAF,t+VAGoodsO,t+VAGH,t+VAI,t+VAOther,t)
C16: Сельское хозяйство и рыболовство | D16: 165.9 | E16: 257.4 | F16: 341.4 | G16: 448.9 | H16: 610.4 | I16: 750.5 | J16: 1151.9 | K16: 1185.6 | L16: 1527.2 | M16: 2002.6 | N16: 2488.3 | O16: 3517.9 | P16: 3827 | Q16: 4839.3 | R16: 7167.6 | S16: 8435.7 | T16: 8279.6 | U16: 10692.6 | V16: 11006.4 | W16: =11399.2+28.4 -> 11427.6 | X16: =13069.4 -> 13069.4 | Y16: 14049.8 | Z16: 16507.9 | AA16: 19050.5 | AB16: 22690.7 | AC16: 27104.8 | AD16: 30352.5 | AE16: 34954.8 | AG16: VAAB,t = VAAB,t-1·gVAAB,t·defVAAB,t/10000
C17: Промышленность | D17: 114 | E17: 206.1 | F17: 291.6 | G17: 592.3 | H17: 858 | I17: 1117.2 | J17: 1440.2 | K17: 1644.4 | L17: 1645.1 | M17: 1987 | N17: 2349.4 | O17: 2515.8 | P17: 2957.4 | Q17: 3642.7 | R17: 4368.9 | S17: 4947.8 | T17: 5103.1 | U17: 5510.9 | V17: =811.2+5471.4+1443.7 -> 7726.3 | W17: =1550+6233.9+1483 -> 9266.9 | X17: =2463.1+8251+2074.6+51.2 -> 12839.9 | Y17: =2528.5+9400.4+3025.7+76.9 -> 15031.5 | Z17: =2642.3+10626.3+3505.5+99.7 -> 16873.8 | AA17: =2410.7+13119.2+3890.1+91.3 -> 19511.3 | AB17: =4669.7+15160.3+4189.5+119.5 -> 24139 | AC17: =5027.2+17893.5+4728.3+113 -> 27762 | AD17: =5407.1+19402.9+4817.5+115.2 -> 29742.7 | AE17: 25921 | AG17: VACDE,t = VACDE,t
C18: Строительство | D18: 14.3 | E18: 39.5 | F18: 73 | G18: 38 | H18: 69.7 | I18: 68.9 | J18: 136.6 | K18: 262.3 | L18: 327.1 | M18: 567.5 | N18: 1034.6 | O18: 1832.6 | P18: 2098.4 | Q18: 2528.2 | R18: 2387.5 | S18: 3023.5 | T18: 4200.8 | U18: 4660 | V18: 7679.3 | W18: 8382.9 | X18: 7680.4 | Y18: 9411.7 | Z18: 9281.6 | AA18: 8863.7 | AB18: 11417.3 | AC18: 13250.1 | AD18: 14923.6 | AE18: 12451.7 | AG18: VAF,t = 0,58·InvNAF,t
C19: Прочие товары | D19: 6 | E19: 10.2 | F19: 4.8 | G19: 5.9 | H19: 7.5 | I19: 13.4 | J19: 14.5 | K19: 24.2 | L19: 20.9 | M19: 20.8 | N19: 29.1 | O19: 34.9 | P19: 29.5 | Q19: 13.8 | AG19: VAGoodsO,t = VAGoodsO,t-1·VACDE,t/VACDE,t-1
C20: Розничная и оптовая торговля | D20: 108.6 | E20: 231.8 | F20: 270 | G20: 193.9 | H20: 274.9 | I20: 394.7 | J20: 544.1 | K20: 1017.5 | L20: 1191.6 | M20: 1593.8 | N20: 2119.7 | O20: 3577.3 | P20: 4345.8 | Q20: 4999.9 | R20: 3949.2 | S20: 5032.7 | T20: 5823.3 | U20: 6419.6 | V20: =4102.8+1331.1 -> 5433.9 | W20: =4625.3+1485.7 -> 6111 | X20: =6353.5 -> 6353.5 | Y20: =7359.6+1699.1 -> 9058.7 | Z20: =8764.1+1938.6 -> 10702.7 | AA20: =8978.4+1744.5 -> 10722.9 | AB20: =10956+2405.8 -> 13361.8 | AC20: =13042+3060.8 -> 16102.8 | AD20: =13851.7+3687.1 -> 17538.8 | AE20: 23332.7 | AG20: VAGH,t = RETt·0,447-750
C21: Транспорт и связь | D21: 15.1 | E21: 42.7 | F21: 99 | G21: 85 | H21: 127.6 | I21: 185.7 | J21: 260.2 | K21: 409 | L21: 533.3 | M21: 673.1 | N21: 1221.9 | O21: 1782.2 | P21: 2264.9 | Q21: 2758 | R21: 4356.3 | S21: 5535.2 | T21: 6172.2 | U21: 6523.8 | V21: 4859.2 | W21: 4875.2 | X21: 4870 | Y21: 4277.6 | Z21: 4829.2 | AA21: 3818.8 | AB21: =3735+1473.6 -> 5208.6 | AC21: =4401.1+1622.4 -> 6023.5 | AD21: =5272.4+1967.1 -> 7239.5 | AE21: 14321.1 | AG21: VAI,t = VAI,t-1+(RETt+SERt-RETt-1-SERt-1)·0,24
C22: Прочие услуги (остатком) | D22: 44.7 | E22: 159.7 | F22: 167.2 | G22: 273.2 | H22: 385.6 | I22: 512.2 | J22: 706.1 | K22: 945 | L22: 1130.7 | M22: 1431.2 | N22: 1958.1 | O22: 2214.2 | P22: 2823.8 | Q22: 3143.4 | R22: 4114.1 | S22: 4732.4 | T22: 5786.7 | U22: 5438.1 | V22: =2197.5+694+1492.8+2522.7+1152.2+1619.3-776.4 -> 8902.1 | W22: =1091.7+765.3+1708.6+2871.3+1292.1+1644.1-306.5 -> 9066.6 | X22: =1697.8+1533.8+1994.4+740.6+237.2+57.7+1874.8+3022.7+1359.1+296.7+736.4+275-542.2 -> 13284 | Y22: =1366.8+2078.9+791.4+237.7+60.1+2005.6+3256.3+1440.9+328.2+923.2+286-564.3 -> 12210.8 | Z22: =1424.1+1925.1+852.7+288.9+81.5+2139.9+3752.6+1651.2+366+972.3+347.6-580 -> 13221.9 | AA22: =1492.9+2157.1+1103.3+269.5+97.4+2247.4+4086.8+1842.9+408+888+462.1-607 -> 14448.4 | AB22: =2055.7+1228.9+568.4+207.9+2411.3+4778.7+2072.3+525.4+844.2+471.6-602 -> 14562.4 | AC22: =4066.6+1323+474.1+242.5+2620.7+5058.3+2146.1+571.5+1142.2+541.1-935 -> 17251.1 | AD22: =4831.1+1339.3+464.6+320.1+3473.8+6075.3+2451.3+559.2+1173.7+619.5-1520.3 -> 19787.6 | AE22: 27995 | AG22: VAOther,t = VAOther,t-1·(SERt/SERt-1)
C23: Справочно:
C24: Товары | D24: 300.2 | E24: 513.2 | F24: 710.8 | G24: 1085.1 | H24: 1545.6 | I24: 1950 | J24: 2743.2 | K24: 3116.5 | L24: 3520.3 | M24: 4577.9 | N24: 5901.4 | O24: 7901.2 | P24: 8912.3 | Q24: 11024 | R24: 13924 | S24: 16407 | T24: 17583.5 | U24: 20863.5 | V24: =V16+V17+V18+V19 -> 26412 | W24: =W16+W17+W18+W19 -> 29077.4 | X24: =X16+X17+X18+X19 -> 33589.7 | Y24: =Y16+Y17+Y18+Y19 -> 38493 | Z24: =Z16+Z17+Z18+Z19 -> 42663.3 | AA24: =AA16+AA17+AA18+AA19 -> 47425.5 | AB24: =AB16+AB17+AB18+AB19 -> 58247 | AC24: =AC16+AC17+AC18+AC19 -> 68116.9 | ... AE24: =AE16+AE17+AE18+AE19 -> 73327.5 | AG24: VAGoods,t = VAAB,t+VACDE,t+VAF,t+VAGoodsO,t
C25: Услуги | D25: 168.4 | E25: 434.2 | F25: 536.2 | G25: 552 | H25: 787.9 | I25: 1092.5 | J25: 1509.9 | K25: 2371 | L25: 2855.1 | M25: 3697.7 | N25: 5299.4 | O25: 7744.3 | P25: 9429.7 | Q25: 10901.3 | R25: 12419.6 | S25: 15300.3 | T25: 17782.2 | U25: 18381.5 | V25: =V20+V21+V22 -> 19195.2 | W25: =W20+W21+W22 -> 20052.8 | X25: =X20+X21+X22 -> 24507.5 | Y25: =Y20+Y21+Y22 -> 25547.1 | Z25: =Z15-Z24 -> 28753.8 | AA25: =AA15-AA24 -> 28990.1 | AB25: =AB15-AB24 -> 33132.8 | AC25: =AC15-AC24 -> 39377.4 | AD25: =AD15-AD24 -> 44565.9 | AE25: =AE15-AE24 -> 65648.8 | AG25: VAServces,t = GDPfc,t-VAGoods,t
V27: 5370.8 | W27: =W13-V13 -> 3812.9 | X27: =X13-W13 -> 9644 | Y27: =Y13-X13 -> 6624.9 | Z27: =Z13-Y13 -> 8050.6 | AA27: =AA13-Z13 -> 4848.5 | AB27: =AB13-AA13 -> 17118 | AC27: =AC13-AB13 -> 17105.4 | AD27: =AD13-AC13 -> 14600.2 | AE27: =AE13-AD13 -> 20620.3
C30: ВВП в рыночных ценах, % | D30: 101.7 | E30: 105.3 | F30: 103.7 | G30: 108.3 | H30: 109.6 | I30: 110.8 | J30: 111.1 | K30: 110.3 | L30: 106.7 | M30: 107 | N30: 107.8 | O30: 107.9 | P30: 103.9 | Q30: 106.5 | R30: 107.4 | S30: 107.5 | T30: 107.4 | U30: 106.7 | V30: 106 | W30: =(V14*W31+W32*V15)/(V14+V15) -> 106.9 | X30: =(W14*X31+X32*W15)/(W14+W15) -> 107.1 | Y30: =(X14*Y31+Y32*X15)/(X14+X15) -> 107.56589 | Z30: =(Y14*Z31+Z32*Y15)/(Y14+Y15) -> 107.42266 | AA30: =(Z14*AA31+AA32*Z15)/(Z14+Z15) -> 104.44609 | AB30: =(AA14*AB31+AB32*AA15)/(AA14+AA15) -> 109.41561 | AC30: =(AB14*AC31+AC32*AB15)/(AB14+AB15) -> 108.03592 | AD30: =(AC14*AD31+AD32*AC15)/(AC14+AC15) -> 108.31977 | AE30: =(AD14*AE31+AE32*AD15)/(AD14+AD15) -> 108.35354 | AG30: gGDPmp,t = (NITt-1·gNITt+gGDPfc,t·GDPfc,t-1)/(NITt-1+GDPfc,t-1)
C31: Чистые косвенные налоги | H31: 110 | I31: 111.8 | J31: 111.9 | K31: 111 | L31: 107.3 | M31: 107.4 | N31: 108.3 | O31: 107.9 | P31: 102 | Q31: 106.5 | R31: 107.4 | S31: 107.5 | T31: 107.4 | U31: 106.7 | V31: 106 | W31: 106.9 | X31: 107.1 | Y31: 104.8 | Z31: 103 | AA31: 100 | AB31: 100 | AC31: 100 | AD31: 100 | AE31: =(AE32/100)^1*100 -> 108.35354 | AG31: gNITt = (gGDPfc,t/100)^1,00·100
C32: ВВП в основных ценах | H32: 109.60139 | I32: 110.72988 | J32: 111.0332 | K32: 110.16366 | L32: 106.66415 | M32: 106.90176 | N32: 107.66178 | O32: 107.89471 | P32: 103.9 | Q32: 106.5 | R32: 107.4 | S32: 107.5 | T32: 107.4 | U32: 106.7 | V32: 106 | W32: 106.9 | X32: 107.1 | Y32: =SUMPRODUCT(Y33:Y39,X16:X22)/SUM(X16:X22) -> 107.86758 | Z32: =SUMPRODUCT(Z33:Z39,Y16:Y22)/SUM(Y16:Y22) -> 107.9074 | AA32: =SUMPRODUCT(AA33:AA39,Z16:Z22)/SUM(Z16:Z22) -> 104.925 | AB32: =SUMPRODUCT(AB33:AB39,AA16:AA22)/SUM(AA16:AA22) -> 110.34499 | AC32: =SUMPRODUCT(AC33:AC39,AB16:AB22)/SUM(AB16:AB22) -> 108.88863 | AD32: =SUMPRODUCT(AD33:AD39,AC16:AC22)/SUM(AC16:AC22) -> 109.14694 | AE32: =SUMPRODUCT(AE33:AE39,AD16:AD22)/SUM(AD16:AD22) -> 108.35354 | AG32: gGDPfc,t = (gVAAB,t·VAAB,t-1+gVACDE,t·VACDE,t-1+gVAF,t·VAF,t-1+gVAGoodsO,t·VAGoodsO,t-1+gVAGH,t·VAGH,t-1+gVAI,t·VAI,t-1+gVAOther,t·VAOther,t-1)/(VAAB,t-1+VACDE,t-1+VAF,t-1+VAGoodsO,t-1+VAGH,t-1+VAI,t-1+VAOther,t-1)
C33: Сельское хозяйство и рыболовство | L33: 101.4 | M33: 105.7 | N33: 103.5 | O33: 106.1 | P33: 110.5 | Q33: 106.8 | R33: 107.9 | S33: 110.4 | T33: 107.6 | U33: 104.5 | V33: =Agriculture!V3 -> 103.2 | W33: =Agriculture!W3 -> 105.2 | X33: =Agriculture!X3 -> 106.8 | Y33: =Agriculture!Y3 -> 107 | Z33: =Agriculture!Z3 -> 107 | AA33: =Agriculture!AA3 -> 107.9 | AB33: =Agriculture!AB3 -> 99.7 | AC33: =Agriculture!AC3 -> 108 | AD33: 112.2 | AE33: =Agriculture!AE3 -> 110.6 | AG33: gVAAB,t = (1+gVAAB,t/100)·100
C34: Промышленность | L34: 106.4 | M34: 105.5 | N34: 109.9 | O34: 96.5 | P34: 93.5 | Q34: 109.2 | R34: 105.7 | S34: 110.8 | T34: 103.8 | U34: 105 | V34: =Industry!V58 -> 111.3 | W34: =Industry!W58 -> 116 | X34: =Industry!X58 -> 121.3 | Y34: =Industry!Y58 -> 110.6 | Z34: =Industry!Z58 -> 113.2 | AA34: =Industry!AA58 -> 108.8 | AB34: =Industry!AB58 -> 120.8 | AC34: =Industry!AC58 -> 115.4 | AD34: 109.7 | AE34: =Industry!AE58 -> 120 | AG34: gVACDE,t = gVACDE,t
C35: Строительство | L35: 116.4 | M35: 107.2 | N35: 110.4 | O35: 121.2 | P35: 84.5 | Q35: 109.52934 | R35: 105.5 | S35: 75.6 | T35: 117.2 | U35: 125.3 | V35: =OEA!V39 -> 121.2 | W35: =OEA!W39 -> 120.3 | X35: =OEA!X39 -> 104.1 | Y35: =OEA!Y39 -> 110.2 | Z35: =OEA!Z39 -> 104.6 | AA35: =OEA!AA39 -> 104 | AB35: 132.1 | AC35: =OEA!AC39 -> 111.4 | AD35: =OEA!AD39 -> 112.3 | AE35: =OEA!AE39 -> 79.690833 | AG35: gVAF,t = gCONSTRt
C36: Прочие товары | L36: 100 | M36: 100 | N36: 110.2 | O36: 100 | P36: 100 | Q36: 109.2 | R36: 105.7 | S36: 110.8 | T36: 103.8 | U36: 105 | V36: =V34 -> 111.3 | W36: =W34 -> 116 | X36: =X34 -> 121.3 | Y36: =Y34 -> 110.6 | Z36: =Z34 -> 113.2 | AA36: =AA34 -> 108.8 | AB36: =AB34 -> 120.8 | AC36: =AC34 -> 115.4 | ... AE36: =AE34 -> 120 | AG36: gVAGoodsO,t = gVACDE,t
C37: Розничная и оптовая торговля | L37: 108.9 | M37: 110.8 | N37: 105.3 | O37: 112.4 | P37: 112.5 | Q37: 107.5 | R37: 109.1 | S37: 115.9 | T37: 118.8 | U37: 106.7 | V37: 105.6 | W37: 106 | X37: 106.6 | Y37: 112.2 | Z37: 109.6 | AA37: 94.1 | AB37: 110.2 | AC37: =Household!AC4 -> 111.2 | AD37: 98.6 | AE37: =Household!AE4 -> 113.6 | AG37: gVAGH,t = VAGH,t/VAGH,t-1/defVAGH,t·10000
C38: Транспорт и связь | L38: 130 | M38: 118.1 | N38: 183.8 | O38: 143.3 | P38: 153.5 | Q38: 119.39626 | R38: 150.89372 | S38: 124.05492 | T38: 110.30013 | U38: 105.11255 | V38: 102.1 | W38: =(W21/V21)^0.4*100 -> 100.13158 | X38: =(X21/W21)^3*100 -> 99.680354 | Y38: 93.3 | Z38: 115.7 | AA38: 79.4 | AB38: 95.3 | AC38: 96 | AD38: 121.7 | AE38: =(AE21/AD21)^0.82*100 -> 174.96033 | AG38: gVAI,t = (VAI,t/VAI,t-1)^0,9·100
C39: Прочие услуги (остатком) | L39: 97.001641 | M39: 96.376863 | N39: 78.00434 | O39: 92.627551 | P39: 73.250437 | Q39: 93 | R39: 97 | S39: 95 | T39: 95 | U39: 102 | V39: 97 | W39: 97 | X39: 101 | Y39: 108 | Z39: 101 | AA39: 115 | AB39: 101 | AC39: 100 | AD39: 106.5 | AE39: 80 | AG39: gVAOther,t = gVAOther,t
C40: Справочно:
C41: Товары | H41: 112.4 | I41: 111 | J41: 111.5 | K41: 105.3 | L41: 105.8 | M41: 105.2 | N41: 104.4 | O41: 103.4 | P41: 99 | Q41: 106.1 | R41: 106.9 | S41: 103.6 | T41: 105.9 | U41: 112.2 | V41: 109.7 | W41: 114.1 | X41: 107.4 | Y41: =SUMPRODUCT(Y33:Y36,X16:X19)/SUM(X16:X19) -> 109.10782 | Z41: =SUMPRODUCT(Z33:Z36,Y16:Y19)/SUM(Y16:Y19) -> 108.83429 | AA41: =SUMPRODUCT(AA33:AA36,Z16:Z19)/SUM(Z16:Z19) -> 107.4075 | AB41: =SUMPRODUCT(AB33:AB36,AA16:AA19)/SUM(AA16:AA19) -> 114.43621 | AC41: =SUMPRODUCT(AC33:AC36,AB16:AB19)/SUM(AB16:AB19) -> 111.7332 | AD41: =SUMPRODUCT(AD33:AD36,AC16:AC19)/SUM(AC16:AC19) -> 111.20054 | AE41: =SUMPRODUCT(AE33:AE36,AD16:AD19)/SUM(AD16:AD19) -> 108.17801 | AG41: gVAGoods,t = (gVAAB,t·VAAB,t-1+gVACDE,t·VACDE,t-1+gVAF,t·VAF,t-1+gVAGoodsO,t·VAGoodsO,t-1)/(VAAB,t-1+VACDE,t-1+VAF,t-1+VAGoodsO,t-1)
C42: Услуги | H42: 104.1 | I42: 110.2 | J42: 110.2 | K42: 119 | L42: 107.8 | M42: 109 | N42: 111.7 | O42: 112.9 | P42: 109.7 | Q42: 106.9 | R42: 107.7 | S42: 112 | T42: 109.1 | U42: 101.2 | V42: 101.7 | W42: 98.9 | X42: 106.6 | Y42: =(Y37*X20+X21*Y38+Y39*X22)/X25 -> 106.16773 | Z42: =(Z37*Y20+Y21*Z38+Z39*Y22)/Y25 -> 106.51082 | AA42: =(AA37*Z20+Z21*AA38+AA39*Z22)/Z25 -> 101.24161 | AB42: =(AB37*AA20+AA21*AB38+AB39*AA22)/AA25 -> 103.65206 | AC42: =(AC37*AB20+AB21*AC38+AC39*AB22)/AB25 -> 103.88792 | AD42: =(AD37*AC20+AC21*AD38+AD39*AC22)/AC25 -> 105.59453 | AE42: =(AE37*AD20+AD21*AE38+AE39*AD22)/AD25 -> 108.64901 | AG42: gVAServces,t = (gVAGH,t·VAGH,t-1+VAI,t-1·gVAI,t+gVAOther,t·VAOther,t-1)/VAServces,t-1
C46: В постоянных ценах 2009 года, млн. сомони
C47: ВВП в рыночных ценах 2009 года | G47: 10046.952 | H47: 11011.46 | I47: 12200.697 | J47: 13554.975 | K47: 14951.137 | L47: 15952.863 | M47: 17069.564 | N47: 18400.99 | O47: 19854.668 | P47: 20629 | Q47: 21969.885 | R47: 23595.656 | S47: 25365.331 | T47: 27242.365 | U47: 29067.604 | V47: 30811.66 | W47: =V47*W30/100 -> 32937.664 | X47: =W47*X30/100 -> 35276.239 | Y47: =X47*Y30/100 -> 37945.199 | Z47: =Y47*Z30/100 -> 40761.741 | AA47: =Z47*AA30/100 -> 42574.045 | AB47: =AA47*AB30/100 -> 46582.649 | AC47: =AB47*AC30/100 -> 50325.994 | AD47: =AC47*AD30/100 -> 54513 | AE47: =AD47*AE30/100 -> 59066.766 | AG47: GDP2009mp,t = GDP2009mp,t-1·gGDPmp,t/100
C48: Чистые косвенные налоги | H48: 1198.9946 | I48: 1340.4759 | J48: 1499.9926 | K48: 1664.9918 | L48: 1786.5362 | M48: 1918.7398 | N48: 2077.9952 | O48: 2242.1569 | P48: 2287 | Q48: 2435.655 | R48: 2615.8935 | S48: 2812.0855 | T48: 3020.1798 | U48: 3222.5319 | V48: 3415.8838 | W48: =V48*W31/100 -> 3651.5797 | X48: =W48*X31/100 -> 3910.8419 | Y48: =X48*Y31/100 -> 4098.5623 | Z48: =Y48*Z31/100 -> 4221.5192 | AA48: =Z48*AA31/100 -> 4221.5192 | AB48: =AA48*AB31/100 -> 4221.5192 | AC48: =AB48*AC31/100 -> 4221.5192 | AD48: =AC48*AD31/100 -> 4221.5192 | AE48: =AD48*AE31/100 -> 4574.1655 | AG48: NIT2009t = NIT2009t-1·gNITt/100
C49: ВВП в основных ценах | K49: 13293.54 | L49: 14180.584 | M49: 15155.605 | N49: 16320.036 | O49: 17598.221 | P49: 18342 | Q49: 19534.23 | R49: 20979.763 | S49: 22553.245 | T49: 24222.185 | U49: 25845.072 | V49: 27395.776 | W49: =V49*W32/100 -> 29286.085 | X49: =W49*X32/100 -> 31365.397 | Y49: =X49*Y32/100 -> 33833.095 | Z49: =Y49*Z32/100 -> 36508.414 | AA49: =Z49*AA32/100 -> 38306.454 | AB49: =AA49*AB32/100 -> 42269.251 | AC49: =AB49*AC32/100 -> 46026.408 | AD49: =AC49*AD32/100 -> 50236.418 | AE49: =AD49*AE32/100 -> 54432.938 | AG49: GDP2009fc,t = GDP2009fc,t-1·gGDPfc,t/100
...

Sheet Agriculture
D1: 1997 | E1: 1998 | F1: 1999 | G1: 2000 | H1: 2001 | I1: 2002 | J1: 2003 | K1: 2004 | L1: 2005 | M1: 2006 | N1: 2007 | O1: 2008 | P1: 2009 | Q1: 2010 | R1: 2011 | S1: 2012 | T1: 2013 | U1: 2014 | V1: 2015 | W1: 2016 | X1: 2017 | Y1: 2018 | Z1: 2019 | AA1: 2020 | AB1: 2021 | AC1: 2022 | AD1: 2023 | AE1: 2024
B2: СЕЛЬСКОЕ ХОЗЯЙСТВО | C2: млн. Сомони | L2: 6855.9 | M2: 7246.7 | N2: 7500.4 | O2: 7957.9 | P2: 8793.5 | Q2: 9391.4 | R2: 14853.3 | S2: 16477.5 | T2: 16756.6 | U2: 21021.9 | V2: 21577.8 | W2: =W5+W8 -> 22907.672 | X2: =X5+X8 -> 24576 | Y2: =Y5+Y8 -> 26370.3 | Z2: =Z5+Z8 -> 27750.4 | AA2: =AA5+AA8 -> 37298.4 | AB2: =AB5+AB8 -> 39769.4 | AC2: =AC5+AC8 -> 49272.4 | AD2: =AD5+AD8 -> 63028.4 | AE2: =AE5+AE8 -> 73981.3
B3: темп роста | C3: % | L3: 101.6 | M3: 105.7 | N3: 103.5 | O3: 107.9 | P3: 110.5 | Q3: 106.8 | R3: 107.9 | S3: 110.4 | T3: 107.6 | U3: 104.5 | V3: 103.2 | W3: 105.2 | X3: 106.8 | Y3: 107 | Z3: 107 | AA3: 107.9 | AB3: 99.7 | AC3: 108 | AD3: 109 | AE3: 110.6
B4: дефлятор | C4: % | M4: 100.00019 | N4: 100.00087 | O4: 98.331487 | P4: 100.00023 | Q4: 99.999382 | R4: 146.5788 | S4: 100.48455 | T4: 94.51099 | U4: 120.0521 | V4: 99.461614 | W4: =W2/V2/W3*10000 -> 100.91554 | X4: =X2/W2/X3*10000 -> 100.45209 | Y4: =Y2/X2/Y3*10000 -> 100.28133 | Z4: =Z2/Y2/Z3*10000 -> 98.349102 | AA4: =AA2/Z2/AA3*10000 -> 124.566 | AB4: =AB2/AA2/AB3*10000 -> 106.94579 | AC4: =AC2/AB2/AC3*10000 -> 114.71783 | AD4: =AD2/AC2/AD3*10000 -> 117.35621 | AE4: =AE2/AD2/AE3*10000 -> 106.12814
B5: РАСТЕНИЕВОДСТВО | C5: млн. Сомони | L5: 4724.9 | M5: 5032 | N5: 5147.7 | O5: 5523.5 | P5: 6219.5 | Q5: 6617.5 | R5: 10894.7 | S5: 11836.3 | T5: 11502.5 | U5: 14532.8 | V5: 14623.7 | W5: 15066.6 | X5: 16977.8 | Y5: 18229.2 | Z5: 19279.7 | AA5: 27130 | AB5: 28743.9 | AC5: 33902 | AD5: 43365.7 | AE5: 50984.8
B6: темп роста | C6: % | L6: 98.6 | M6: 106.5 | N6: 102.3 | O6: 108.4 | P6: 112.6 | Q6: 106.4 | R6: 108.2 | S6: 110.6 | T6: 107.6 | U6: 104.5 | V6: 101.4 | W6: 105.1 | X6: 107.4 | Y6: 103.4 | Z6: 107.8 | AA6: 108.1 | AB6: 105.9 | AC6: 107.7 | AD6: 106.8 | AE6: 113.4
B7: дефлятор | C7: % | M7: 99.999632 | N7: 99.999301 | O7: 98.985561 | P7: 100.00063 | Q7: 99.999275 | R7: 152.15775 | S7: 98.230321 | T7: 90.315857 | U7: 120.90403 | V7: 99.236175 | W7: =W5/V5/W6*10000 -> 98.029158 | X7: =X5/W5/X6*10000 -> 104.92087 | Y7: =Y5/X5/Y6*10000 -> 103.84023 | Z7: =Z5/Y5/Z6*10000 -> 98.110141 | AA7: =AA5/Z5/AA6*10000 -> 130.17387 | AB7: =AB5/AA5/AB6*10000 -> 100.04605 | AC7: =AC5/AB5/AC6*10000 -> 109.51256 | AD7: =AD5/AC5/AD6*10000 -> 119.77048 | AE7: =AE5/AD5/AE6*10000 -> 103.67673
B8: ЖИВОТНОВОДСТВО | C8: млн. Сомони | L8: 2134.1 | M8: 2208.8 | N8: 2356.8 | O8: 2429.8 | P8: 2573.2 | Q8: 2773.9 | R8: 3958.6 | S8: 3958.6 | T8: 3958.6 | U8: 3958.6 | V8: 6954.1 | W8: 7841.0717 | X8: 7598.2 | Y8: 8141.1 | Z8: 8470.7 | AA8: 10168.4 | AB8: 11025.5 | AC8: 15370.4 | AD8: 19662.7 | AE8: 22996.5
B9: темп роста | C9: % | L9: 110.1 | M9: 103.5 | N9: 106.7 | O9: 106.7 | P9: 105.9 | Q9: 107.7 | R9: 107 | S9: 109.7 | T9: 107.5 | U9: 112.5 | V9: 107.2 | W9: 105.5 | X9: 105.6 | Y9: 105.3 | Z9: 105.7 | AA9: 110.7 | AB9: 108.4 | AC9: 108.7 | AD9: 114.1 | AE9: 104.9
B10: дефлятор | C10: % | M10: 100.00029 | N10: 100.00044 | O10: 96.623637 | P10: 100.00162 | Q10: 100.0925 | R10: 133.37273 | S10: 91.157703 | T10: 93.023256 | U10: 88.888889 | V10: 163.87191 | W10: =W8/V8/W9*10000 -> 106.87645 | X10: =X8/W8/X9*10000 -> 91.763797 | Y10: =Y8/X8/Y9*10000 -> 101.75224 | Z10: =Z8/Y8/Z9*10000 -> 98.437647 | AA10: =AA8/Z8/AA9*10000 -> 108.43905 | AB10: =AB8/AA8/AB9*10000 -> 100.0268 | AC10: =AC8/AB8/AC9*10000 -> 128.24999 | AD10: =AD8/AC8/AD9*10000 -> 112.11722 | AE10: =AE8/AD8/AE9*10000 -> 111.49184
W11: =W2-V2 -> 1329.8717 | X11: =X2-W2 -> 1668.3283 | Y11: =Y2-X2 -> 1794.3 | Z11: =Z2-Y2 -> 1380.1 | AA11: =AA2-Z2 -> 9548 | AB11: =AB2-AA2 -> 2471 | AC11: =AC2-AB2 -> 9503 | AD11: =AD2-AC2 -> 13756 | AE11: =AE2-AD2 -> 10952.9 | AF11: =AE2-U2 -> 52959.4
AB12: =AB8-AA8 -> 857.1 | AC12: =AC8-AB8 -> 4344.9 | AD12: =AD8-AC8 -> 4292.3 | AE12: =AE8-AD8 -> 3333.8
B13: Общая земельная площадь | C13: га | L13: 14255397 | M13: 14255397 | N13: 14255397 | O13: 14255397 | P13: 14255397 | Q13: 14255397 | R13: 14255397 | S13: 14255397 | T13: 14255397 | U13: 14137685 | V13: 14137685 | W13: 14137685 | X13: 14137685 | Y13: 14137900 | Z13: =Y13 -> 14137900 | AA13: 14137907 | AB13: 14137907 | AC13: =AB13 -> 14137907 | AD13: =AC13 -> 14137907 | AE13: =AD13 -> 14137907
B14: площадь орошаемых земель (оби) | C14: га | L14: 737694 | M14: 741539 | N14: 742051 | O14: 741626 | P14: 743621 | Q14: 743856 | R14: 748256 | S14: 749000 | T14: 749995 | U14: 753000 | V14: 753000 | W14: 753000 | X14: =W14 -> 753000 | Y14: 757842 | Z14: 762198 | AA14: 762198 | AB14: 762851 | AC14: 763930 | AD14: 763930 | AE14: 763930
B15: Всего СХ угодья | C15: га | L15: 4668470 | M15: 4728417 | N15: 4725644 | O15: 4719198 | P15: 4719486 | Q15: 4705044 | R15: 3695161 | S15: 3614663 | T15: 3617515 | U15: 3604616 | V15: 3611907 | W15: 3638485 | X15: 3658200 | Y15: 4702084 | Z15: 4706451 | AA15: 4704794 | AB15: =AA15 -> 4704794 | AC15: 4704410 | AD15: 4704410 | AE15: 4704410
B16: в том числе, | C16: га
B17: Пашня | C17: га | L17: 718560 | M17: 714162 | N17: 710493 | O17: 704823 | P17: 701856 | Q17: 685441 | R17: 666077 | S17: 662011 | T17: 658410 | U17: 655643 | V17: 653195 | W17: 650644 | X17: 657300 | Y17: 668267 | Z17: 674609 | AA17: 672404 | AB17: 672404 | AC17: 672609 | AD17: 672609 | AE17: 672609
B18: многолетние насождение | C18: га | L18: 101635 | M18: 103135 | N18: 105571 | O18: 105104 | P18: 109671 | Q18: 120662 | R18: 121000 | S18: 126500 | T18: 131800 | U18: 137000 | V18: 140400 | W18: 144400 | X18: 148200 | Y18: 154491 | Z18: 159112 | AA18: 160330 | AB18: =AA18 -> 160330 | AC18: 161231 | AD18: 161231 | AE18: 161231
B19: сенокосы | C19: га | L19: 20619 | M19: 21259 | N19: 21259 | O19: 21211 | P19: 21264 | Q19: 21269 | R19: 17200 | S19: 17300 | T19: 17300 | U19: 17500 | V19: 17600 | W19: 17400 | X19: 15800 | Y19: =X19 -> 15800 | Z19: 18514 | AA19: 18824 | AB19: =AA19 -> 18824 | AC19: =AB19 -> 18824 | AD19: =AC19 -> 18824 | AE19: =AD19 -> 18824
B20: пастбища | C20: га | L20: 3797566 | M20: 3857776 | N20: 3856246 | O20: 3856236 | P20: 3854742 | Q20: 3846564 | R20: 2857000 | S20: 2777900 | T20: 2780000 | U20: 2764800 | V20: 2771500 | W20: 2797500 | X20: 2809600 | Y20: =X20 -> 2809600 | Z20: 3832161 | AA20: 3831887 | AB20: =AA20 -> 3831887 | AC20: 3830626 | AD20: 3830627 | AE20: 3830628
B21: залежи | C21: га | L21: 30090 | M21: 32084 | N21: 32075 | O21: 31824 | P21: 31953 | Q21: 31108 | R21: 33800 | S21: 31000 | T21: 30000 | U21: 29700 | V21: 29300 | W21: 28500 | X21: 27100 | Y21: 28727 | Z21: 20686 | AA21: 20100 | AB21: =AA21 -> 20100 | AC21: =AB21 -> 20100 | AD21: =AC21 -> 20100 | AE21: =AD21 -> 20100
B23: РАСТЕНИЕВОДСТВО | AE23: =AE25*AE28/1000 -> 2920.1
B24: Зерновые | C24: пос. площадь -га | L24: 395565 | M24: 401912 | N24: 396880 | O24: 438152 | P24: 461741 | Q24: 459942 | R24: 427178 | S24: 424332 | T24: 437440 | U24: 412626 | V24: 422947 | W24: 423449 | X24: 411581.1 | Y24: 374941.2 | Z24: =Y24 -> 374941.2 | AA24: 391483.8 | AB24: 394442.5 | AC24: 390531 | AD24: 390922 | AE24: 390922
C25: тыс. тонн | L25: 934.9 | M25: 912.3 | N25: 931.2 | O25: 942.9 | P25: 1294.5 | Q25: 1261.1 | R25: 1098.2 | S25: 1232.6 | T25: 1392.6 | U25: 1317.8 | V25: 1392.6 | W25: 1435.8 | X25: 1447.6 | Y25: 1295.6 | Z25: 1414.8 | AA25: 1562.1 | AB25: 1586.6 | AC25: 1756.2 | AD25: 1754.9 | AE25: 1828.3
C26: Рост, %, тыс. тонн | U26: 94.628752 | V26: 105.67613 | W26: =W25/V25*100 -> 103.10211 | X26: =X25/W25*100 -> 100.82184 | Y26: 89.5 | Z26: 109.2 | AA26: 110.4 | AB26: =AB25/AA25*100 -> 101.5684 | AC26: =AC25/AB25*100 -> 110.68952 | AD26: =AD25/AC25*100 -> 99.925977 | AE26: =AE25/AD25*100 -> 104.18257
C27: млн. сомони | L27: х | M27: х | N27: х | O27: х | P27: 1344.6 | Q27: 1301.7 | R27: 2120.5 | S27: 2697 | T27: 2088.1 | U27: 2371.1 | V27: 2509.8 | W27: 2541.7 | X27: 2578.3 | Y27: 2307.5749 | Z27: 2519.8804 | AA27: 2782.2343 | AB27: 3527.8521 | AC27: 4674.9295 | AD27: 3851.8991 | AE27: 2920.1
C28: цена, сомони\тонну | R28: 1930.8869 | S28: 2188.0578 | T28: 1499.4255 | U28: 1799.2867 | V28: =V27/V25*1000 -> 1802.2404 | W28: =W27/W25*1000 -> 1770.2326 | X28: =X27/X25*1000 -> 1781.0859 | Y28: =Y27/Y25*1000 -> 1781.0859 | Z28: =Z27/Z25*1000 -> 1781.0859 | AA28: =AA27/AA25*1000 -> 1781.0859 | AB28: =AB27/AB25*1000 -> 2223.5296 | AC28: =AC27/AC25*1000 -> 2661.9574 | ... AE28: =AE27/AE25*1000 -> 1597.1668
C29: урожайность -ц/га | L29: 19.5 | M29: 20.6 | N29: 20.5 | O29: 20.9 | P29: 25.2 | Q29: 27.418675 | R29: 23.6 | S29: 25.3 | T29: 27.7 | U29: 28.1 | V29: 27.7 | W29: 28.4 | X29: =X25/X24*10000 -> 35.171683 | Y29: =Y25/Y24*10000 -> 34.554752 | Z29: =Z25/Z24*10000 -> 37.733917 | AA29: =AA25/AA24*10000 -> 39.902034 | AB29: =AB25/AB24*10000 -> 40.22386 | AC29: =AC25/AC24*10000 -> 44.969541 | AD29: =AD25/AD24*10000 -> 44.891308 | AE29: =AE25/AE24*10000 -> 46.768921
C30: урожайность стат.
B31: в том числе,
B32: пшеница | C32: пос. площадь -га | L32: 317738 | M32: 320694 | N32: 307961 | O32: 331766 | P32: 358766 | Q32: 342566 | R32: 311179 | S32: 303677 | T32: 318601 | U32: 292573 | V32: 295632 | W32: 297479 | X32: 285867 | Y32: 255548.8 | Z32: =Y32 -> 255548.8 | AA32: 269645.3 | AB32: 274747.7 | AC32: 271067 | AD32: 271338 | AE32: 271338
C33: тыс. тонн | L33: 618.5 | M33: 640.3 | N33: 649.3 | O33: 659.1 | P33: 938.4 | Q33: 857.5 | R33: 726.9 | S33: 812.6 | T33: 947.4 | U33: 868.4 | V33: 896.4 | W33: 917.1 | X33: 900.2 | Y33: 779 | Z33: 836.2 | AA33: 863.7 | AB33: 876.1 | AC33: 934.3 | AD33: 860.8 | AE33: 880.7
C34: млн. сомони | W34: 1336.4 | X34: 1295.97
C35: урожайность -ц/га | L35: 19.6 | M35: 19.9 | N35: 20.6 | O35: 20.6 | P35: 25.1 | Q35: 23.9 | R35: 23.359545 | S35: 26.758694 | T35: 29.736253 | U35: 29.681481 | V35: =V33/V32*10000 -> 30.321481 | W35: =W33/W32*10000 -> 30.829067 | X35: =X33/X32*10000 -> 31.490169 | Y35: =Y33/Y32*10000 -> 30.483415 | Z35: =Z33/Z32*10000 -> 32.721735 | AA35: =AA33/AA32*10000 -> 32.030968 | AB35: =AB33/AB32*10000 -> 31.887437 | AC35: =AC33/AC32*10000 -> 34.467493 | ... AE35: =AE33/AE32*10000 -> 32.457673
AE36: =AE38*AE41/1000 -> 1289.7
B37: Хлопок | C37: пос. площадь -га | L37: 288655 | M37: 262894 | N37: 254830 | O37: 237130 | P37: 168916 | Q37: 162428 | R37: 204110 | S37: 199254 | T37: 190925 | U37: 177637 | V37: 159492 | W37: 162558 | X37: 173979 | Y37: 185816.8 | Z37: 185435 | AA37: 185435 | AB37: 177048 | AC37: 181542 | AD37: 185540 | AE37: 185540
C38: тыс. тонн | L38: 447.9 | M38: 437.9 | N38: 419.7 | O38: 353.1 | P38: 296 | Q38: 310.9 | R38: 416.5 | S38: 418 | T38: 392.8 | U38: 372.7 | V38: 270 | W38: 284.7 | X38: 386.5 | Y38: 300.4 | Z38: 403 | AA38: 396 | AB38: 388.8 | AC38: 404.7 | AD38: 344.4 | AE38: 253.2
C39: млн. сомони | L39: 0 | M39: 0 | N39: 0 | O39: 0 | P39: 550.8 | Q39: 789.4 | R39: 1509.3 | S39: 1107.5 | T39: 1327.3 | U39: 1098.8 | V39: 807.5 | W39: 1276.2 | X39: 1744.98 | Y39: 1346.577 | Z39: 1806.4932 | AA39: 1775.1149 | AB39: 1742.84 | AC39: 1851.5953 | AD39: 1922.3224 | AE39: 1289.7
C40: урожайность -ц/га | L40: 15.6 | M40: 17 | N40: 16.6 | O40: 15.6 | P40: 17.8 | Q40: 19.3 | R40: 20.4 | S40: 21 | T40: 20.573524 | U40: 20.980989 | V40: 17.3 | W40: =W38/W37*10000 -> 17.513749 | X40: =22.4 -> 22.4 | Y40: =Y38/Y37*10000 -> 16.166461 | Z40: =Z38/Z37*10000 -> 21.732683 | AA40: =AA38/AA37*10000 -> 21.355192 | AB40: =AB38/AB37*10000 -> 21.960146 | AC40: =AC38/AC37*10000 -> 22.292362 | AD40: =AD38/AD37*10000 -> 18.562035 | AE40: =AE38/AE37*10000 -> 13.646653
C41: цена | V41: =V39/V38*1000 -> 2990.7407 | W41: =W39/W38*1000 -> 4482.6133 | X41: =X39/X38*1000 -> 4514.8254 | Y41: =Y39/Y38*1000 -> 4482.6133 | Z41: =Z39/Z38*1000 -> 4482.6133 | AA41: =AA39/AA38*1000 -> 4482.6133 | AB41: =AB39/AB38*1000 -> 4482.6133 | AC41: =AC39/AC38*1000 -> 4575.2293 | ... AE41: =AE39/AE38*1000 -> 5093.6019
...

Sheet Industry
B1: Var. Name | C1: Наименование индикатора | D1: 1997 | E1: 1998 | F1: 1999 | G1: 2000 | H1: 2001 | I1: 2002 | J1: 2003 | K1: 2004 | L1: 2005 | M1: 2006 | N1: 2007 | O1: 2008 | P1: 2009 | Q1: 2010 | R1: 2011 | S1: 2012 | T1: 2013 | U1: 2014 | V1: 2015 | W1: 2016 | X1: 2017 | Y1: 2018 | Z1: 2019 | AA1: 2020 | AB1: 2021 | AC1: 2022 | AD1: 2023 | AE1: 2024
C2: Промышленность | W2: =W4-V4 -> 2894 | X2: =X4-W4 -> 4938.512 | Y2: =Y4-X4 -> 3865.388 | Z2: =Z4-Y4 -> 3719.4 | AA2: =AA4-Z4 -> 3276.7 | AB2: =AB4-AA4 -> 7939 | AC2: =AC4-AB4 -> 3392.4 | AD2: =AD4-AC4 -> 4594.6 | AE2: =AE4-AD4 -> 7003
C3: Номиналы, млн. сомони
B4: INDCDE,t | C4: Промышленное производство | I4: 2418 | J4: 3205 | K4: 3952 | L4: 4278 | M4: 4663 | N4: 5571 | O4: 6106 | P4: 6501 | Q4: 6164.7 | R4: 7862 | S4: 9504 | T4: 9952 | U4: 10534.657 | V4: =V5+V8+V15 -> 12196 | W4: =W5+W8+W15 -> 15090 | X4: =X5+X8+X15 -> 20028.512 | Y4: =Y5+Y8+Y15 -> 23893.9 | Z4: =Z5+Z8+Z15 -> 27613.3 | AA4: =AA5+AA8+AA15 -> 30890 | AB4: =AB5+AB8+AB15 -> 38829 | AC4: =AC5+AC8+AC15 -> 42221.4 | AD4: =AD5+AD8+AD15 -> 46816 | AE4: =AE5+AE8+AE15+AE17 -> 53819
B5: INDC,t | C5: Добыча полезных ископаемых | Q5: 755 | R5: 975 | S5: 1227 | T5: 1117 | U5: 1402 | V5: =V6+V7 -> 1641 | W5: =W6+W7 -> 3004 | X5: =X6+X7 -> 4523.512 | Y5: =Y6+Y7 -> 4685.9 | Z5: =Z6+Z7 -> 4853.3 | AA5: =AA6+AA7 -> 4309 | AB5: =AB6+AB7 -> 8409 | AC5: =AC6+AC7 -> 8890.9 | ... AE5: =AE6+AE7 -> 13363.1
B6: INDC13,t | C6: Добыча неэнергетических материалов | Q6: 677 | R6: 900 | S6: 1115 | T6: 804 | U6: 1175 | V6: 1438 | W6: 2782 | X6: 4225.986 | Y6: 4355.2 | Z6: 4476.7 | AA6: 3880 | AB6: 7924 | AC6: 8309 | AD6: 8795 | AE6: 12653.6
B7: INDCOther,t | C7: Добыча энергетических материалов | Q7: 78 | R7: 75 | S7: 112 | T7: 313 | U7: 227 | V7: 203 | W7: 222 | X7: 297.526 | Y7: 330.7 | Z7: 376.6 | AA7: 429 | AB7: 485 | AC7: 581.9 | AD7: 578 | AE7: 709.5
B8: INDDJ, t | C8: Обрабатывающая промышленность | Q8: 3959.3 | R8: 5428 | S8: 6536 | T8: 6916 | U8: 6959 | V8: 8006 | W8: 9368 | X8: 11776 | Y8: 13520 | Z8: 15952 | AA8: 19054 | AB8: 22313 | AC8: 25708.7 | AD8: 28459.8 | AE8: 30275.6
B9: INDDA, t | C9: пищевые продукты и табак | I9: 432.822 | J9: 493.57 | K9: 624.416 | L9: 834.21 | M9: 918.611 | N9: 1169.91 | O9: 1263.942 | P9: 1358.709 | Q9: 3048 | R9: 2442 | S9: 3318 | T9: 3588 | U9: 3266 | V9: 3482 | W9: 3690 | X9: 4304 | Y9: 4900 | Z9: 5399 | AA9: 7089 | AB9: 7608 | AC9: 10099 | AD9: 11610 | AE9: 11445.7
B10: INDDB, t | C10: текстильное производство | I10: 431.7 | J10: 696 | K10: 708.9 | L10: 751.1 | M10: 647.3 | N10: 813.2 | O10: 732 | P10: 705.3 | Q10: 534.3 | R10: 1414 | S10: 1533 | T10: 1361 | U10: 1315 | V10: 1292 | W10: 1520 | X10: 2354 | Y10: 2479 | Z10: 2636 | AA10: 2870 | AB10: 4096 | AC10: 4438 | AD10: 4632 | AE10: 4062.5
B11: INDDJ, t | C11: металлургическое производство и готовые металлические изделия | I11: 1182 | J11: 1430 | K11: 1817 | L11: 1799 | M11: 2092 | N11: 2273 | O11: 2400 | P11: 2510 | Q11: 886.5 | R11: 786 | S11: 835 | T11: 1034 | U11: 915 | V11: 1450.2 | W11: 1850 | X11: 2187.3 | Y11: 2708.4 | Z11: 3873.5 | AA11: 4978 | AB11: 5967 | AC11: 6025 | AD11: 6442 | AE11: 8090.7
B12: INDD27, t | C12: металлургическое производство | Q12: 700 | R12: 727 | S12: 681.07801 | T12: 880.2 | U12: 724 | V12: =V11-V13 -> 1202.6249 | W12: =W11-W13 -> 1557.4819 | X12: =X11-X13 -> 1932.7978 | Y12: =Y11-Y13 -> 2455.2806 | Z12: =Z11-Z13 -> 3768.9349 | AA12: =AA11-AA13 -> 4883.6227 | AB12: =AB11-AB13 -> 5845.5362 | AC12: =AC11-AC13 -> 5903.6407 | ... AE12: =AE11-AE13 -> 7962.559
B13: INDD28, t | C13: готовые металлические изделия | Q13: 100 | R13: 92.2 | S13: 73.318359 | T13: 148.6 | U13: 179.1 | V13: 247.57509 | W13: 292.51809 | X13: 254.50217 | Y13: 253.11944 | Z13: 104.56511 | AA13: 94.377342 | AB13: 121.46379 | AC13: 121.35925 | AD13: 122.87853 | AE13: 128.14095
B14: INDDOther, t | C14: переработка прочие (d) | I14: =I4-I15-I11-I10-I9 -> 231.234 | J14: 345.055 | K14: 568.516 | L14: 619.898 | M14: 715.983 | N14: 930.491 | O14: 1062.822 | P14: 1029.853 | Q14: -509.5 | R14: 786 | S14: 850 | T14: 933 | U14: 1463 | V14: 1781.8 | W14: 2308 | X14: 2930.7 | Y14: 3432.6 | Z14: 4043.5 | AA14: 4117 | AB14: 4642 | AC14: 5146.7 | AD14: 5775.8 | AE14: =AE8-AE9-AE10-AE11-AE13 -> 6548.559
B15: INDE, t | C15: Производство и распределение электроэнергии, газа и воды | I15: 140.244 | J15: 240.375 | K15: 233.168 | L15: 273.792 | M15: 289.106 | N15: 384.399 | O15: 647.236 | P15: 897.138 | Q15: 1450.4 | R15: 1459 | S15: 1741 | T15: 1919 | U15: 2173.657 | V15: 2549 | W15: 2718 | X15: 3729 | Y15: 5688 | Z15: 6808 | AA15: 7527 | AB15: 8107 | AC15: 7621.8 | AD15: 8983.2 | AE15: 9872.2
Z16: =Z4-Y4 -> 3719.4 | AA16: =AA4-Z4 -> 3276.7 | AB16: =AB4-AA4 -> 7939 | AC16: =AC4-AB4 -> 3392.4 | AD16: =AD4-AC4 -> 4594.6 | AE16: =AE4-AD4 -> 7003
B17: Секция Е (36-39) | C17: Водоснабжение, очистка, обработка отходов и получение вторичного сырья | X17: 87.1 | Y17: 132.5 | Z17: 181.6 | AA17: 168.5 | AB17: 184.6 | AC17: 188.4 | AD17: 228.8 | AE17: 308.1
A18: Реальные темпы роста, % | B18: gINDCDE,t | C18: Все промышленность | I18: 108.4 | J18: 109.9 | K18: 115.1 | L18: 110.4 | M18: 105.5 | N18: 109.9 | O18: 96.5 | P18: 93.5 | Q18: 109.2 | R18: 105.7 | S18: 110.8 | T18: 103.8 | U18: 105 | V18: 111.3 | W18: 116 | X18: 121.3 | Y18: 110.6 | Z18: 113.2 | AA18: 108.8 | AB18: 120.8 | AC18: 115.4 | AD18: 112 | AE18: 120
A19: Т/Р | B19: gINDC,t | C19: Добыча полезных ископаемых | R19: 134.3 | S19: 121.2 | T19: 143.1 | U19: 124.5 | V19: 117.9 | W19: 153.3 | X19: 121.7 | Y19: 112 | Z19: 112.6 | AA19: 97.4 | AB19: 155.2 | AC19: 97.7 | AD19: 111.7 | AE19: 143
B20: gINDC13,t | C20: Добыча неэнергетических материалов | R20: 136.4 | S20: 120.6 | T20: 122.2 | U20: 145.7 | V20: 123 | W20: 156.7 | X20: 120.3 | Y20: 113 | Z20: 113.3 | AA20: 96.5 | AB20: 160.5 | AC20: 117.7 | AD20: 113.1 | AE20: 145.2
B21: gINDCOther,t | C21: Добыча энергетических материалов | R21: 113.5 | S21: 126.9 | T21: 255.1 | U21: 68.5 | V21: 90.9 | W21: 119 | X21: 137.1 | Y21: 108.2 | Z21: 103.1 | AA21: 103.6 | AB21: 106.8 | AC21: 100.1 | AD21: 99.2 | AE21: 116.5
B22: gINDD, t | C22: Обрабатывающая промышленность | R22: 103.3 | S22: 110.2 | T22: 99 | U22: 100.9 | V22: 110.1 | W22: 112.5 | X22: 122.9 | Y22: 112.1 | Z22: 115.3 | AA22: 114.1 | AB22: 115.3 | AC22: 116.4 | AD22: 112.4 | AE22: 107.6
B23: gINDDA, t | C23: пищевые продукты и табак | I23: 102.7 | J23: 102.9 | K23: 117.3 | L23: 129.1 | M23: 107.1 | N23: 121.6 | O23: 102.4 | P23: 94.4 | Q23: 116.1 | R23: 102.1 | S23: 106.6 | T23: 100.8 | U23: 92.9 | V23: 103.5 | W23: 105.4 | X23: 115.6 | Y23: 117.6 | Z23: 107.7 | AA23: 125.9 | AB23: 103.3 | AC23: 132 | AD23: 127 | AE23: 110
B24: gINDDB, t | C24: текстильное производство | I24: 124.9 | J24: 117.8 | K24: 113.2 | L24: 111.9 | M24: 91.7 | N24: 115.3 | O24: 86 | P24: 91.1 | Q24: 113 | R24: 116.3 | S24: 128.2 | T24: 90.1 | U24: 92.9 | V24: 94.4 | W24: 103.8 | X24: 130.9 | Y24: 92.1 | Z24: 118.8 | AA24: 113.5 | AB24: 109.5 | AC24: 107.3 | AD24: 110.4 | AE24: 93
B25: gINDDJ, t | C25: металлургическое производство и готовые металлические изделия | I25: 105.3 | J25: 104.1 | K25: 114.8 | L25: 105.1 | M25: 108.6 | N25: 101.3 | O25: 96.3 | P25: 92.4 | Q25: 103 | R25: 83.6 | S25: 102.7 | T25: 96 | U25: 86.8 | V25: 130.3 | W25: 104.7 | X25: 109.4 | Y25: 110.7 | Z25: 142.2 | AA25: 109.4 | AB25: 109.4 | AC25: 103.4 | AD25: 102.7 | AE25: 113.5
B26: gINDD27J, t | C26: металлургическое производство | R26: 80.7 | S26: 158321.32 | T26: 70.080396 | U26: 80.6 | V26: 139.49313 | W26: 81.716387 | X26: 81.734833 | Y26: 93.476349 | Z26: 102.18957 | AA26: 89.702999 | AB26: 64.107442 | AC26: 101.64246 | AD26: =(AC156*AD152/AC152+AD159*AD154/AC154)/(AC156+AC159)*100 -> 104.39341 | AE26: =(AD156*AE152/AD152+AE159*AE154/AD154)/(AD156+AD159)*100 -> 129.33687
B27: gINDD28, t | C27: готовые металлические изделия | R27: 127.9 | S27: 72.673905 | T27: 79.412844 | U27: 115.9 | V27: 110.6603 | W27: 92.954709 | X27: 79.737046 | Y27: 92.919496 | Z27: 105.15921 | AA27: 83.333333 | AB27: 72.039498 | AC27: 102.47934 | AD27: =(AC158*AD153/AC153+AC159*AD154/AC154)/(AC158+AC159)*100 -> 107.41935 | AE27: =(AD158*AE153/AD153+AD159*AE154/AD154)/(AD158+AD159)*100 -> 123.42342
B28: gINDDther, t | C28: переработка прочие (d) | R28: 75.477134 | S28: 96.503053 | T28: 110.97212 | U28: 158.96152 | V28: 126.31196 | W28: 139.03169 | X28: 140.12357 | Y28: 121.13205 | Z28: 102.39653 | AA28: 103.23784 | AB28: 147.13974 | AC28: =(AC22*AB8-SUMPRODUCT(AB9:AB11,AC23:AC25))/AB14 -> 115.57273 | AD28: =(AD22*AC8-SUMPRODUCT(AC9:AC11,AD23:AD25))/AC14 -> 96.831403 | AE28: =(AE22*AD8-SUMPRODUCT(AD9:AD11,AE23:AE25))/AD14 -> 107.90392
B29: gINDE, t | C29: Производство и распределение электроэнергии, газа и воды | I29: 107.6 | J29: 106.6 | K29: 98.1 | L29: 104.4 | M29: 105.5 | N29: 105.6 | O29: 93.4 | P29: 97.7 | Q29: 104.4 | R29: 100.5 | S29: 106.4 | T29: 105.6 | U29: 106.8 | V29: 111.5 | W29: 103.7 | X29: 116.5 | Y29: 107.5 | Z29: 105.6 | AA29: 100.1 | AB29: 112.7 | AC29: 117.5 | AD29: 107.1 | AE29: 105.7
AE30: 134.9
B31: gINDD27J, t | C31: металлургическое производство | V31: 139.49313 | W31: 81.716387 | X31: 81.734833 | Y31: 93.476349 | Z31: 102.18957 | AA31: 89.702999 | AB31: 64.107442 | AC31: 101.64246 | AD31: 104.4737 | AE31: 129.06373
C32: Дефлятор, %
B33: defINDCDE,t | C33: Все промышленность | J33: 120.60742 | K33: 107.13061 | L33: 98.051619 | M33: 103.31709 | N33: 108.71014 | O33: 113.57855 | P33: 113.87064 | Q33: 86.837866 | R33: 120.65522 | S33: 109.10223 | T33: 100.88035 | U33: 100.81397 | V33: 114.7 | W33: 101.7 | X33: 101.8 | Y33: 101.1 | Z33: 105.4 | AA33: 105.9 | AB33: =AB4/AA4/AB18*10000 -> 104.05701 | AC33: =AC4/AB4/AC18*10000 -> 94.22597 | AD33: =AD4/AC4/AD18*10000 -> 99.001928 | AE33: =AE4/AD4/AE18*10000 -> 95.798801
B34: defINDC,t | C34: Добыча полезных ископаемых | R34: 96.157165 | S34: 103.83346 | T34: 63.616384 | U34: 100.81508 | V34: 163.9 | W34: 84.9 | X34: 90.1 | Y34: 100.3 | Z34: 107.7 | AA34: 116.7 | AB34: =AB5/AA5/AB19*10000 -> 125.74078 | AC34: =AC5/AB5/AC19*10000 -> 108.21982 | AD34: =AD5/AC5/AD19*10000 -> 94.379945 | AE34: =AE5/AD5/AE19*10000 -> 99.699404
B35: defINDC13,t | C35: Добыча неэнергетических материалов | R35: 97.462932 | S35: 102.72711 | T35: 59.007875 | U35: 100.30493 | V35: 96.8 | W35: 96.6 | X35: 103.7 | Y35: 116 | Z35: 106.4 | AA35: 112.3 | AB35: =AB6/AA6/AB20*10000 -> 127.24411 | AC35: =AC6/AB6/AC20*10000 -> 89.089768 | AD35: =AD6/AC6/AD20*10000 -> 93.58893 | AE35: =AE6/AD6/AE20*10000 -> 99.08585
B36: defINDCOther,t | C36: Добыча энергетических материалов | R36: 84.717045 | S36: 117.67796 | T36: 109.55088 | U36: 105.8744 | V36: 173.6 | W36: 83.4 | X36: 89.2 | Y36: 99.2 | Z36: 108.3 | AA36: 117.5 | AB36: =AB7/AA7/AB21*10000 -> 105.85544 | AC36: =AC7/AB7/AC21*10000 -> 119.85952 | AD36: 115 | AE36: =AE7/AD7/AE21*10000 -> 105.36555
B37: defINDD,t | C37: Обрабатывающая промышленность | R37: 132.71533 | S37: 109.2674 | T37: 106.88278 | U37: 99.724229 | V37: 102.7 | W37: 102 | X37: 102.8 | Y37: 101.5 | Z37: 104.5 | AA37: 104.8 | AB37: =AB8/AA8/AB22*10000 -> 101.56463 | AC37: =AC8/AB8/AC22*10000 -> 98.984951 | AD37: =AD8/AC8/AD22*10000 -> 98.488476 | AE37: =AE8/AD8/AE22*10000 -> 98.866382
B38: defINDDA, t | C38: пищевые продукты и табак | J38: 136.86169 | K38: 89.976544 | L38: 94.68533 | M38: 93.980664 | N38: 108.95884 | O38: 104.66832 | P38: 105.7656 | Q38: 67.039821 | R38: 78.470235 | S38: 127.45988 | T38: 107.2792 | U38: 97.982391 | V38: 101.1 | W38: 100.5 | X38: 101.7 | Y38: 102.6 | Z38: 104.1 | AA38: 108.4 | AB38: 103.89274 | AC38: 100.56201 | AD38: =Monetary!AD5 -> 103.6 | AE38: =Monetary!AE5 -> 102.2
B39: defINDDB, t | C39: текстильное производство | J39: 110.82151 | K39: 107.85176 | L39: 103.48446 | M39: 102.81744 | N39: 104.73389 | O39: 105.50541 | P39: 113.87472 | Q39: 193.22187 | R39: 227.55402 | S39: 84.567739 | T39: 98.535149 | U39: 104.00445 | V39: 120.7 | W39: 111.6 | X39: 106.3 | Y39: 94.2 | Z39: 99.5 | AA39: 113.4 | AB39: =AB10/AA10/AB24*10000 -> 130.33586 | AC39: =AC10/AB10/AC24*10000 -> 100.9782 | AD39: =AD10/AC10/AD24*10000 -> 94.539256 | AE39: =AE10/AD10/AE24*10000 -> 94.306554
B40: defINDDJ, t | C40: металлургическое производство и готовые металлические изделия | J40: 116.21651 | K40: 110.682 | L40: 94.204906 | M40: 107.07811 | N40: 107.25766 | O40: 109.64416 | P40: 113.18543 | Q40: 34.290024 | R40: 106.05656 | S40: 103.44118 | T40: 128.99202 | U40: 101.9485 | V40: 111.4 | W40: 110.7 | X40: 105.9 | Y40: 100.4 | Z40: 131.3 | AA40: 99 | AB40: =AB11/AA11/AB25*10000 -> 109.56802 | AC40: =AC11/AB11/AC25*10000 -> 97.65185 | AD40: =AD11/AC11/AD25*10000 -> 104.11019 | AE40: =AE11/AD11/AE25*10000 -> 110.65461
...

Sheet OEA
B1: Var. Name | C1: Наименование индикатора | D1: 1997 | E1: 1998 | F1: 1999 | G1: 2000 | H1: 2001 | I1: 2002 | J1: 2003 | K1: 2004 | L1: 2005 | M1: 2006 | N1: 2007 | O1: 2008 | P1: 2009 | Q1: 2010 | R1: 2011 | S1: 2012 | T1: 2013 | U1: 2014 | V1: 2015 | W1: 2016 | X1: 2017 | Y1: 2018 | Z1: 2019 | AA1: 2020 | AB1: 2021 | AC1: 2022 | AD1: 2023 | AE1: 2024
C2: Транспорт
B3: TRANCt | C3: Перевозка грузов, млн.тонна | D3: 36 | E3: 34.6 | F3: 27.7 | G3: 27.6763 | H3: 30.0127 | I3: 35.6024 | J3: 32.9246 | K3: 35.7322 | L3: 38.5936 | M3: 39.541 | N3: 44.998 | O3: 47.732 | P3: 58.863 | Q3: 59.327 | R3: 61.657 | S3: 68.399 | T3: 72.2 | U3: 74.4 | V3: 74.4 | W3: 84.1 | X3: 84.1 | Y3: 89.6 | Z3: 85.4 | AA3: 79.9 | AB3: 82 | AC3: 103.4 | AD3: 120.6 | AE3: 134.4 | AH3: TRANCt = TRANCM, t+TRANCOther, t
B4: PROXYTRANIND,t | C4: Промышленное производство, превозимое автотранспортом | J4: 100 | K4: 118.04233 | L4: 137.16425 | M4: 141.23944 | N4: 167.12739 | O4: 162.22223 | P4: 151.63621 | Q4: 175.32456 | R4: 189.83791 | S4: 242.58339 | T4: 238.86549 | U4: 242.72656 | V4: 258.4009 | W4: =(Industry!V9*Industry!W23+Industry!W24*Industry!V10+Industry!V14*Industry!W28+Industry!V7*Industry!W21)/(Industry!V7+Industry!V9+Industry!V10+Industry!V14)*V4/100 -> 295.53009 | X4: =(Industry!W9*Industry!X23+Industry!X24*Industry!W10+Industry!W14*Industry!X28+Industry!W7*Industry!X21)/(Industry!W7+Industry!W9+Industry!W10+Industry!W14)*W4/100 -> 373.94614 | Y4: =(Industry!X9*Industry!Y23+Industry!Y24*Industry!X10+Industry!X14*Industry!Y28+Industry!X7*Industry!Y21)/(Industry!X7+Industry!X9+Industry!X10+Industry!X14)*X4/100 -> 419.913 | Z4: =(Industry!Y9*Industry!Z23+Industry!Z24*Industry!Y10+Industry!Y14*Industry!Z28+Industry!Y7*Industry!Z21)/(Industry!Y7+Industry!Y9+Industry!Y10+Industry!Y14)*Y4/100 -> 455.18244 | AA4: =(Industry!Z9*Industry!AA23+Industry!AA24*Industry!Z10+Industry!Z14*Industry!AA28+Industry!Z7*Industry!AA21)/(Industry!Z7+Industry!Z9+Industry!Z10+Industry!Z14)*Z4/100 -> 524.57137 | AB4: =(Industry!AA9*Industry!AB23+Industry!AB24*Industry!AA10+Industry!AA14*Industry!AB28+Industry!AA7*Industry!AB21)/(Industry!AA7+Industry!AA9+Industry!AA10+Industry!AA14)*AA4/100 -> 614.13373 | AC4: =(Industry!AB9*Industry!AC23+Industry!AC24*Industry!AB10+Industry!AB14*Industry!AC28+Industry!AB7*Industry!AC21)/(Industry!AB7+Industry!AB9+Industry!AB10+Industry!AB14)*AB4/100 -> 740.27139 | AD4: =(Industry!AC9*Industry!AD23+Industry!AD24*Industry!AC10+Industry!AC14*Industry!AD28+Industry!AC7*Industry!AD21)/(Industry!AC7+Industry!AC9+Industry!AC10+Industry!AC14)*AC4/100 -> 850.60741 | AE4: =(Industry!AD9*Industry!AE23+Industry!AE24*Industry!AD10+Industry!AD14*Industry!AE28+Industry!AD7*Industry!AE21)/(Industry!AD7+Industry!AD9+Industry!AD10+Industry!AD14)*AD4/100 -> 902.88224 | AH4: PROXYTRANIND,t = PROXYTRANIND,t-1·((INDDBC, t-1·gINDDBC, t+INDDA, t-1·gINDDA, t+INDDther, t-1·gINDDther, t)/(INDDBC, t-1+INDDA, t-1+INDDther, t-1))/100
B5: TRANCM, t | C5: - в т.ч. авто, млн.тонна | D5: 22.8 | E5: 21.9 | F5: 16.1 | G5: 14.5763 | H5: 17.2959 | I5: 23.8024 | J5: 21.2003 | K5: 23.4598 | L5: 26.4757 | M5: 25.6036 | N5: 30.4975 | O5: 33.1856 | P5: 42.3148 | Q5: 50.8 | R5: 52.397 | S5: 60.425602 | T5: 65.5 | U5: 67.6 | V5: 68.3 | W5: 78.6 | X5: 79.5 | Y5: 84.3 | Z5: 79.6 | AA5: 73.6 | AB5: 76.3 | AC5: 97.3 | AD5: 114.1 | AE5: 127.7 | AH5: TRANCM, t = TRANCM, t-1·(PROXYTRANIND,t/PROXYTRANIND,t-1)^0,1·(gRETt/100)^0,8
B6: TRANCOther, t | C6: - прочее | D6: 13.2 | E6: 12.7 | F6: 11.6 | G6: 13.1 | H6: 12.7168 | I6: 11.8 | J6: 11.7243 | K6: 12.2724 | L6: 12.1179 | M6: 13.9374 | N6: 14.5 | O6: 14.5467 | P6: 14.5482 | Q6: 10.4 | R6: 9.26 | S6: 7.9733984 | T6: 6.7 | U6: 6.8 | V6: =V3-V5 -> 6.1 | W6: =W3-W5 -> 5.5 | X6: =X3-X5 -> 4.6 | Y6: =Y3-Y5 -> 5.3 | Z6: =Z3-Z5 -> 5.8 | AA6: =AA3-AA5 -> 6.3 | AB6: =AB3-AB5 -> 5.7 | AC6: =AC3-AC5 -> 6.1 | ... AE6: =AE3-AE5 -> 6.7 | AH6: TRANCOther, t = TRANCOther, t-1·(qEXAl,t/qEXAl,t-1)
B7: gTRANC, t | C7: - темпы роста | D7: 31.551271 | E7: 96.111111 | F7: 80.057803 | G7: 99.91444 | H7: 108.44188 | I7: 118.62445 | J7: 92.478597 | K7: 108.52736 | L7: 108.0079 | M7: 102.45481 | N7: 113.7996 | O7: 106.07767 | P7: 119.12898 | Q7: 107.6271 | R7: 103.92739 | S7: 110.93469 | T7: 105.5 | U7: 103 | V7: 100 | W7: 113 | X7: 100.1 | Y7: =Y3/X3*100 -> 106.53983 | Z7: =Z3/Y3*100 -> 95.3125 | AA7: 99.7 | AB7: 103.8 | AC7: 126.1 | AD7: 116.6 | AE7: 111.5 | AH7: gTRANC, t = TRANCt/TRANCt-1·100
B12: TRANPt | C12: Перевозка пассажиров | D12: 124.5 | E12: 174.1 | F12: 187.6 | G12: 151.4 | H12: 171.6 | I12: 225.9 | J12: 265.5 | K12: 340.6 | L12: 398.4 | M12: 415.4 | N12: 429.2 | O12: 455 | P12: 514.6 | Q12: 539.5 | R12: 479.3 | S12: 512.8 | T12: 545 | U12: 556.9 | V12: 564.5 | W12: 572.9 | X12: 594.7 | Y12: 614.5 | Z12: 658.1 | AA12: 654.7 | AB12: 737.1 | AC12: 818.6 | AD12: 899.3 | AE12: 1020 | AH12: TRANPt = TRANPM, t+TRANPOther, t
B13: TRANPM, t | C13: - в т.ч. авто | D13: 93.6 | E13: 140.8 | F13: 145.8 | G13: 122.8 | H13: 147.1 | I13: 203.7 | J13: 243.5 | K13: 317.4 | L13: 380.7 | M13: 391.4 | N13: 406.5 | O13: 443 | P13: 502.9 | Q13: 526.8 | R13: 467.3 | S13: 500.8 | T13: 533.2 | U13: 545.2 | V13: 553.1 | W13: 560.7 | X13: 582.2 | Y13: 602.6 | Z13: 635.4 | AA13: 634.8 | AB13: 717.1 | AC13: 797.1 | AD13: 876.7 | AE13: 996.1 | AH13: TRANPM, t = TRANPM, t-1·gRETt/100
B14: TRANPOther, t | C14: - прочее | D14: 30.9 | E14: 33.3 | F14: 41.8 | G14: 28.6 | H14: 24.5 | I14: 22.2 | J14: 22 | K14: 23.2 | L14: 17.7 | M14: 24 | N14: 22.7 | O14: 12 | P14: 11.7 | Q14: 12.7 | R14: 12 | S14: 12 | T14: 11.8 | U14: 11.7 | V14: =V12-V13 -> 11.4 | W14: =W12-W13 -> 12.2 | X14: =X12-X13 -> 12.5 | Y14: =Y12-Y13 -> 11.9 | Z14: =Z12-Z13 -> 22.7 | AA14: =AA12-AA13 -> 19.9 | AB14: =AB12-AB13 -> 20 | AC14: =AC12-AC13 -> 21.5 | ... AE14: =AE12-AE13 -> 23.9 | AH14: TRANPOther, t = TRANPOther, t-1
B15: gTRANPt | C15: - темпы роста | D15: 105.06329 | E15: 139.83936 | F15: 107.75416 | G15: 80.703625 | H15: 113.34214 | I15: 131.64336 | J15: 117.52988 | K15: 128.28625 | L15: 116.97005 | M15: 104.26707 | N15: 103.3221 | O15: 106.01118 | P15: 113.0989 | Q15: 104.83871 | R15: 88.84152 | S15: 106.98936 | T15: 104.7 | U15: 102.2 | V15: 101.4 | W15: 101.5 | X15: 103.8 | Y15: 103.3 | Z15: 107.1 | AA15: 97.5 | AB15: 113 | AC15: =AC12/AB12*100 -> 111.05684 | AD15: =AD12/AC12*100 -> 109.85829 | AE15: =AE12/AD12*100 -> 113.42155 | AH15: gTRANPt = TRANPt/TRANPt-1·100
W20: =W22-V22 -> 1759.3 | X20: =X22-W22 -> 297.1 | Y20: =Y22-X22 -> 1554.7 | Z20: =Z22-Y22 -> -843.2 | AA20: =AA22-Z22 -> -900.9 | AB20: =AB22-AA22 -> 3140.3 | AC20: =AC22-AB22 -> 1522.3 | AD20: =AD22-AC22 -> 3579.5 | AE20: =AE22-AD22 -> 2684
W21: =W23-V23 -> 953.9 | X21: =X23-W23 -> 613.9 | Y21: =Y23-X23 -> 1455 | Z21: =Z23-Y23 -> -207.4 | AA21: =AA23-Z23 -> -574.5 | AB21: =AB23-AA23 -> 421.9 | AC21: =AC23-AB23 -> 628.1 | AD21: =AD23-AC23 -> 1185.6 | AE21: =AE23-AD23 -> 1908
B22: INVt | C22: Инвестиции в ОК | D22: 67.5 | E22: 68.3 | F22: 122.5 | G22: 108.6 | H22: 194.8 | I22: 206.9 | J22: 318.4 | K22: 592 | L22: 682.5 | M22: 1214.5 | N22: 2828.7 | O22: 4341.4 | P22: 3899.4 | Q22: 4413.5 | R22: 4848 | S22: 4540.2 | T22: 5796.8 | U22: 7495.2 | V22: 9749.9 | W22: =SUM(W23+W25+W26+W27) -> 11509.2 | X22: =SUM(X23+X25+X26+X27) -> 11806.3 | Y22: 13361 | Z22: 12517.8 | AA22: =SUM(AA23+AA25+AA26+AA27) -> 11616.9 | AB22: =SUM(AB23+AB25+AB26+AB27) -> 14757.2 | AC22: =SUM(AC23+AC25+AC26+AC27) -> 16279.5 | AD22: =SUM(AD23+AD25+AD26+AD27) -> 19859 | AE22: =SUM(AE23+AE25+AE26+AE27) -> 22543 | AH22: INVt = INVt-1·InvNAF,t/InvNAF,t-1
C23: за счет бюджета | D23: 47.6 | E23: 46.3 | F23: 95.2 | G23: 47.3 | H23: 100.5 | I23: 117.2 | J23: 180.2 | K23: 349 | L23: 319.2 | M23: 429.3 | N23: 547.5 | O23: 1015 | P23: 1219.3 | Q23: 1629.9 | R23: 2183.3169 | S23: 2018.5 | T23: 2426 | U23: 3104 | V23: 3446 | W23: 4399.9 | X23: 5013.8 | Y23: 6468.8 | Z23: 6261.4 | AA23: 5686.9 | AB23: 6108.8 | AC23: 6736.9 | AD23: 7922.5 | AE23: 9830.5
C24: в. том числе цент.кап.влож. | W24: 3375.4 | X24: 3174.2 | Y24: 3410.6
C25: частные | G25: 27.3 | H25: 48.9 | I25: 19.3 | J25: 48 | K25: 79.7 | L25: 143.9 | M25: 230.2 | N25: 587.3 | O25: 414.1 | P25: 787.9 | Q25: 744.7 | R25: 1058.2553 | S25: 1119.2 | T25: 1701.9 | U25: 2310 | V25: 2444.3 | W25: 1993.7 | X25: 1821 | Y25: 2256.3 | Z25: 3067.8 | AA25: 3095.2 | AB25: 4443.8 | AC25: 4620 | AD25: 5721.4 | AE25: 8295
C26: совместные | D26: 3.4 | E26: 3.9 | F26: 6.3 | G26: 4.9 | H26: 9.8 | I26: 42.3 | J26: 39 | K26: 58.6 | L26: 68.3 | M26: 115.2 | N26: 105.4 | O26: 211.3 | P26: 280.7 | Q26: 316.6 | R26: 449.90416 | S26: 367 | T26: 509.4 | U26: 509.4 | V26: 276.2 | W26: 509.4 | X26: 509.4 | Y26: 433.6 | Z26: 161.8 | AA26: 45.2 | AB26: 101.5 | AC26: 230.6 | AD26: 695.9 | AE26: 98.8
C27: иностранные инвестиции | G27: 29.1 | H27: 35.6 | I27: 28.1 | J27: 51.2 | K27: 104.7 | L27: 151.1 | M27: 439.8 | N27: 1588.5 | O27: 2701 | P27: 1611.5 | Q27: 1722.3 | R27: 1156.5236 | S27: 1035.5 | T27: 1159.5 | U27: 1571.8 | V27: 3583.4 | W27: 4606.2 | X27: 4462.1 | Y27: 4202.3 | Z27: 3026.8 | AA27: 2789.6 | AB27: 4103.1 | AC27: 4692 | AD27: 5519.2 | AE27: 4318.7
V28: =V27/Household!V2 -> 581.29613 | W28: =W27/Household!W2 -> 587.85543 | X28: =X27/Household!X2 -> 521.90135 | Y28: =Y27/Household!Y2 -> 459.20754 | Z28: =Z27/Household!Z2 -> 317.60422 | AA28: =AA27/Household!AA2 -> 270.26032 | AB28: =AB27/Household!AB2 -> 362.82043 | AC28: =AC27/Household!AC2 -> 425.54735 | ... AE28: =AE27/Household!AE2 -> 399.93147
C29: Инвестиции в ОК | M29: 0.77948718 | N29: 1.3291066 | O29: 0.53476862 | P29: -0.10181048 | Q29: 0.1318408 | R29: 0.098447944 | S29: -0.063490099 | T29: 0.27677195 | U29: 0.29298924 | V29: 0.30081919 | W29: =W22/V22-1 -> 0.18044288 | X29: =X22/W22-1 -> 0.025814131 | Y29: =Y22/X22-1 -> 0.13168393 | Z29: =Z22/Y22-1 -> -0.063109049 | AA29: =AA22/Z22-1 -> -0.071969515 | AB29: =AB22/AA22-1 -> 0.27032169 | AC29: =AC22/AB22-1 -> 0.10315643 | AD29: =AD22/AC22-1 -> 0.21987776 | AE29: =AE22/AD22-1 -> 0.13515283
C30: за счет бюджета | M30: 0.34492481 | N30: 0.27533194 | O30: 0.85388128 | P30: 0.20128079 | Q30: 0.33675059 | R30: 0.33954042 | S30: -0.075489239 | T30: 0.20188259 | U30: 0.27947238 | V30: 0.11018041 | W30: =W23/V23-1 -> 0.2768137 | X30: =X23/W23-1 -> 0.1395259 | Y30: =Y23/X23-1 -> 0.29019905 | Z30: =Z23/Y23-1 -> -0.032061588 | AA30: =AA23/Z23-1 -> -0.091752643 | AB30: =AB23/AA23-1 -> 0.074188046 | AC30: =AC23/AB23-1 -> 0.10281888 | AD30: =AD23/AC23-1 -> 0.17598599 | AE30: =AE23/AD23-1 -> 0.24083307
C31: частные | M31: 0.59972203 | N31: 1.5512598 | O31: -0.29490891 | P31: 0.90268051 | Q31: -0.054829293 | R31: 0.42104915 | S31: 0.057589786 | T31: 0.52063974 | U31: 0.35730654 | V31: 0.058138528 | W31: =W25/V25-1 -> -0.18434726 | X31: =X25/W25-1 -> -0.086622862 | Y31: =Y25/X25-1 -> 0.23904448 | Z31: =Z25/Y25-1 -> 0.35965962 | AA31: =AA25/Z25-1 -> 0.0089314818 | AB31: =AB25/AA25-1 -> 0.4357069 | AC31: =AC25/AB25-1 -> 0.039650749 | AD31: =AD25/AC25-1 -> 0.23839827 | AE31: =AE25/AD25-1 -> 0.44981997
C32: совместные | M32: 0.68667643 | N32: -0.085069444 | O32: 1.0047438 | P32: 0.32844297 | Q32: 0.12789455 | R32: 0.42104915 | S32: -0.18427072 | T32: 0.3880109 | U32: 0 | V32: -0.45779348 | W32: =W26/V26-1 -> 0.84431571 | X32: =X26/W26-1 -> -1.7763568e-15 | Y32: =Y26/X26-1 -> -0.14880251 | Z32: =Z26/Y26-1 -> -0.62684502 | AA32: =AA26/Z26-1 -> -0.72064277 | AB32: =AB26/AA26-1 -> 1.2455752 | AC32: =AC26/AB26-1 -> 1.2719212 | AD32: =AD26/AC26-1 -> 2.0177797 | AE32: =AE26/AD26-1 -> -0.85802558
C33: иностранные инвестиции | M33: 1.9106552 | N33: 2.611869 | O33: 0.70034624 | P33: -0.40336912 | Q33: 0.068755818 | R33: -0.32850049 | S33: -0.1046443 | T33: 0.11974891 | U33: 0.3555843 | V33: 1.2798066 | W33: =W27/V27-1 -> 0.28542725 | X33: =X27/W27-1 -> -0.031283922 | Y33: =Y27/X27-1 -> -0.058223706 | Z33: =Z27/Y27-1 -> -0.27972777 | AA33: =AA27/Z27-1 -> -0.078366592 | AB33: =AB27/AA27-1 -> 0.47085604 | AC33: =AC27/AB27-1 -> 0.14352563 | AD33: =AD27/AC27-1 -> 0.17630009 | AE33: =AE27/AD27-1 -> -0.21751341
C34: иностранные инвестиции | AC34: 2577 | AD34: 2690 | AE34: 4905.6
AD35: =AD34/AC34*100 -> 104.38494 | AE35: =AE34/AD34*100 -> 182.36431
AD36: =AD34-AC34 -> 113 | AE36: =AE34-AD34 -> 2215.6
B37: CONSTRt | C37: Строительство | G37: 38 | H37: 69.7 | I37: 68.9 | J37: 136.6 | K37: 262.3 | L37: 327.1 | M37: 567.5 | N37: 1034.6 | O37: 1832.6 | P37: 2098.4 | Q37: 2528.2 | R37: 2387.5 | S37: 3023.5 | T37: 4200.8 | U37: 4660 | V37: =GDP!V18 -> 7679.3 | W37: =GDP!W18 -> 8382.9 | X37: =GDP!X18 -> 7680.4 | Y37: =GDP!Y18 -> 9411.7 | Z37: =GDP!Z18 -> 9281.6 | AA37: =GDP!AA18 -> 8863.7 | AB37: =GDP!AB18 -> 11417.3 | AC37: =GDP!AC18 -> 13250.1 | ... AE37: =GDP!AE18 -> 12451.7 | AH37: CONSTRt = VAF,t
B38: defCONSTRt | C38: - дефлятор | L38: 107.13448 | M38: 161.84174 | N38: 165.13439 | O38: 146.1479 | P38: 135.50767 | Q38: 110 | R38: 89.511636 | S38: 167.51157 | T38: 118.54805 | U38: 88.532523 | V38: 135.96687 | W38: =W37/V37/W39*10000 -> 90.741724 | X38: =X37/W37/X39*10000 -> 88.011379 | Y38: =Y37/X37/Y39*10000 -> 111.19945 | Z38: =Z37/Y37/Z39*10000 -> 94.280763 | AA38: =AA37/Z37/AA39*10000 -> 91.824561 | AB38: =AB37/AA37/AB39*10000 -> 104.46848 | AC38: =AC37/AB37/AC39*10000 -> 104.17669 | AD38: =AD37/AC37/AD39*10000 -> 100.29394 | AE38: 104.7 | AH38: defCONSTRt = EXP(0,25+1,31·LN(erRURt/erRURt-1))·100
B39: gCONSTRt | C39: - темпы роста | L39: 116.4 | M39: 107.2 | N39: 110.4 | O39: 121.2 | P39: 84.5 | Q39: 109.52934 | R39: 105.5 | S39: 75.6 | T39: 117.2 | U39: 125.3 | V39: 121.2 | W39: 120.3 | X39: 104.1 | Y39: 110.2 | Z39: 104.6 | AA39: 104 | AB39: 123.3 | AC39: 111.4 | AD39: 112.3 | AE39: =AE37/AD37/AE38*10000 -> 79.690833 | AH39: gCONSTRt = CONSTRt/CONSTRt-1/defCONSTRt·10000
B41: соотношение строительство/инвестиции в ОК | G41: 0.34990792 | H41: 0.35780287 | I41: 0.33301112 | J41: 0.4290201 | K41: 0.44307432 | L41: 0.4792674 | M41: 0.46727048 | N41: 0.36575105 | O41: 0.4221219 | P41: 0.53813407 | Q41: 0.57283335 | R41: 0.49247112 | S41: 0.66593983 | T41: 0.72467568 | U41: 0.62173124 | V41: =V37/V22 -> 0.78762859 | W41: =W37/W22 -> 0.72836513 | X41: =X37/X22 -> 0.65053404 | Y41: =Y37/Y22 -> 0.70441584 | Z41: =Z37/Z22 -> 0.74147214 | AA41: =AA37/AA22 -> 0.76300046 | AB41: =AB37/AB22 -> 0.77367658 | AC41: =AC37/AC22 -> 0.8139132 | ... AE41: =AE37/AE22 -> 0.55235328
V43: =GDP!V2 -> 50977.4 | W43: =GDP!W2 -> 54790.3 | X43: =GDP!X2 -> 64434.3 | Y43: =GDP!Y2 -> 71059.2 | Z43: =GDP!Z2 -> 79109.8 | AA43: =GDP!AA2 -> 83958.3 | AB43: =GDP!AB2 -> 101076.3 | AC43: =GDP!AC2 -> 118181.7 | ... AE43: =GDP!AE2 -> 153402.2
